Workbook
Name shift: Data_Shifted!$I$1
Name valuevx: 42.314159

Sheet BoxPlot
A1: Box Plot Template
I5: Using This Worksheet
I6: This template shows how to create a box and
I7: whisker chart in Excel. The ends of the whisker
I8: are set at 1.5*IQR above the third quartile (Q3)
I9: and 1.5*IQR below the first quartile (Q1). If the
I10: Minimum or Maximum values are outside this
I11: range, then they are shown as outliers. The
I12: normal convention for box plots is to show all
I13: the outliers, but to simplify this template, only
I14: the Min and Max outliers are shown. The
I15: number of outliers for each data set are included
I16: in the table below the chart.
... I25: - Adding Columns: You can easily add
A26: Labels | B26: Sample 1 | C26: Sample 2 | D26: Sample 3 | E26: Sample 4 | F26: Sample 5 | G26: Sample 6 | I26: additional data sets by copying an existing
A27: Min | B27: =MIN(B$50:B$90) -> 22 | C27: =MIN(C$50:C$90) -> 12.079733 | D27: =MIN(D$50:D$90) -> 30 | E27: =MIN(E$50:E$90) -> 40 | F27: =MIN(F$50:F$90) -> 10 | G27: =MIN(G$50:G$90) -> 22 | I27: column and inserting it between Sample 5 and
A28: Q1 | B28: =PERCENTILE(B$50:B$90,0.25) -> 39.5 | C28: =PERCENTILE(C$50:C$90,0.25) -> 17.683313 | D28: =PERCENTILE(D$50:D$90,0.25) -> 82 | E28: =PERCENTILE(E$50:E$90,0.25) -> 55 | F28: =PERCENTILE(F$50:F$90,0.25) -> 75.25 | G28: =PERCENTILE(G$50:G$90,0.25) -> 35 | I28: Sample 6. Doing so will ensure that the chart
A29: Median | B29: =MEDIAN(B$50:B$90) -> 62.5 | C29: =MEDIAN(C$50:C$90) -> 21.870211 | D29: =MEDIAN(D$50:D$90) -> 92 | E29: =MEDIAN(E$50:E$90) -> 93 | F29: =MEDIAN(F$50:F$90) -> 83.5 | G29: =MEDIAN(G$50:G$90) -> 44 | I29: series expand to include the new data set.
A30: Q3 | B30: =PERCENTILE(B$50:B$90,0.75) -> 80 | C30: =PERCENTILE(C$50:C$90,0.75) -> 33.864251 | D30: =PERCENTILE(D$50:D$90,0.75) -> 99 | E30: =PERCENTILE(E$50:E$90,0.75) -> 116 | F30: =PERCENTILE(F$50:F$90,0.75) -> 93.75 | G30: =PERCENTILE(G$50:G$90,0.75) -> 56
A31: Max | B31: =MAX(B$50:B$90) -> 108 | C31: =MAX(C$50:C$90) -> 78.604551 | D31: =MAX(D$50:D$90) -> 145 | E31: =MAX(E$50:E$90) -> 138 | F31: =MAX(F$50:F$90) -> 140 | G31: =MAX(G$50:G$90) -> 130 | I31: - Adding Rows: The formulas allow you to
A32: IQR | B32: =B30-B28 -> 40.5 | C32: =C30-C28 -> 16.180938 | D32: =D30-D28 -> 17 | E32: =E30-E28 -> 61 | F32: =F30-F28 -> 18.5 | G32: =G30-G28 -> 21 | I32: have blank values within the data sets, but if
A33: Upper Outliers | B33: =COUNTIF(B$50:B$90,">"&B39) -> 0 | C33: =COUNTIF(C$50:C$90,">"&C39) -> 1 | D33: =COUNTIF(D$50:D$90,">"&D39) -> 2 | E33: =COUNTIF(E$50:E$90,">"&E39) -> 0 | F33: =COUNTIF(F$50:F$90,">"&F39) -> 2 | G33: =COUNTIF(G$50:G$90,">"&G39) -> 1 | I33: you need to add more rows, add rows above
A34: Lower Outliers | B34: =COUNTIF(B$50:B$90,"<"&B40) -> 0 | C34: =COUNTIF(C$50:C$90,"<"&C40) -> 0 | D34: =COUNTIF(D$50:D$90,"<"&D40) -> 1 | E34: =COUNTIF(E$50:E$90,"<"&E40) -> 0 | F34: =COUNTIF(F$50:F$90,"<"&F40) -> 2 | G34: =COUNTIF(G$50:G$90,"<"&G40) -> 0 | I34: the gray line below the table so that the range
A35: For the Box (IQR and Median)
A36: Q2-Q1 | B36: =B29-B28 -> 23 | C36: =C29-C28 -> 4.1868985 | D36: =D29-D28 -> 10 | E36: =E29-E28 -> 38 | F36: =F29-F28 -> 8.25 | G36: =G29-G28 -> 9
A37: Q3-Q2 | B37: =B30-B29 -> 17.5 | C37: =C30-C29 -> 11.99404 | D37: =D30-D29 -> 7 | E37: =E30-E29 -> 23 | F37: =F30-F29 -> 10.25 | G37: =G30-G29 -> 12
A38: For the Whiskers
A39: Q3+1.5*IQR | B39: =B30+1.5*B32 -> 140.75 | C39: =C30+1.5*C32 -> 58.135659 | D39: =D30+1.5*D32 -> 124.5 | E39: =E30+1.5*E32 -> 207.5 | F39: =F30+1.5*F32 -> 121.5 | G39: =G30+1.5*G32 -> 87.5
A40: Q1-1.5*IQR | B40: =B28-1.5*B32 -> -21.25 | C40: =C28-1.5*C32 -> -6.5880945 | D40: =D28-1.5*D32 -> 56.5 | E40: =E28-1.5*E32 -> -36.5 | F40: =F28-1.5*F32 -> 47.5 | G40: =G28-1.5*G32 -> 3.5
A41: Upper Whisker | B41: =MIN(B39,B31) -> 108 | C41: =MIN(C39,C31) -> 58.135659 | D41: =MIN(D39,D31) -> 124.5 | E41: =MIN(E39,E31) -> 138 | F41: =MIN(F39,F31) -> 121.5 | G41: =MIN(G39,G31) -> 87.5
A42: Lower Whisker | B42: =MAX(B27,B40) -> 22 | C42: =MAX(C27,C40) -> 12.079733 | D42: =MAX(D27,D40) -> 56.5 | E42: =MAX(E27,E40) -> 40 | F42: =MAX(F27,F40) -> 47.5 | G42: =MAX(G27,G40) -> 22
A43: Wupper-Q3 | B43: =B41-B30 -> 28 | C43: =C41-C30 -> 24.271408 | D43: =D41-D30 -> 25.5 | E43: =E41-E30 -> 22 | F43: =F41-F30 -> 27.75 | G43: =G41-G30 -> 31.5
A44: Q1-Wlower | B44: =B28-B42 -> 17.5 | C44: =C28-C42 -> 5.6035799 | D44: =D28-D42 -> 25.5 | E44: =E28-E42 -> 15 | F44: =F28-F42 -> 27.75 | G44: =G28-G42 -> 13
A45: For the Outliers
A46: Max | B46: =IF(B33>0,B31,NA()) -> #N/A | C46: =IF(C33>0,C31,NA()) -> 78.604551 | D46: =IF(D33>0,D31,NA()) -> 145 | E46: =IF(E33>0,E31,NA()) -> #N/A | F46: =IF(F33>0,F31,NA()) -> 140 | G46: =IF(G33>0,G31,NA()) -> 130
A47: Min | B47: =IF(B34>0,B27,NA()) -> #N/A | C47: =IF(C34>0,C27,NA()) -> #N/A | D47: =IF(D34>0,D27,NA()) -> 30 | E47: =IF(E34>0,E27,NA()) -> #N/A | F47: =IF(F34>0,F27,NA()) -> 10 | G47: =IF(G34>0,G27,NA()) -> #N/A
I48: references expand to include these new rows.
A49: Data Table | B49: =B26 -> Sample 1 | C49: =C26 -> Sample 2 | D49: =D26 -> Sample 3 | E49: =E26 -> Sample 4 | F49: =F26 -> Sample 5 | G49: =G26 -> Sample 6
B50: 52 | C50: 18.158814 | D50: 102 | E50: 116 | F50: 98 | G50: 31
B51: 63 | C51: 17.014401 | D51: 99 | E51: 98 | F51: 97 | G51: 35
...

Sheet BoxPlot2
A1: Box Plot Template
I5: Using This Worksheet
I6: This version of the box plot does not use bar
I7: charts to represent the quartiles. Instead, each
I8: of the series is an X-Y chart, which allows the
I9: data to include negative values. The Median is
I10: represented with an "x" marker and horizontal
I11: markers are used for Q1 and Q3. This is a
I12: more practical approach for creating box plots
I13: in Excel because it does not require shifting
I14: the data as in the BoxPlot_Shifted worksheet.
A26: Labels | B26: Sample 1 | C26: Sample 2 | D26: Sample 3 | E26: Sample 4 | F26: Sample 5 | G26: Sample 6
A27: Min | B27: =MIN(B$50:B$90) -> -48 | C27: =MIN(C$50:C$90) -> -7 | D27: =MIN(D$50:D$90) -> -10 | E27: =MIN(E$50:E$90) -> 10 | F27: =MIN(F$50:F$90) -> -115 | G27: =MIN(G$50:G$90) -> 33
A28: Q1 | B28: =PERCENTILE(B$50:B$90,0.25) -> -29.5 | C28: =PERCENTILE(C$50:C$90,0.25) -> 6 | D28: =PERCENTILE(D$50:D$90,0.25) -> 42 | E28: =PERCENTILE(E$50:E$90,0.25) -> 34.5 | F28: =PERCENTILE(F$50:F$90,0.25) -> -49.5 | G28: =PERCENTILE(G$50:G$90,0.25) -> 46
A29: Median | B29: =MEDIAN(B$50:B$90) -> -7.5 | C29: =MEDIAN(C$50:C$90) -> 19.5 | D29: =MEDIAN(D$50:D$90) -> 52 | E29: =MEDIAN(E$50:E$90) -> 45 | F29: =MEDIAN(F$50:F$90) -> -41 | G29: =MEDIAN(G$50:G$90) -> 54
A30: Q3 | B30: =PERCENTILE(B$50:B$90,0.75) -> 11.5 | C30: =PERCENTILE(C$50:C$90,0.75) -> 24.75 | D30: =PERCENTILE(D$50:D$90,0.75) -> 59 | E30: =PERCENTILE(E$50:E$90,0.75) -> 62.5 | F30: =PERCENTILE(F$50:F$90,0.75) -> -30.5 | G30: =PERCENTILE(G$50:G$90,0.75) -> 62
A31: Max | B31: =MAX(B$50:B$90) -> 29 | C31: =MAX(C$50:C$90) -> 30 | D31: =MAX(D$50:D$90) -> 105 | E31: =MAX(E$50:E$90) -> 86 | F31: =MAX(F$50:F$90) -> 25 | G31: =MAX(G$50:G$90) -> 100
A32: IQR | B32: =B30-B28 -> 41 | C32: =C30-C28 -> 18.75 | D32: =D30-D28 -> 17 | E32: =E30-E28 -> 28 | F32: =F30-F28 -> 19 | G32: =G30-G28 -> 16
A33: Upper Outliers | B33: =COUNTIF(B$50:B$90,">"&B39) -> 0 | C33: =COUNTIF(C$50:C$90,">"&C39) -> 0 | D33: =COUNTIF(D$50:D$90,">"&D39) -> 2 | E33: =COUNTIF(E$50:E$90,">"&E39) -> 0 | F33: =COUNTIF(F$50:F$90,">"&F39) -> 3 | G33: =COUNTIF(G$50:G$90,">"&G39) -> 1
A34: Lower Outliers | B34: =COUNTIF(B$50:B$90,"<"&B40) -> 0 | C34: =COUNTIF(C$50:C$90,"<"&C40) -> 0 | D34: =COUNTIF(D$50:D$90,"<"&D40) -> 1 | E34: =COUNTIF(E$50:E$90,"<"&E40) -> 0 | F34: =COUNTIF(F$50:F$90,"<"&F40) -> 2 | G34: =COUNTIF(G$50:G$90,"<"&G40) -> 0
A35: For the Box (IQR and Median)
A36: Q2-Q1 | B36: =B29-B28 -> 22 | C36: =C29-C28 -> 13.5 | D36: =D29-D28 -> 10 | E36: =E29-E28 -> 10.5 | F36: =F29-F28 -> 8.5 | G36: =G29-G28 -> 8
A37: Q3-Q2 | B37: =B30-B29 -> 19 | C37: =C30-C29 -> 5.25 | D37: =D30-D29 -> 7 | E37: =E30-E29 -> 17.5 | F37: =F30-F29 -> 10.5 | G37: =G30-G29 -> 8
A38: For the Whiskers
A39: Q3+1.5*IQR | B39: =B30+1.5*B32 -> 73 | C39: =C30+1.5*C32 -> 52.875 | D39: =D30+1.5*D32 -> 84.5 | E39: =E30+1.5*E32 -> 104.5 | F39: =F30+1.5*F32 -> -2 | G39: =G30+1.5*G32 -> 86
A40: Q1-1.5*IQR | B40: =B28-1.5*B32 -> -91 | C40: =C28-1.5*C32 -> -22.125 | D40: =D28-1.5*D32 -> 16.5 | E40: =E28-1.5*E32 -> -7.5 | F40: =F28-1.5*F32 -> -78 | G40: =G28-1.5*G32 -> 22
A41: Upper Whisker | B41: =MIN(B39,B31) -> 29 | C41: =MIN(C39,C31) -> 30 | D41: =MIN(D39,D31) -> 84.5 | E41: =MIN(E39,E31) -> 86 | F41: =MIN(F39,F31) -> -2 | G41: =MIN(G39,G31) -> 86
A42: Lower Whisker | B42: =MAX(B27,B40) -> -48 | C42: =MAX(C27,C40) -> -7 | D42: =MAX(D27,D40) -> 16.5 | E42: =MAX(E27,E40) -> 10 | F42: =MAX(F27,F40) -> -78 | G42: =MAX(G27,G40) -> 33
A43: Wupper-Q3 | B43: =B41-B30 -> 17.5 | C43: =C41-C30 -> 5.25 | D43: =D41-D30 -> 25.5 | E43: =E41-E30 -> 23.5 | F43: =F41-F30 -> 28.5 | G43: =G41-G30 -> 24
A44: Q1-Wlower | B44: =B28-B42 -> 18.5 | C44: =C28-C42 -> 13 | D44: =D28-D42 -> 25.5 | E44: =E28-E42 -> 24.5 | F44: =F28-F42 -> 28.5 | G44: =G28-G42 -> 13
A45: For the Outliers
A46: Max | B46: =IF(B33>0,B31,NA()) -> #N/A | C46: =IF(C33>0,C31,NA()) -> #N/A | D46: =IF(D33>0,D31,NA()) -> 105 | E46: =IF(E33>0,E31,NA()) -> #N/A | F46: =IF(F33>0,F31,NA()) -> 25 | G46: =IF(G33>0,G31,NA()) -> 100
A47: Min | B47: =IF(B34>0,B27,NA()) -> #N/A | C47: =IF(C34>0,C27,NA()) -> #N/A | D47: =IF(D34>0,D27,NA()) -> -10 | E47: =IF(E34>0,E27,NA()) -> #N/A | F47: =IF(F34>0,F27,NA()) -> -115 | G47: =IF(G34>0,G27,NA()) -> #N/A
A49: Data Table
B50: -41 | C50: 28 | D50: 62 | E50: 42 | F50: -27
B51: -7 | C51: 27 | D51: 59 | E51: 27 | F51: -28
B52: -12 | C52: 24 | D52: 62 | E52: 49 | F52: -31 | G52: 100
B53: -48 | C53: 28 | D53: 60 | E53: 58 | F53: -27
B54: -26 | C54: 26 | D54: 66 | E54: 29 | F54: -29
B55: -30 | C55: 13 | D55: 51 | E55: 45 | F55: -42 | G55: 53
...

Sheet BoxPlot_Shifted
A1: Box Plot Template
A3: ="Note: All values represent X + "&shift&" where X is the original data" -> Note: All values represent X + 140 where X is the original data
I5: Using This Worksheet
I6: If your data contains negative values, then using
I7: bar charts to display the interquartile range
I8: requires that the data be shifted so that it is all
I9: positive.In the BoxPlot worksheet, the use of bar
I10: charts to create the interquartile ranges requires
I11: that the...
I13: This worksheet is basically the same as the
I14: BoxPlot worksheet except that it is set up to
I15: allow negative values reference the Data_Shifted
I16: worksheet. This makes it easier to delete existing
I17: data and add your own data sets of any length
... I26: to include the new data set.
A28: Labels | B28: Sample 1 | C28: Sample 2 | D28: Sample 3 | E28: Sample 4 | F28: Sample 5 | G28: Sample 6 | I28: Important: After inserting a new column, you
A29: Min | B29: =MIN(Data_Shifted!A:A) -> 92 | C29: =MIN(Data_Shifted!B:B) -> 133 | D29: =MIN(Data_Shifted!C:C) -> 170 | E29: =MIN(Data_Shifted!D:D) -> 150 | F29: =MIN(Data_Shifted!E:E) -> 0 | G29: =MIN(Data_Shifted!F:F) -> 203 | I29: will need to update the references in the formulas
A30: Q1 | B30: =PERCENTILE(Data_Shifted!A:A,0.25) -> 110.5 | C30: =PERCENTILE(Data_Shifted!B:B,0.25) -> 146 | D30: =PERCENTILE(Data_Shifted!C:C,0.25) -> 222 | E30: =PERCENTILE(Data_Shifted!D:D,0.25) -> 174.5 | F30: =PERCENTILE(Data_Shifted!E:E,0.25) -> 65.25 | G30: =PERCENTILE(Data_Shifted!F:F,0.25) -> 216 | I30: to refer to the correct column in the Data sheet.
A31: Median | B31: =MEDIAN(Data_Shifted!A:A) -> 132.5 | C31: =MEDIAN(Data_Shifted!B:B) -> 159.5 | D31: =MEDIAN(Data_Shifted!C:C) -> 232 | E31: =MEDIAN(Data_Shifted!D:D) -> 185 | F31: =MEDIAN(Data_Shifted!E:E) -> 73.5 | G31: =MEDIAN(Data_Shifted!F:F) -> 224 | I31: You can do this by copying cells B27:B49 (the
A32: Q3 | B32: =PERCENTILE(Data_Shifted!A:A,0.75) -> 151.5 | C32: =PERCENTILE(Data_Shifted!B:B,0.75) -> 164.75 | D32: =PERCENTILE(Data_Shifted!C:C,0.75) -> 239 | E32: =PERCENTILE(Data_Shifted!D:D,0.75) -> 202.5 | F32: =PERCENTILE(Data_Shifted!E:E,0.75) -> 83.75 | G32: =PERCENTILE(Data_Shifted!F:F,0.75) -> 232 | I32: formulas for Sample 1) to the right to fill in the
A33: Max | B33: =MAX(Data_Shifted!A:A) -> 169 | C33: =MAX(Data_Shifted!B:B) -> 170 | D33: =MAX(Data_Shifted!C:C) -> 285 | E33: =MAX(Data_Shifted!D:D) -> 226 | F33: =MAX(Data_Shifted!E:E) -> 130 | G33: =MAX(Data_Shifted!F:F) -> 270 | I33: formulas for the other samples. Rows 37-49 are
A34: IQR | B34: =B32-B30 -> 41 | C34: =C32-C30 -> 18.75 | D34: =D32-D30 -> 17 | E34: =E32-E30 -> 28 | F34: =F32-F30 -> 18.5 | G34: =G32-G30 -> 16 | I34: unhidden so that you don't forget to include these
A35: Upper Outliers | B35: =COUNTIF(Data_Shifted!A:A,">"&B43) -> 0 | C35: =COUNTIF(Data_Shifted!B:B,">"&C43) -> 0 | D35: =COUNTIF(Data_Shifted!C:C,">"&D43) -> 2 | E35: =COUNTIF(Data_Shifted!D:D,">"&E43) -> 0 | F35: =COUNTIF(Data_Shifted!E:E,">"&F43) -> 2 | G35: =COUNTIF(Data_Shifted!F:F,">"&G43) -> 1 | I35: cells when updating the formulas. You can hide
A36: Lower Outliers | B36: =COUNTIF(Data_Shifted!A:A,"<"&B44) -> 0 | C36: =COUNTIF(Data_Shifted!B:B,"<"&C44) -> 0 | D36: =COUNTIF(Data_Shifted!C:C,"<"&D44) -> 1 | E36: =COUNTIF(Data_Shifted!D:D,"<"&E44) -> 0 | F36: =COUNTIF(Data_Shifted!E:E,"<"&F44) -> 2 | G36: =COUNTIF(Data_Shifted!F:F,"<"&G44) -> 0 | I36: these rows if you want to unclutter the worksheet.
A37: Zero Offset | B37: =shift -> 140 | C37: =shift -> 140 | D37: =shift -> 140 | E37: =shift -> 140 | F37: =shift -> 140 | G37: =shift -> 140
A39: For the Box (IQR and Median)
A40: Q2-Q1 | B40: =B31-B30 -> 22 | C40: =C31-C30 -> 13.5 | D40: =D31-D30 -> 10 | E40: =E31-E30 -> 10.5 | F40: =F31-F30 -> 8.25 | G40: =G31-G30 -> 8
A41: Q3-Q2 | B41: =B32-B31 -> 19 | C41: =C32-C31 -> 5.25 | D41: =D32-D31 -> 7 | E41: =E32-E31 -> 17.5 | F41: =F32-F31 -> 10.25 | G41: =G32-G31 -> 8
A42: For the Whiskers
A43: Q3+1.5*IQR | B43: =B32+1.5*B34 -> 213 | C43: =C32+1.5*C34 -> 192.875 | D43: =D32+1.5*D34 -> 264.5 | E43: =E32+1.5*E34 -> 244.5 | F43: =F32+1.5*F34 -> 111.5 | G43: =G32+1.5*G34 -> 256
A44: Q1-1.5*IQR | B44: =B30-1.5*B34 -> 49 | C44: =C30-1.5*C34 -> 117.875 | D44: =D30-1.5*D34 -> 196.5 | E44: =E30-1.5*E34 -> 132.5 | F44: =F30-1.5*F34 -> 37.5 | G44: =G30-1.5*G34 -> 192
A45: Upper Whisker | B45: =MIN(B43,B33) -> 169 | C45: =MIN(C43,C33) -> 170 | D45: =MIN(D43,D33) -> 264.5 | E45: =MIN(E43,E33) -> 226 | F45: =MIN(F43,F33) -> 111.5 | G45: =MIN(G43,G33) -> 256
A46: Lower Whisker | B46: =MAX(B29,B44) -> 92 | C46: =MAX(C29,C44) -> 133 | D46: =MAX(D29,D44) -> 196.5 | E46: =MAX(E29,E44) -> 150 | F46: =MAX(F29,F44) -> 37.5 | G46: =MAX(G29,G44) -> 203
A47: Wupper-Q3 | B47: =B45-B32 -> 17.5 | C47: =C45-C32 -> 5.25 | D47: =D45-D32 -> 25.5 | E47: =E45-E32 -> 23.5 | F47: =F45-F32 -> 27.75 | G47: =G45-G32 -> 24
A48: Q1-Wlower | B48: =B30-B46 -> 18.5 | C48: =C30-C46 -> 13 | D48: =D30-D46 -> 25.5 | E48: =E30-E46 -> 24.5 | F48: =F30-F46 -> 27.75 | G48: =G30-G46 -> 13
A49: For the Outliers
A50: Max | B50: =IF(B35>0,B33,NA()) -> #N/A | C50: =IF(C35>0,C33,NA()) -> #N/A | D50: =IF(D35>0,D33,NA()) -> 285 | E50: =IF(E35>0,E33,NA()) -> #N/A | F50: =IF(F35>0,F33,NA()) -> 130 | G50: =IF(G35>0,G33,NA()) -> 270
A51: Min | B51: =IF(B36>0,B29,NA()) -> #N/A | C51: =IF(C36>0,C29,NA()) -> #N/A | D51: =IF(D36>0,D29,NA()) -> 170 | E51: =IF(E36>0,E29,NA()) -> #N/A | F51: =IF(F36>0,F29,NA()) -> 0 | G51: =IF(G36>0,G29,NA()) -> #N/A

Sheet Data_Shifted
A1: =IF(OFFSET(INDIRECT("Data!A1"),ROW()-1,COLUMN()-1,1,1)="","",$I$1+OFFSET(INDIRECT("Data!A1"),ROW()-1,COLUMN()-1,1,1)) -> 99 | B1: =IF(OFFSET(INDIRECT("Data!A1"),ROW()-1,COLUMN()-1,1,1)="","",$I$1+OFFSET(INDIRECT("Data!A1"),ROW()-1,COLUMN()-1,1,1)) -> 168 | C1: =IF(OFFSET(INDIRECT("Data!A1"),ROW()-1,COLUMN()-1,1,1)="","",$I$1+OFFSET(INDIRECT("Data!A1"),ROW()-1,COLUMN()-1,1,1)) -> 242 | D1: =IF(OFFSET(INDIRECT("Data!A1"),ROW()-1,COLUMN()-1,1,1)="","",$I$1+OFFSET(INDIRECT("Data!A1"),ROW()-1,COLUMN()-1,1,1)) -> 182 | E1: =IF(OFFSET(INDIRECT("Data!A1"),ROW()-1,COLUMN()-1,1,1)="","",$I$1+OFFSET(INDIRECT("Data!A1"),ROW()-1,COLUMN()-1,1,1)) -> 88 | F1: =IF(OFFSET(INDIRECT("Data!A1"),ROW()-1,COLUMN()-1,1,1)="","",$I$1+OFFSET(INDIRECT("Data!A1"),ROW()-1,COLUMN()-1,1,1)) | H1: SHIFT: | I1: =ABS(MIN(0,MIN(Data!A1:F48))) -> 140
A2: =IF(OFFSET(INDIRECT("Data!A1"),ROW()-1,COLUMN()-1,1,1)="","",$I$1+OFFSET(INDIRECT("Data!A1"),ROW()-1,COLUMN()-1,1,1)) -> 133 | B2: =IF(OFFSET(INDIRECT("Data!A1"),ROW()-1,COLUMN()-1,1,1)="","",$I$1+OFFSET(INDIRECT("Data!A1"),ROW()-1,COLUMN()-1,1,1)) -> 167 | C2: =IF(OFFSET(INDIRECT("Data!A1"),ROW()-1,COLUMN()-1,1,1)="","",$I$1+OFFSET(INDIRECT("Data!A1"),ROW()-1,COLUMN()-1,1,1)) -> 239 | D2: =IF(OFFSET(INDIRECT("Data!A1"),ROW()-1,COLUMN()-1,1,1)="","",$I$1+OFFSET(INDIRECT("Data!A1"),ROW()-1,COLUMN()-1,1,1)) -> 167 | E2: =IF(OFFSET(INDIRECT("Data!A1"),ROW()-1,COLUMN()-1,1,1)="","",$I$1+OFFSET(INDIRECT("Data!A1"),ROW()-1,COLUMN()-1,1,1)) -> 87 | F2: =IF(OFFSET(INDIRECT("Data!A1"),ROW()-1,COLUMN()-1,1,1)="","",$I$1+OFFSET(INDIRECT("Data!A1"),ROW()-1,COLUMN()-1,1,1))
A3: =IF(OFFSET(INDIRECT("Data!A1"),ROW()-1,COLUMN()-1,1,1)="","",$I$1+OFFSET(INDIRECT("Data!A1"),ROW()-1,COLUMN()-1,1,1)) -> 128 | B3: =IF(OFFSET(INDIRECT("Data!A1"),ROW()-1,COLUMN()-1,1,1)="","",$I$1+OFFSET(INDIRECT("Data!A1"),ROW()-1,COLUMN()-1,1,1)) -> 164 | C3: =IF(OFFSET(INDIRECT("Data!A1"),ROW()-1,COLUMN()-1,1,1)="","",$I$1+OFFSET(INDIRECT("Data!A1"),ROW()-1,COLUMN()-1,1,1)) -> 242 | D3: =IF(OFFSET(INDIRECT("Data!A1"),ROW()-1,COLUMN()-1,1,1)="","",$I$1+OFFSET(INDIRECT("Data!A1"),ROW()-1,COLUMN()-1,1,1)) -> 189 | E3: =IF(OFFSET(INDIRECT("Data!A1"),ROW()-1,COLUMN()-1,1,1)="","",$I$1+OFFSET(INDIRECT("Data!A1"),ROW()-1,COLUMN()-1,1,1)) -> 84 | F3: =IF(OFFSET(INDIRECT("Data!A1"),ROW()-1,COLUMN()-1,1,1)="","",$I$1+OFFSET(INDIRECT("Data!A1"),ROW()-1,COLUMN()-1,1,1)) | H3: Using This Worksheet
A4: =IF(OFFSET(INDIRECT("Data!A1"),ROW()-1,COLUMN()-1,1,1)="","",$I$1+OFFSET(INDIRECT("Data!A1"),ROW()-1,COLUMN()-1,1,1)) -> 92 | B4: =IF(OFFSET(INDIRECT("Data!A1"),ROW()-1,COLUMN()-1,1,1)="","",$I$1+OFFSET(INDIRECT("Data!A1"),ROW()-1,COLUMN()-1,1,1)) -> 168 | C4: =IF(OFFSET(INDIRECT("Data!A1"),ROW()-1,COLUMN()-1,1,1)="","",$I$1+OFFSET(INDIRECT("Data!A1"),ROW()-1,COLUMN()-1,1,1)) -> 240 | D4: =IF(OFFSET(INDIRECT("Data!A1"),ROW()-1,COLUMN()-1,1,1)="","",$I$1+OFFSET(INDIRECT("Data!A1"),ROW()-1,COLUMN()-1,1,1)) -> 198 | E4: =IF(OFFSET(INDIRECT("Data!A1"),ROW()-1,COLUMN()-1,1,1)="","",$I$1+OFFSET(INDIRECT("Data!A1"),ROW()-1,COLUMN()-1,1,1)) -> 88 | F4: =IF(OFFSET(INDIRECT("Data!A1"),ROW()-1,COLUMN()-1,1,1)="","",$I$1+OFFSET(INDIRECT("Data!A1"),ROW()-1,COLUMN()-1,1,1)) | H4: This worksheet adds a value to the data in the Data
A5: =IF(OFFSET(INDIRECT("Data!A1"),ROW()-1,COLUMN()-1,1,1)="","",$I$1+OFFSET(INDIRECT("Data!A1"),ROW()-1,COLUMN()-1,1,1)) -> 114 | B5: =IF(OFFSET(INDIRECT("Data!A1"),ROW()-1,COLUMN()-1,1,1)="","",$I$1+OFFSET(INDIRECT("Data!A1"),ROW()-1,COLUMN()-1,1,1)) -> 166 | C5: =IF(OFFSET(INDIRECT("Data!A1"),ROW()-1,COLUMN()-1,1,1)="","",$I$1+OFFSET(INDIRECT("Data!A1"),ROW()-1,COLUMN()-1,1,1)) -> 246 | D5: =IF(OFFSET(INDIRECT("Data!A1"),ROW()-1,COLUMN()-1,1,1)="","",$I$1+OFFSET(INDIRECT("Data!A1"),ROW()-1,COLUMN()-1,1,1)) -> 169 | E5: =IF(OFFSET(INDIRECT("Data!A1"),ROW()-1,COLUMN()-1,1,1)="","",$I$1+OFFSET(INDIRECT("Data!A1"),ROW()-1,COLUMN()-1,1,1)) -> 86 | F5: =IF(OFFSET(INDIRECT("Data!A1"),ROW()-1,COLUMN()-1,1,1)="","",$I$1+OFFSET(INDIRECT("Data!A1"),ROW()-1,COLUMN()-1,1,1)) | H5: worksheet so that all the values are positive.The
A6: =IF(OFFSET(INDIRECT("Data!A1"),ROW()-1,COLUMN()-1,1,1)="","",$I$1+OFFSET(INDIRECT("Data!A1"),ROW()-1,COLUMN()-1,1,1)) -> 110 | B6: =IF(OFFSET(INDIRECT("Data!A1"),ROW()-1,COLUMN()-1,1,1)="","",$I$1+OFFSET(INDIRECT("Data!A1"),ROW()-1,COLUMN()-1,1,1)) -> 153 | C6: =IF(OFFSET(INDIRECT("Data!A1"),ROW()-1,COLUMN()-1,1,1)="","",$I$1+OFFSET(INDIRECT("Data!A1"),ROW()-1,COLUMN()-1,1,1)) -> 231 | D6: =IF(OFFSET(INDIRECT("Data!A1"),ROW()-1,COLUMN()-1,1,1)="","",$I$1+OFFSET(INDIRECT("Data!A1"),ROW()-1,COLUMN()-1,1,1)) -> 185 | E6: =IF(OFFSET(INDIRECT("Data!A1"),ROW()-1,COLUMN()-1,1,1)="","",$I$1+OFFSET(INDIRECT("Data!A1"),ROW()-1,COLUMN()-1,1,1)) -> 73 | F6: =IF(OFFSET(INDIRECT("Data!A1"),ROW()-1,COLUMN()-1,1,1)="","",$I$1+OFFSET(INDIRECT("Data!A1"),ROW()-1,COLUMN()-1,1,1)) -> 223 | H6: chart in the BoxPlot_Shifted worksheet references
A7: =IF(OFFSET(INDIRECT("Data!A1"),ROW()-1,COLUMN()-1,1,1)="","",$I$1+OFFSET(INDIRECT("Data!A1"),ROW()-1,COLUMN()-1,1,1)) -> 152 | B7: =IF(OFFSET(INDIRECT("Data!A1"),ROW()-1,COLUMN()-1,1,1)="","",$I$1+OFFSET(INDIRECT("Data!A1"),ROW()-1,COLUMN()-1,1,1)) -> 145 | C7: =IF(OFFSET(INDIRECT("Data!A1"),ROW()-1,COLUMN()-1,1,1)="","",$I$1+OFFSET(INDIRECT("Data!A1"),ROW()-1,COLUMN()-1,1,1)) -> 222 | D7: =IF(OFFSET(INDIRECT("Data!A1"),ROW()-1,COLUMN()-1,1,1)="","",$I$1+OFFSET(INDIRECT("Data!A1"),ROW()-1,COLUMN()-1,1,1)) -> 183 | E7: =IF(OFFSET(INDIRECT("Data!A1"),ROW()-1,COLUMN()-1,1,1)="","",$I$1+OFFSET(INDIRECT("Data!A1"),ROW()-1,COLUMN()-1,1,1)) -> 65 | F7: =IF(OFFSET(INDIRECT("Data!A1"),ROW()-1,COLUMN()-1,1,1)="","",$I$1+OFFSET(INDIRECT("Data!A1"),ROW()-1,COLUMN()-1,1,1)) -> 215 | H7: the data on this worksheet.
A8: =IF(OFFSET(INDIRECT("Data!A1"),ROW()-1,COLUMN()-1,1,1)="","",$I$1+OFFSET(INDIRECT("Data!A1"),ROW()-1,COLUMN()-1,1,1)) -> 113 | B8: =IF(OFFSET(INDIRECT("Data!A1"),ROW()-1,COLUMN()-1,1,1)="","",$I$1+OFFSET(INDIRECT("Data!A1"),ROW()-1,COLUMN()-1,1,1)) -> 146 | C8: =IF(OFFSET(INDIRECT("Data!A1"),ROW()-1,COLUMN()-1,1,1)="","",$I$1+OFFSET(INDIRECT("Data!A1"),ROW()-1,COLUMN()-1,1,1)) -> 224 | D8: =IF(OFFSET(INDIRECT("Data!A1"),ROW()-1,COLUMN()-1,1,1)="","",$I$1+OFFSET(INDIRECT("Data!A1"),ROW()-1,COLUMN()-1,1,1)) -> 168 | E8: =IF(OFFSET(INDIRECT("Data!A1"),ROW()-1,COLUMN()-1,1,1)="","",$I$1+OFFSET(INDIRECT("Data!A1"),ROW()-1,COLUMN()-1,1,1)) -> 66 | F8: =IF(OFFSET(INDIRECT("Data!A1"),ROW()-1,COLUMN()-1,1,1)="","",$I$1+OFFSET(INDIRECT("Data!A1"),ROW()-1,COLUMN()-1,1,1)) -> 216
A9: =IF(OFFSET(INDIRECT("Data!A1"),ROW()-1,COLUMN()-1,1,1)="","",$I$1+OFFSET(INDIRECT("Data!A1"),ROW()-1,COLUMN()-1,1,1)) -> 112 | B9: =IF(OFFSET(INDIRECT("Data!A1"),ROW()-1,COLUMN()-1,1,1)="","",$I$1+OFFSET(INDIRECT("Data!A1"),ROW()-1,COLUMN()-1,1,1)) -> 142 | C9: =IF(OFFSET(INDIRECT("Data!A1"),ROW()-1,COLUMN()-1,1,1)="","",$I$1+OFFSET(INDIRECT("Data!A1"),ROW()-1,COLUMN()-1,1,1)) -> 215 | D9: =IF(OFFSET(INDIRECT("Data!A1"),ROW()-1,COLUMN()-1,1,1)="","",$I$1+OFFSET(INDIRECT("Data!A1"),ROW()-1,COLUMN()-1,1,1)) -> 180 | E9: =IF(OFFSET(INDIRECT("Data!A1"),ROW()-1,COLUMN()-1,1,1)="","",$I$1+OFFSET(INDIRECT("Data!A1"),ROW()-1,COLUMN()-1,1,1)) -> 62 | F9: =IF(OFFSET(INDIRECT("Data!A1"),ROW()-1,COLUMN()-1,1,1)="","",$I$1+OFFSET(INDIRECT("Data!A1"),ROW()-1,COLUMN()-1,1,1)) -> 212
A10: =IF(OFFSET(INDIRECT("Data!A1"),ROW()-1,COLUMN()-1,1,1)="","",$I$1+OFFSET(INDIRECT("Data!A1"),ROW()-1,COLUMN()-1,1,1)) -> 103 | B10: =IF(OFFSET(INDIRECT("Data!A1"),ROW()-1,COLUMN()-1,1,1)="","",$I$1+OFFSET(INDIRECT("Data!A1"),ROW()-1,COLUMN()-1,1,1)) -> 154 | C10: =IF(OFFSET(INDIRECT("Data!A1"),ROW()-1,COLUMN()-1,1,1)="","",$I$1+OFFSET(INDIRECT("Data!A1"),ROW()-1,COLUMN()-1,1,1)) -> 233 | D10: =IF(OFFSET(INDIRECT("Data!A1"),ROW()-1,COLUMN()-1,1,1)="","",$I$1+OFFSET(INDIRECT("Data!A1"),ROW()-1,COLUMN()-1,1,1)) -> 166 | E10: =IF(OFFSET(INDIRECT("Data!A1"),ROW()-1,COLUMN()-1,1,1)="","",$I$1+OFFSET(INDIRECT("Data!A1"),ROW()-1,COLUMN()-1,1,1)) -> 74 | F10: =IF(OFFSET(INDIRECT("Data!A1"),ROW()-1,COLUMN()-1,1,1)="","",$I$1+OFFSET(INDIRECT("Data!A1"),ROW()-1,COLUMN()-1,1,1)) -> 224
A11: =IF(OFFSET(INDIRECT("Data!A1"),ROW()-1,COLUMN()-1,1,1)="","",$I$1+OFFSET(INDIRECT("Data!A1"),ROW()-1,COLUMN()-1,1,1)) -> 149 | B11: =IF(OFFSET(INDIRECT("Data!A1"),ROW()-1,COLUMN()-1,1,1)="","",$I$1+OFFSET(INDIRECT("Data!A1"),ROW()-1,COLUMN()-1,1,1)) -> 159 | C11: =IF(OFFSET(INDIRECT("Data!A1"),ROW()-1,COLUMN()-1,1,1)="","",$I$1+OFFSET(INDIRECT("Data!A1"),ROW()-1,COLUMN()-1,1,1)) -> 238 | D11: =IF(OFFSET(INDIRECT("Data!A1"),ROW()-1,COLUMN()-1,1,1)="","",$I$1+OFFSET(INDIRECT("Data!A1"),ROW()-1,COLUMN()-1,1,1)) -> 182 | E11: =IF(OFFSET(INDIRECT("Data!A1"),ROW()-1,COLUMN()-1,1,1)="","",$I$1+OFFSET(INDIRECT("Data!A1"),ROW()-1,COLUMN()-1,1,1)) -> 79 | F11: =IF(OFFSET(INDIRECT("Data!A1"),ROW()-1,COLUMN()-1,1,1)="","",$I$1+OFFSET(INDIRECT("Data!A1"),ROW()-1,COLUMN()-1,1,1)) -> 229
A12: =IF(OFFSET(INDIRECT("Data!A1"),ROW()-1,COLUMN()-1,1,1)="","",$I$1+OFFSET(INDIRECT("Data!A1"),ROW()-1,COLUMN()-1,1,1)) -> 92 | B12: =IF(OFFSET(INDIRECT("Data!A1"),ROW()-1,COLUMN()-1,1,1)="","",$I$1+OFFSET(INDIRECT("Data!A1"),ROW()-1,COLUMN()-1,1,1)) -> 160 | C12: =IF(OFFSET(INDIRECT("Data!A1"),ROW()-1,COLUMN()-1,1,1)="","",$I$1+OFFSET(INDIRECT("Data!A1"),ROW()-1,COLUMN()-1,1,1)) -> 237 | D12: =IF(OFFSET(INDIRECT("Data!A1"),ROW()-1,COLUMN()-1,1,1)="","",$I$1+OFFSET(INDIRECT("Data!A1"),ROW()-1,COLUMN()-1,1,1)) -> 204 | E12: =IF(OFFSET(INDIRECT("Data!A1"),ROW()-1,COLUMN()-1,1,1)="","",$I$1+OFFSET(INDIRECT("Data!A1"),ROW()-1,COLUMN()-1,1,1)) -> 80 | F12: =IF(OFFSET(INDIRECT("Data!A1"),ROW()-1,COLUMN()-1,1,1)="","",$I$1+OFFSET(INDIRECT("Data!A1"),ROW()-1,COLUMN()-1,1,1)) -> 230
A13: =IF(OFFSET(INDIRECT("Data!A1"),ROW()-1,COLUMN()-1,1,1)="","",$I$1+OFFSET(INDIRECT("Data!A1"),ROW()-1,COLUMN()-1,1,1)) -> 147 | B13: =IF(OFFSET(INDIRECT("Data!A1"),ROW()-1,COLUMN()-1,1,1)="","",$I$1+OFFSET(INDIRECT("Data!A1"),ROW()-1,COLUMN()-1,1,1)) -> 162 | C13: =IF(OFFSET(INDIRECT("Data!A1"),ROW()-1,COLUMN()-1,1,1)="","",$I$1+OFFSET(INDIRECT("Data!A1"),ROW()-1,COLUMN()-1,1,1)) -> 239 | D13: =IF(OFFSET(INDIRECT("Data!A1"),ROW()-1,COLUMN()-1,1,1)="","",$I$1+OFFSET(INDIRECT("Data!A1"),ROW()-1,COLUMN()-1,1,1)) -> 200 | E13: =IF(OFFSET(INDIRECT("Data!A1"),ROW()-1,COLUMN()-1,1,1)="","",$I$1+OFFSET(INDIRECT("Data!A1"),ROW()-1,COLUMN()-1,1,1)) -> 82 | F13: =IF(OFFSET(INDIRECT("Data!A1"),ROW()-1,COLUMN()-1,1,1)="","",$I$1+OFFSET(INDIRECT("Data!A1"),ROW()-1,COLUMN()-1,1,1)) -> 232
A14: =IF(OFFSET(INDIRECT("Data!A1"),ROW()-1,COLUMN()-1,1,1)="","",$I$1+OFFSET(INDIRECT("Data!A1"),ROW()-1,COLUMN()-1,1,1)) -> 138 | B14: =IF(OFFSET(INDIRECT("Data!A1"),ROW()-1,COLUMN()-1,1,1)="","",$I$1+OFFSET(INDIRECT("Data!A1"),ROW()-1,COLUMN()-1,1,1)) -> 165 | C14: =IF(OFFSET(INDIRECT("Data!A1"),ROW()-1,COLUMN()-1,1,1)="","",$I$1+OFFSET(INDIRECT("Data!A1"),ROW()-1,COLUMN()-1,1,1)) -> 236 | D14: =IF(OFFSET(INDIRECT("Data!A1"),ROW()-1,COLUMN()-1,1,1)="","",$I$1+OFFSET(INDIRECT("Data!A1"),ROW()-1,COLUMN()-1,1,1)) -> 166 | E14: =IF(OFFSET(INDIRECT("Data!A1"),ROW()-1,COLUMN()-1,1,1)="","",$I$1+OFFSET(INDIRECT("Data!A1"),ROW()-1,COLUMN()-1,1,1)) -> 85 | F14: =IF(OFFSET(INDIRECT("Data!A1"),ROW()-1,COLUMN()-1,1,1)="","",$I$1+OFFSET(INDIRECT("Data!A1"),ROW()-1,COLUMN()-1,1,1)) -> 235
A15: =IF(OFFSET(INDIRECT("Data!A1"),ROW()-1,COLUMN()-1,1,1)="","",$I$1+OFFSET(INDIRECT("Data!A1"),ROW()-1,COLUMN()-1,1,1)) -> 98 | B15: =IF(OFFSET(INDIRECT("Data!A1"),ROW()-1,COLUMN()-1,1,1)="","",$I$1+OFFSET(INDIRECT("Data!A1"),ROW()-1,COLUMN()-1,1,1)) -> 161 | C15: =IF(OFFSET(INDIRECT("Data!A1"),ROW()-1,COLUMN()-1,1,1)="","",$I$1+OFFSET(INDIRECT("Data!A1"),ROW()-1,COLUMN()-1,1,1)) -> 232 | D15: =IF(OFFSET(INDIRECT("Data!A1"),ROW()-1,COLUMN()-1,1,1)="","",$I$1+OFFSET(INDIRECT("Data!A1"),ROW()-1,COLUMN()-1,1,1)) -> 219 | E15: =IF(OFFSET(INDIRECT("Data!A1"),ROW()-1,COLUMN()-1,1,1)="","",$I$1+OFFSET(INDIRECT("Data!A1"),ROW()-1,COLUMN()-1,1,1)) -> 81 | F15: =IF(OFFSET(INDIRECT("Data!A1"),ROW()-1,COLUMN()-1,1,1)="","",$I$1+OFFSET(INDIRECT("Data!A1"),ROW()-1,COLUMN()-1,1,1)) -> 231
A16: =IF(OFFSET(INDIRECT("Data!A1"),ROW()-1,COLUMN()-1,1,1)="","",$I$1+OFFSET(INDIRECT("Data!A1"),ROW()-1,COLUMN()-1,1,1)) -> 133 | B16: =IF(OFFSET(INDIRECT("Data!A1"),ROW()-1,COLUMN()-1,1,1)="","",$I$1+OFFSET(INDIRECT("Data!A1"),ROW()-1,COLUMN()-1,1,1)) -> 169 | C16: =IF(OFFSET(INDIRECT("Data!A1"),ROW()-1,COLUMN()-1,1,1)="","",$I$1+OFFSET(INDIRECT("Data!A1"),ROW()-1,COLUMN()-1,1,1)) -> 248 | D16: =IF(OFFSET(INDIRECT("Data!A1"),ROW()-1,COLUMN()-1,1,1)="","",$I$1+OFFSET(INDIRECT("Data!A1"),ROW()-1,COLUMN()-1,1,1)) -> 205 | E16: =IF(OFFSET(INDIRECT("Data!A1"),ROW()-1,COLUMN()-1,1,1)="","",$I$1+OFFSET(INDIRECT("Data!A1"),ROW()-1,COLUMN()-1,1,1)) -> 89 | F16: =IF(OFFSET(INDIRECT("Data!A1"),ROW()-1,COLUMN()-1,1,1)="","",$I$1+OFFSET(INDIRECT("Data!A1"),ROW()-1,COLUMN()-1,1,1)) -> 239
A17: =IF(OFFSET(INDIRECT("Data!A1"),ROW()-1,COLUMN()-1,1,1)="","",$I$1+OFFSET(INDIRECT("Data!A1"),ROW()-1,COLUMN()-1,1,1)) -> 152 | B17: =IF(OFFSET(INDIRECT("Data!A1"),ROW()-1,COLUMN()-1,1,1)="","",$I$1+OFFSET(INDIRECT("Data!A1"),ROW()-1,COLUMN()-1,1,1)) -> 170 | C17: =IF(OFFSET(INDIRECT("Data!A1"),ROW()-1,COLUMN()-1,1,1)="","",$I$1+OFFSET(INDIRECT("Data!A1"),ROW()-1,COLUMN()-1,1,1)) -> 242 | D17: =IF(OFFSET(INDIRECT("Data!A1"),ROW()-1,COLUMN()-1,1,1)="","",$I$1+OFFSET(INDIRECT("Data!A1"),ROW()-1,COLUMN()-1,1,1)) -> 226 | E17: =IF(OFFSET(INDIRECT("Data!A1"),ROW()-1,COLUMN()-1,1,1)="","",$I$1+OFFSET(INDIRECT("Data!A1"),ROW()-1,COLUMN()-1,1,1)) -> 90 | F17: =IF(OFFSET(INDIRECT("Data!A1"),ROW()-1,COLUMN()-1,1,1)="","",$I$1+OFFSET(INDIRECT("Data!A1"),ROW()-1,COLUMN()-1,1,1)) -> 240
A18: =IF(OFFSET(INDIRECT("Data!A1"),ROW()-1,COLUMN()-1,1,1)="","",$I$1+OFFSET(INDIRECT("Data!A1"),ROW()-1,COLUMN()-1,1,1)) -> 162 | B18: =IF(OFFSET(INDIRECT("Data!A1"),ROW()-1,COLUMN()-1,1,1)="","",$I$1+OFFSET(INDIRECT("Data!A1"),ROW()-1,COLUMN()-1,1,1)) -> 133 | C18: =IF(OFFSET(INDIRECT("Data!A1"),ROW()-1,COLUMN()-1,1,1)="","",$I$1+OFFSET(INDIRECT("Data!A1"),ROW()-1,COLUMN()-1,1,1)) -> 204 | D18: =IF(OFFSET(INDIRECT("Data!A1"),ROW()-1,COLUMN()-1,1,1)="","",$I$1+OFFSET(INDIRECT("Data!A1"),ROW()-1,COLUMN()-1,1,1)) -> 187 | E18: =IF(OFFSET(INDIRECT("Data!A1"),ROW()-1,COLUMN()-1,1,1)="","",$I$1+OFFSET(INDIRECT("Data!A1"),ROW()-1,COLUMN()-1,1,1)) -> 53 | F18: =IF(OFFSET(INDIRECT("Data!A1"),ROW()-1,COLUMN()-1,1,1)="","",$I$1+OFFSET(INDIRECT("Data!A1"),ROW()-1,COLUMN()-1,1,1)) -> 203
A19: =IF(OFFSET(INDIRECT("Data!A1"),ROW()-1,COLUMN()-1,1,1)="","",$I$1+OFFSET(INDIRECT("Data!A1"),ROW()-1,COLUMN()-1,1,1)) -> 156 | B19: =IF(OFFSET(INDIRECT("Data!A1"),ROW()-1,COLUMN()-1,1,1)="","",$I$1+OFFSET(INDIRECT("Data!A1"),ROW()-1,COLUMN()-1,1,1)) -> 144 | C19: =IF(OFFSET(INDIRECT("Data!A1"),ROW()-1,COLUMN()-1,1,1)="","",$I$1+OFFSET(INDIRECT("Data!A1"),ROW()-1,COLUMN()-1,1,1)) -> 224 | D19: =IF(OFFSET(INDIRECT("Data!A1"),ROW()-1,COLUMN()-1,1,1)="","",$I$1+OFFSET(INDIRECT("Data!A1"),ROW()-1,COLUMN()-1,1,1)) -> 201 | E19: =IF(OFFSET(INDIRECT("Data!A1"),ROW()-1,COLUMN()-1,1,1)="","",$I$1+OFFSET(INDIRECT("Data!A1"),ROW()-1,COLUMN()-1,1,1)) -> 64 | F19: =IF(OFFSET(INDIRECT("Data!A1"),ROW()-1,COLUMN()-1,1,1)="","",$I$1+OFFSET(INDIRECT("Data!A1"),ROW()-1,COLUMN()-1,1,1)) -> 214
... A48: =IF(OFFSET(INDIRECT("Data!A1"),ROW()-1,COLUMN()-1,1,1)="","",$I$1+OFFSET(INDIRECT("Data!A1"),ROW()-1,COLUMN()-1,1,1)) | B48: =IF(OFFSET(INDIRECT("Data!A1"),ROW()-1,COLUMN()-1,1,1)="","",$I$1+OFFSET(INDIRECT("Data!A1"),ROW()-1,COLUMN()-1,1,1)) | C48: =IF(OFFSET(INDIRECT("Data!A1"),ROW()-1,COLUMN()-1,1,1)="","",$I$1+OFFSET(INDIRECT("Data!A1"),ROW()-1,COLUMN()-1,1,1)) | D48: =IF(OFFSET(INDIRECT("Data!A1"),ROW()-1,COLUMN()-1,1,1)="","",$I$1+OFFSET(INDIRECT("Data!A1"),ROW()-1,COLUMN()-1,1,1)) | E48: =IF(OFFSET(INDIRECT("Data!A1"),ROW()-1,COLUMN()-1,1,1)="","",$I$1+OFFSET(INDIRECT("Data!A1"),ROW()-1,COLUMN()-1,1,1)) | F48: =IF(OFFSET(INDIRECT("Data!A1"),ROW()-1,COLUMN()-1,1,1)="","",$I$1+OFFSET(INDIRECT("Data!A1"),ROW()-1,COLUMN()-1,1,1))

Sheet Data
A1: -41 | B1: 28 | C1: 102 | D1: 42 | E1: -52
A2: -7 | B2: 27 | C2: 99 | D2: 27 | E2: -53
A3: -12 | B3: 24 | C3: 102 | D3: 49 | E3: -56 | H3: Using This Worksheet
A4: -48 | B4: 28 | C4: 100 | D4: 58 | E4: -52 | H4: This worksheet is where you enter your data for the
A5: -26 | B5: 26 | C5: 106 | D5: 29 | E5: -54 | H5: chart in the BoxPlot_Shifted worksheet. The
A6: -30 | B6: 13 | C6: 91 | D6: 45 | E6: -67 | F6: 83 | H6: Data_Shifted worksheet first offsets all the data based
A7: 12 | B7: 5 | C7: 82 | D7: 43 | E7: -75 | F7: 75 | H7: on the minimum value, so that all the values are
A8: -27 | B8: 6 | C8: 84 | D8: 28 | E8: -74 | F8: 76 | H8: positive. A relative comparison is still possible.
A9: -28 | B9: 2 | C9: 75 | D9: 40 | E9: -78 | F9: 72
A10: -37 | B10: 14 | C10: 93 | D10: 26 | E10: -66 | F10: 84
A11: 9 | B11: 19 | C11: 98 | D11: 42 | E11: -61 | F11: 89
A12: -48 | B12: 20 | C12: 97 | D12: 64 | E12: -60 | F12: 90
A13: 7 | B13: 22 | C13: 99 | D13: 60 | E13: -58 | F13: 92
A14: -2 | B14: 25 | C14: 96 | D14: 26 | E14: -55 | F14: 95
A15: -42 | B15: 21 | C15: 92 | D15: 79 | E15: -59 | F15: 91
A16: -7 | B16: 29 | C16: 108 | D16: 65 | E16: -51 | F16: 99
A17: 12 | B17: 30 | C17: 102 | D17: 86 | E17: -50 | F17: 100
A18: 22 | B18: -7 | C18: 64 | D18: 47 | E18: -87 | F18: 63
A19: 16 | B19: 4 | C19: 84 | D19: 61 | E19: -76 | F19: 74
A20: 4 | B20: 6 | C20: 77 | D20: 43 | E20: -74 | F20: 76
... A22: 15 | B22: 23 | C22: 97 | D22: 78 | E22: -57 | F22: 93
A23: 18 | B23: 22 | C23: 93 | E23: -58 | F23: 92
A24: -37 | B24: 8 | C24: 85 | E24: -72 | F24: 78
A25: -8 | B25: 3 | C25: 75 | D25: 10 | E25: -77 | F25: 73
A26: -21 | B26: -2 | C26: 70 | E26: -82 | F26: 68
A27: 20 | C27: 91 | E27: -68 | F27: 82
A28: 15 | C28: 95 | E28: -61 | F28: 89
A29: 29 | C29: 94 | E29: -64 | F29: 86
A30: -28 | C30: 78 | E30: -78
A31: -42 | C31: 82 | E31: -76
A32: 10 | C32: 85 | E32: -71
A33: -26 | C33: 85 | E33: -72
A34: -41 | C34: 82 | E34: -69
E36: -130
C37: 30 | E37: -140
C38: 140 | E38: -10 | F38: 130
C39: 145 | E39: -20
