Workbook
Name chart_date: '1-Year'!$K$71:$K$1531
Name chart_values: '1-Year'!$L$71:$L$1531
Name data_labels: Data!$A$1:$G$1
Name holidays: Holidays!$A:$A
Name valuevx: 42.314159

Sheet 4-Year
J1: Calendar Chart
K3: Data Set | AC3: From | AU3: To | BM3: Calendar Start Day
K4: Sample | AC4: 40909 | AU4: 42369 | BM4: Sunday
K5: =MATCH(K4,data_labels,0) -> 2 | BM5: =MATCH(BM4,{"Sunday";"Monday";"Tuesday";"Wednesday";"Thursday";"Friday";"Saturday"},0) -> 1
K7: Summary Stats: | AB7: Max: | AC7: =MAX($K$12:$Q$64,$AC$12:$AI$64,$AU$12:$BA$64,$BM$12:$BS$64) -> 497 | AT7: Min: | AU7: =MIN($K$12:$Q$64,$AC$12:$AI$64,$AU$12:$BA$64,$BM$12:$BS$64) -> 10 | BL7: Median: | BM7: =MEDIAN($K$12:$Q$64,$AC$12:$AI$64,$AU$12:$BA$64,$BM$12:$BS$64) -> 181 | BT7: Avg: | BU7: =AVERAGE($K$12:$Q$64,$AC$12:$AI$64,$AU$12:$BA$64,$BM$12:$BS$64) -> 180.90148
J9: Avg | K9: =IFERROR(AVERAGE(K12:K64),"") -> 29.679245 | L9: =IFERROR(AVERAGE(L12:L64),"") -> 291.39623 | M9: =IFERROR(AVERAGE(M12:M64),"") -> 268.0566 | N9: =IFERROR(AVERAGE(N12:N64),"") -> 231.26415 | O9: =IFERROR(AVERAGE(O12:O64),"") -> 204.07547 | P9: =IFERROR(AVERAGE(P12:P64),"") -> 180.81132 | Q9: =IFERROR(AVERAGE(Q12:Q64),"") -> 59.301887 | AC9: =IFERROR(AVERAGE(AC12:AC64),"") -> 28.339623 | AD9: =IFERROR(AVERAGE(AD12:AD64),"") -> 290.58491 | AE9: =IFERROR(AVERAGE(AE12:AE64),"") -> 255.26415 | AF9: =IFERROR(AVERAGE(AF12:AF64),"") -> 221.84906 | AG9: =IFERROR(AVERAGE(AG12:AG64),"") -> 195.50943 | AH9: =IFERROR(AVERAGE(AH12:AH64),"") -> 176.88679 | AI9: =IFERROR(AVERAGE(AI12:AI64),"") -> 59.698113 | AU9: =IFERROR(AVERAGE(AU12:AU64),"") -> 28.716981 | AV9: =IFERROR(AVERAGE(AV12:AV64),"") -> 294.24528 | AW9: =IFERROR(AVERAGE(AW12:AW64),"") -> 273.98113 | AX9: =IFERROR(AVERAGE(AX12:AX64),"") -> 237.45283 | AY9: =IFERROR(AVERAGE(AY12:AY64),"") -> 206.66038 | AZ9: =IFERROR(AVERAGE(AZ12:AZ64),"") -> 183.01887 | BA9: =IFERROR(AVERAGE(BA12:BA64),"") -> 58.716981 | BM9: =IFERROR(AVERAGE(BM12:BM64),"") -> 29.09434 | BN9: =IFERROR(AVERAGE(BN12:BN64),"") -> 308.66038 | BO9: =IFERROR(AVERAGE(BO12:BO64),"") -> 267.24528 | BP9: =IFERROR(AVERAGE(BP12:BP64),"") -> 238.37736 | BQ9: =IFERROR(AVERAGE(BQ12:BQ64),"") -> 201.54717 | BR9: =IFERROR(AVERAGE(BR12:BR64),"") -> 180.23077 | BS9: =IFERROR(AVERAGE(BS12:BS64),"") -> 62.326923 | BW9: Note: The values you choose for missing data affect averages.
B10: =IF(MONTH(H13)=1,YEAR(H13),YEAR(B12)&"-"&YEAR(H60)) -> 2012 | K10: =B10 -> 2012 | T10: =IF(MONTH(Z13)=1,YEAR(Z13),YEAR(T12)&"-"&YEAR(Z60)) -> 2013 | AC10: =T10 -> 2013 | AL10: =IF(MONTH(AR13)=1,YEAR(AR13),YEAR(AL12)&"-"&YEAR(AR60)) -> 2014 | AU10: =AL10 -> 2014 | BD10: =IF(MONTH(BJ13)=1,YEAR(BJ13),YEAR(BD12)&"-"&YEAR(BJ60)) -> 2015 | BM10: =BD10 -> 2015
B11: =CHOOSE(WEEKDAY(B12,1),"Su","M","Tu","W","Th","F","Sa") -> Su | C11: =CHOOSE(WEEKDAY(C12,1),"Su","M","Tu","W","Th","F","Sa") -> M | D11: =CHOOSE(WEEKDAY(D12,1),"Su","M","Tu","W","Th","F","Sa") -> Tu | E11: =CHOOSE(WEEKDAY(E12,1),"Su","M","Tu","W","Th","F","Sa") -> W | F11: =CHOOSE(WEEKDAY(F12,1),"Su","M","Tu","W","Th","F","Sa") -> Th | G11: =CHOOSE(WEEKDAY(G12,1),"Su","M","Tu","W","Th","F","Sa") -> F | H11: =CHOOSE(WEEKDAY(H12,1),"Su","M","Tu","W","Th","F","Sa") -> Sa | K11: =B11 -> Su | L11: =C11 -> M | M11: =D11 -> Tu | N11: =E11 -> W | O11: =F11 -> Th | P11: =G11 -> F | Q11: =H11 -> Sa | T11: =CHOOSE(WEEKDAY(T12,1),"Su","M","Tu","W","Th","F","Sa") -> Su | U11: =CHOOSE(WEEKDAY(U12,1),"Su","M","Tu","W","Th","F","Sa") -> M | V11: =CHOOSE(WEEKDAY(V12,1),"Su","M","Tu","W","Th","F","Sa") -> Tu | W11: =CHOOSE(WEEKDAY(W12,1),"Su","M","Tu","W","Th","F","Sa") -> W | X11: =CHOOSE(WEEKDAY(X12,1),"Su","M","Tu","W","Th","F","Sa") -> Th | Y11: =CHOOSE(WEEKDAY(Y12,1),"Su","M","Tu","W","Th","F","Sa") -> F | Z11: =CHOOSE(WEEKDAY(Z12,1),"Su","M","Tu","W","Th","F","Sa") -> Sa | AC11: =T11 -> Su | AD11: =U11 -> M | AE11: =V11 -> Tu | AF11: =W11 -> W | AG11: =X11 -> Th | AH11: =Y11 -> F | AI11: =Z11 -> Sa | AL11: =CHOOSE(WEEKDAY(AL12,1),"Su","M","Tu","W","Th","F","Sa") -> Su | AM11: =CHOOSE(WEEKDAY(AM12,1),"Su","M","Tu","W","Th","F","Sa") -> M | AN11: =CHOOSE(WEEKDAY(AN12,1),"Su","M","Tu","W","Th","F","Sa") -> Tu | AO11: =CHOOSE(WEEKDAY(AO12,1),"Su","M","Tu","W","Th","F","Sa") -> W | AP11: =CHOOSE(WEEKDAY(AP12,1),"Su","M","Tu","W","Th","F","Sa") -> Th | AQ11: =CHOOSE(WEEKDAY(AQ12,1),"Su","M","Tu","W","Th","F","Sa") -> F | AR11: =CHOOSE(WEEKDAY(AR12,1),"Su","M","Tu","W","Th","F","Sa") -> Sa | AU11: =AL11 -> Su | AV11: =AM11 -> M | AW11: =AN11 -> Tu | AX11: =AO11 -> W | AY11: =AP11 -> Th | AZ11: =AQ11 -> F | BA11: =AR11 -> Sa | BD11: =CHOOSE(WEEKDAY(BD12,1),"Su","M","Tu","W","Th","F","Sa") -> Su | BE11: =CHOOSE(WEEKDAY(BE12,1),"Su","M","Tu","W","Th","F","Sa") -> M | BF11: =CHOOSE(WEEKDAY(BF12,1),"Su","M","Tu","W","Th","F","Sa") -> Tu | BG11: =CHOOSE(WEEKDAY(BG12,1),"Su","M","Tu","W","Th","F","Sa") -> W | BH11: =CHOOSE(WEEKDAY(BH12,1),"Su","M","Tu","W","Th","F","Sa") -> Th | BI11: =CHOOSE(WEEKDAY(BI12,1),"Su","M","Tu","W","Th","F","Sa") -> F | BJ11: =CHOOSE(WEEKDAY(BJ12,1),"Su","M","Tu","W","Th","F","Sa") -> Sa | BM11: =BD11 -> Su | BN11: =BE11 -> M | BO11: =BF11 -> Tu | BP11: =BG11 -> W | BQ11: =BH11 -> Th | BR11: =BI11 -> F | BS11: =BJ11 -> Sa | BU11: Avg | BW11: Value for Blank Cell: | BX11: 0
B12: =AC4-WEEKDAY(AC4,1)+BM5 -> 40909 | C12: =B12+1 -> 40910 | D12: =C12+1 -> 40911 | E12: =D12+1 -> 40912 | F12: =E12+1 -> 40913 | G12: =F12+1 -> 40914 | H12: =G12+1 -> 40915 | J12: =IF(DAY(B12)=1,"",B12) | K12: =IF(AND(B12>=$AC$4,B12<=$AU$4),IF(""=IFERROR(INDEX(INDIRECT("Data!C"&$K$5,FALSE),MATCH(B12,Data!$A:$A,0)),$BX$12),$BX$11,IFERROR(INDEX(INDIRECT("Data!C"&$K$5,FALSE),MATCH(B12,Data!$A:$A,0)),$BX$12)),"-") -> 19 | L12: =IF(AND(C12>=$AC$4,C12<=$AU$4),IF(""=IFERROR(INDEX(INDIRECT("Data!C"&$K$5,FALSE),MATCH(C12,Data!$A:$A,0)),$BX$12),$BX$11,IFERROR(INDEX(INDIRECT("Data!C"&$K$5,FALSE),MATCH(C12,Data!$A:$A,0)),$BX$12)),"-") -> 298 | M12: =IF(AND(D12>=$AC$4,D12<=$AU$4),IF(""=IFERROR(INDEX(INDIRECT("Data!C"&$K$5,FALSE),MATCH(D12,Data!$A:$A,0)),$BX$12),$BX$11,IFERROR(INDEX(INDIRECT("Data!C"&$K$5,FALSE),MATCH(D12,Data!$A:$A,0)),$BX$12)),"-") -> 176 | N12: =IF(AND(E12>=$AC$4,E12<=$AU$4),IF(""=IFERROR(INDEX(INDIRECT("Data!C"&$K$5,FALSE),MATCH(E12,Data!$A:$A,0)),$BX$12),$BX$11,IFERROR(INDEX(INDIRECT("Data!C"&$K$5,FALSE),MATCH(E12,Data!$A:$A,0)),$BX$12)),"-") -> 113 | O12: =IF(AND(F12>=$AC$4,F12<=$AU$4),IF(""=IFERROR(INDEX(INDIRECT("Data!C"&$K$5,FALSE),MATCH(F12,Data!$A:$A,0)),$BX$12),$BX$11,IFERROR(INDEX(INDIRECT("Data!C"&$K$5,FALSE),MATCH(F12,Data!$A:$A,0)),$BX$12)),"-") -> 217 | P12: =IF(AND(G12>=$AC$4,G12<=$AU$4),IF(""=IFERROR(INDEX(INDIRECT("Data!C"&$K$5,FALSE),MATCH(G12,Data!$A:$A,0)),$BX$12),$BX$11,IFERROR(INDEX(INDIRECT("Data!C"&$K$5,FALSE),MATCH(G12,Data!$A:$A,0)),$BX$12)),"-") -> 185 | Q12: =IF(AND(H12>=$AC$4,H12<=$AU$4),IF(""=IFERROR(INDEX(INDIRECT("Data!C"&$K$5,FALSE),MATCH(H12,Data!$A:$A,0)),$BX$12),$BX$11,IFERROR(INDEX(INDIRECT("Data!C"&$K$5,FALSE),MATCH(H12,Data!$A:$A,0)),$BX$12)),"-") -> 47 | T12: =IF(MONTH(H64)=1,B64,H64+1) -> 41273 | U12: =T12+1 -> 41274 | V12: =U12+1 -> 41275 | W12: =V12+1 -> 41276 | X12: =W12+1 -> 41277 | Y12: =X12+1 -> 41278 | Z12: =Y12+1 -> 41279 | AB12: =IF(DAY(T12)=1,"",T12) -> 41273 | AC12: =IF(AND(T12>=$AC$4,T12<=$AU$4),IF(""=IFERROR(INDEX(INDIRECT("Data!C"&$K$5,FALSE),MATCH(T12,Data!$A:$A,0)),$BX$12),$BX$11,IFERROR(INDEX(INDIRECT("Data!C"&$K$5,FALSE),MATCH(T12,Data!$A:$A,0)),$BX$12)),"-") -> 30 | AD12: =IF(AND(U12>=$AC$4,U12<=$AU$4),IF(""=IFERROR(INDEX(INDIRECT("Data!C"&$K$5,FALSE),MATCH(U12,Data!$A:$A,0)),$BX$12),$BX$11,IFERROR(INDEX(INDIRECT("Data!C"&$K$5,FALSE),MATCH(U12,Data!$A:$A,0)),$BX$12)),"-") -> 123 | AE12: =IF(AND(V12>=$AC$4,V12<=$AU$4),IF(""=IFERROR(INDEX(INDIRECT("Data!C"&$K$5,FALSE),MATCH(V12,Data!$A:$A,0)),$BX$12),$BX$11,IFERROR(INDEX(INDIRECT("Data!C"&$K$5,FALSE),MATCH(V12,Data!$A:$A,0)),$BX$12)),"-") -> 126 | AF12: =IF(AND(W12>=$AC$4,W12<=$AU$4),IF(""=IFERROR(INDEX(INDIRECT("Data!C"&$K$5,FALSE),MATCH(W12,Data!$A:$A,0)),$BX$12),$BX$11,IFERROR(INDEX(INDIRECT("Data!C"&$K$5,FALSE),MATCH(W12,Data!$A:$A,0)),$BX$12)),"-") -> 141 | AG12: =IF(AND(X12>=$AC$4,X12<=$AU$4),IF(""=IFERROR(INDEX(INDIRECT("Data!C"&$K$5,FALSE),MATCH(X12,Data!$A:$A,0)),$BX$12),$BX$11,IFERROR(INDEX(INDIRECT("Data!C"&$K$5,FALSE),MATCH(X12,Data!$A:$A,0)),$BX$12)),"-") -> 86 | AH12: =IF(AND(Y12>=$AC$4,Y12<=$AU$4),IF(""=IFERROR(INDEX(INDIRECT("Data!C"&$K$5,FALSE),MATCH(Y12,Data!$A:$A,0)),$BX$12),$BX$11,IFERROR(INDEX(INDIRECT("Data!C"&$K$5,FALSE),MATCH(Y12,Data!$A:$A,0)),$BX$12)),"-") -> 109 | AI12: =IF(AND(Z12>=$AC$4,Z12<=$AU$4),IF(""=IFERROR(INDEX(INDIRECT("Data!C"&$K$5,FALSE),MATCH(Z12,Data!$A:$A,0)),$BX$12),$BX$11,IFERROR(INDEX(INDIRECT("Data!C"&$K$5,FALSE),MATCH(Z12,Data!$A:$A,0)),$BX$12)),"-") -> 45 | AL12: =IF(MONTH(Z64)=1,T64,Z64+1) -> 41637 | AM12: =AL12+1 -> 41638 | AN12: =AM12+1 -> 41639 | AO12: =AN12+1 -> 41640 | AP12: =AO12+1 -> 41641 | AQ12: =AP12+1 -> 41642 | AR12: =AQ12+1 -> 41643 | AT12: =IF(DAY(AL12)=1,"",AL12) -> 41637 | AU12: =IF(AND(AL12>=$AC$4,AL12<=$AU$4),IF(""=IFERROR(INDEX(INDIRECT("Data!C"&$K$5,FALSE),MATCH(AL12,Data!$A:$A,0)),$BX$12),$BX$11,IFERROR(INDEX(INDIRECT("Data!C"&$K$5,FALSE),MATCH(AL12,Data!$A:$A,0)),$BX$12)),"-") -> 27 | AV12: =IF(AND(AM12>=$AC$4,AM12<=$AU$4),IF(""=IFERROR(INDEX(INDIRECT("Data!C"&$K$5,FALSE),MATCH(AM12,Data!$A:$A,0)),$BX$12),$BX$11,IFERROR(INDEX(INDIRECT("Data!C"&$K$5,FALSE),MATCH(AM12,Data!$A:$A,0)),$BX$12)),"-") -> 249 | AW12: =IF(AND(AN12>=$AC$4,AN12<=$AU$4),IF(""=IFERROR(INDEX(INDIRECT("Data!C"&$K$5,FALSE),MATCH(AN12,Data!$A:$A,0)),$BX$12),$BX$11,IFERROR(INDEX(INDIRECT("Data!C"&$K$5,FALSE),MATCH(AN12,Data!$A:$A,0)),$BX$12)),"-") -> 269 | AX12: =IF(AND(AO12>=$AC$4,AO12<=$AU$4),IF(""=IFERROR(INDEX(INDIRECT("Data!C"&$K$5,FALSE),MATCH(AO12,Data!$A:$A,0)),$BX$12),$BX$11,IFERROR(INDEX(INDIRECT("Data!C"&$K$5,FALSE),MATCH(AO12,Data!$A:$A,0)),$BX$12)),"-") -> 154 | AY12: =IF(AND(AP12>=$AC$4,AP12<=$AU$4),IF(""=IFERROR(INDEX(INDIRECT("Data!C"&$K$5,FALSE),MATCH(AP12,Data!$A:$A,0)),$BX$12),$BX$11,IFERROR(INDEX(INDIRECT("Data!C"&$K$5,FALSE),MATCH(AP12,Data!$A:$A,0)),$BX$12)),"-") -> 123 | AZ12: =IF(AND(AQ12>=$AC$4,AQ12<=$AU$4),IF(""=IFERROR(INDEX(INDIRECT("Data!C"&$K$5,FALSE),MATCH(AQ12,Data!$A:$A,0)),$BX$12),$BX$11,IFERROR(INDEX(INDIRECT("Data!C"&$K$5,FALSE),MATCH(AQ12,Data!$A:$A,0)),$BX$12)),"-") -> 88 | BA12: =IF(AND(AR12>=$AC$4,AR12<=$AU$4),IF(""=IFERROR(INDEX(INDIRECT("Data!C"&$K$5,FALSE),MATCH(AR12,Data!$A:$A,0)),$BX$12),$BX$11,IFERROR(INDEX(INDIRECT("Data!C"&$K$5,FALSE),MATCH(AR12,Data!$A:$A,0)),$BX$12)),"-") -> 20 | BD12: =IF(MONTH(AR64)=1,AL64,AR64+1) -> 42001 | BE12: =BD12+1 -> 42002 | BF12: =BE12+1 -> 42003 | BG12: =BF12+1 -> 42004 | BH12: =BG12+1 -> 42005 | BI12: =BH12+1 -> 42006 | BJ12: =BI12+1 -> 42007 | BL12: =IF(DAY(BD12)=1,"",BD12) -> 42001 | BM12: =IF(AND(BD12>=$AC$4,BD12<=$AU$4),IF(""=IFERROR(INDEX(INDIRECT("Data!C"&$K$5,FALSE),MATCH(BD12,Data!$A:$A,0)),$BX$12),$BX$11,IFERROR(INDEX(INDIRECT("Data!C"&$K$5,FALSE),MATCH(BD12,Data!$A:$A,0)),$BX$12)),"-") -> 28 | BN12: =IF(AND(BE12>=$AC$4,BE12<=$AU$4),IF(""=IFERROR(INDEX(INDIRECT("Data!C"&$K$5,FALSE),MATCH(BE12,Data!$A:$A,0)),$BX$12),$BX$11,IFERROR(INDEX(INDIRECT("Data!C"&$K$5,FALSE),MATCH(BE12,Data!$A:$A,0)),$BX$12)),"-") -> 122 | BO12: =IF(AND(BF12>=$AC$4,BF12<=$AU$4),IF(""=IFERROR(INDEX(INDIRECT("Data!C"&$K$5,FALSE),MATCH(BF12,Data!$A:$A,0)),$BX$12),$BX$11,IFERROR(INDEX(INDIRECT("Data!C"&$K$5,FALSE),MATCH(BF12,Data!$A:$A,0)),$BX$12)),"-") -> 160 | BP12: =IF(AND(BG12>=$AC$4,BG12<=$AU$4),IF(""=IFERROR(INDEX(INDIRECT("Data!C"&$K$5,FALSE),MATCH(BG12,Data!$A:$A,0)),$BX$12),$BX$11,IFERROR(INDEX(INDIRECT("Data!C"&$K$5,FALSE),MATCH(BG12,Data!$A:$A,0)),$BX$12)),"-") -> 122 | BQ12: =IF(AND(BH12>=$AC$4,BH12<=$AU$4),IF(""=IFERROR(INDEX(INDIRECT("Data!C"&$K$5,FALSE),MATCH(BH12,Data!$A:$A,0)),$BX$12),$BX$11,IFERROR(INDEX(INDIRECT("Data!C"&$K$5,FALSE),MATCH(BH12,Data!$A:$A,0)),$BX$12)),"-") -> 187 | BR12: =IF(AND(BI12>=$AC$4,BI12<=$AU$4),IF(""=IFERROR(INDEX(INDIRECT("Data!C"&$K$5,FALSE),MATCH(BI12,Data!$A:$A,0)),$BX$12),$BX$11,IFERROR(INDEX(INDIRECT("Data!C"&$K$5,FALSE),MATCH(BI12,Data!$A:$A,0)),$BX$12)),"-") -> 147 | BS12: =IF(AND(BJ12>=$AC$4,BJ12<=$AU$4),IF(""=IFERROR(INDEX(INDIRECT("Data!C"&$K$5,FALSE),MATCH(BJ12,Data!$A:$A,0)),$BX$12),$BX$11,IFERROR(INDEX(INDIRECT("Data!C"&$K$5,FALSE),MATCH(BJ12,Data!$A:$A,0)),$BX$12)),"-") -> 60 | BU12: =AVERAGE(K12:Q12,AC12:AI12,AU12:BA12,BM12:BS12) -> 123.96429 | BW12: Missing Date or Error: | BX12: -
B13: =B12+7 -> 40916 | C13: =B13+1 -> 40917 | D13: =C13+1 -> 40918 | E13: =D13+1 -> 40919 | F13: =E13+1 -> 40920 | G13: =F13+1 -> 40921 | H13: =G13+1 -> 40922 | J13: {=IFERROR(IF(MATCH(8,DAY(B13:H13),0),H13,""),"")} -> 40922 | K13: =IF(AND(B13>=$AC$4,B13<=$AU$4),IF(""=IFERROR(INDEX(INDIRECT("Data!C"&$K$5,FALSE),MATCH(B13,Data!$A:$A,0)),$BX$12),$BX$11,IFERROR(INDEX(INDIRECT("Data!C"&$K$5,FALSE),MATCH(B13,Data!$A:$A,0)),$BX$12)),"-") -> 29 | L13: =IF(AND(C13>=$AC$4,C13<=$AU$4),IF(""=IFERROR(INDEX(INDIRECT("Data!C"&$K$5,FALSE),MATCH(C13,Data!$A:$A,0)),$BX$12),$BX$11,IFERROR(INDEX(INDIRECT("Data!C"&$K$5,FALSE),MATCH(C13,Data!$A:$A,0)),$BX$12)),"-") -> 225 | M13: =IF(AND(D13>=$AC$4,D13<=$AU$4),IF(""=IFERROR(INDEX(INDIRECT("Data!C"&$K$5,FALSE),MATCH(D13,Data!$A:$A,0)),$BX$12),$BX$11,IFERROR(INDEX(INDIRECT("Data!C"&$K$5,FALSE),MATCH(D13,Data!$A:$A,0)),$BX$12)),"-") -> 220 | N13: =IF(AND(E13>=$AC$4,E13<=$AU$4),IF(""=IFERROR(INDEX(INDIRECT("Data!C"&$K$5,FALSE),MATCH(E13,Data!$A:$A,0)),$BX$12),$BX$11,IFERROR(INDEX(INDIRECT("Data!C"&$K$5,FALSE),MATCH(E13,Data!$A:$A,0)),$BX$12)),"-") -> 199 | O13: =IF(AND(F13>=$AC$4,F13<=$AU$4),IF(""=IFERROR(INDEX(INDIRECT("Data!C"&$K$5,FALSE),MATCH(F13,Data!$A:$A,0)),$BX$12),$BX$11,IFERROR(INDEX(INDIRECT("Data!C"&$K$5,FALSE),MATCH(F13,Data!$A:$A,0)),$BX$12)),"-") -> 102 | P13: =IF(AND(G13>=$AC$4,G13<=$AU$4),IF(""=IFERROR(INDEX(INDIRECT("Data!C"&$K$5,FALSE),MATCH(G13,Data!$A:$A,0)),$BX$12),$BX$11,IFERROR(INDEX(INDIRECT("Data!C"&$K$5,FALSE),MATCH(G13,Data!$A:$A,0)),$BX$12)),"-") -> 164 | Q13: =IF(AND(H13>=$AC$4,H13<=$AU$4),IF(""=IFERROR(INDEX(INDIRECT("Data!C"&$K$5,FALSE),MATCH(H13,Data!$A:$A,0)),$BX$12),$BX$11,IFERROR(INDEX(INDIRECT("Data!C"&$K$5,FALSE),MATCH(H13,Data!$A:$A,0)),$BX$12)),"-") -> 34 | T13: =T12+7 -> 41280 | U13: =T13+1 -> 41281 | V13: =U13+1 -> 41282 | W13: =V13+1 -> 41283 | X13: =W13+1 -> 41284 | Y13: =X13+1 -> 41285 | Z13: =Y13+1 -> 41286 | AB13: {=IFERROR(IF(MATCH(8,DAY(T13:Z13),0),Z13,""),"")} -> 41286 | AC13: =IF(AND(T13>=$AC$4,T13<=$AU$4),IF(""=IFERROR(INDEX(INDIRECT("Data!C"&$K$5,FALSE),MATCH(T13,Data!$A:$A,0)),$BX$12),$BX$11,IFERROR(INDEX(INDIRECT("Data!C"&$K$5,FALSE),MATCH(T13,Data!$A:$A,0)),$BX$12)),"-") -> 11 | AD13: =IF(AND(U13>=$AC$4,U13<=$AU$4),IF(""=IFERROR(INDEX(INDIRECT("Data!C"&$K$5,FALSE),MATCH(U13,Data!$A:$A,0)),$BX$12),$BX$11,IFERROR(INDEX(INDIRECT("Data!C"&$K$5,FALSE),MATCH(U13,Data!$A:$A,0)),$BX$12)),"-") -> 143 | AE13: =IF(AND(V13>=$AC$4,V13<=$AU$4),IF(""=IFERROR(INDEX(INDIRECT("Data!C"&$K$5,FALSE),MATCH(V13,Data!$A:$A,0)),$BX$12),$BX$11,IFERROR(INDEX(INDIRECT("Data!C"&$K$5,FALSE),MATCH(V13,Data!$A:$A,0)),$BX$12)),"-") -> 182 | AF13: =IF(AND(W13>=$AC$4,W13<=$AU$4),IF(""=IFERROR(INDEX(INDIRECT("Data!C"&$K$5,FALSE),MATCH(W13,Data!$A:$A,0)),$BX$12),$BX$11,IFERROR(INDEX(INDIRECT("Data!C"&$K$5,FALSE),MATCH(W13,Data!$A:$A,0)),$BX$12)),"-") -> 202 | AG13: =IF(AND(X13>=$AC$4,X13<=$AU$4),IF(""=IFERROR(INDEX(INDIRECT("Data!C"&$K$5,FALSE),MATCH(X13,Data!$A:$A,0)),$BX$12),$BX$11,IFERROR(INDEX(INDIRECT("Data!C"&$K$5,FALSE),MATCH(X13,Data!$A:$A,0)),$BX$12)),"-") -> 78 | AH13: =IF(AND(Y13>=$AC$4,Y13<=$AU$4),IF(""=IFERROR(INDEX(INDIRECT("Data!C"&$K$5,FALSE),MATCH(Y13,Data!$A:$A,0)),$BX$12),$BX$11,IFERROR(INDEX(INDIRECT("Data!C"&$K$5,FALSE),MATCH(Y13,Data!$A:$A,0)),$BX$12)),"-") -> 157 | AI13: =IF(AND(Z13>=$AC$4,Z13<=$AU$4),IF(""=IFERROR(INDEX(INDIRECT("Data!C"&$K$5,FALSE),MATCH(Z13,Data!$A:$A,0)),$BX$12),$BX$11,IFERROR(INDEX(INDIRECT("Data!C"&$K$5,FALSE),MATCH(Z13,Data!$A:$A,0)),$BX$12)),"-") -> 52 | AL13: =AL12+7 -> 41644 | AM13: =AL13+1 -> 41645 | AN13: =AM13+1 -> 41646 | AO13: =AN13+1 -> 41647 | AP13: =AO13+1 -> 41648 | AQ13: =AP13+1 -> 41649 | AR13: =AQ13+1 -> 41650 | AT13: {=IFERROR(IF(MATCH(8,DAY(AL13:AR13),0),AR13,""),"")} -> 41650 | AU13: =IF(AND(AL13>=$AC$4,AL13<=$AU$4),IF(""=IFERROR(INDEX(INDIRECT("Data!C"&$K$5,FALSE),MATCH(AL13,Data!$A:$A,0)),$BX$12),$BX$11,IFERROR(INDEX(INDIRECT("Data!C"&$K$5,FALSE),MATCH(AL13,Data!$A:$A,0)),$BX$12)),"-") -> 23 | AV13: =IF(AND(AM13>=$AC$4,AM13<=$AU$4),IF(""=IFERROR(INDEX(INDIRECT("Data!C"&$K$5,FALSE),MATCH(AM13,Data!$A:$A,0)),$BX$12),$BX$11,IFERROR(INDEX(INDIRECT("Data!C"&$K$5,FALSE),MATCH(AM13,Data!$A:$A,0)),$BX$12)),"-") -> 113 | AW13: =IF(AND(AN13>=$AC$4,AN13<=$AU$4),IF(""=IFERROR(INDEX(INDIRECT("Data!C"&$K$5,FALSE),MATCH(AN13,Data!$A:$A,0)),$BX$12),$BX$11,IFERROR(INDEX(INDIRECT("Data!C"&$K$5,FALSE),MATCH(AN13,Data!$A:$A,0)),$BX$12)),"-") -> 157 | AX13: =IF(AND(AO13>=$AC$4,AO13<=$AU$4),IF(""=IFERROR(INDEX(INDIRECT("Data!C"&$K$5,FALSE),MATCH(AO13,Data!$A:$A,0)),$BX$12),$BX$11,IFERROR(INDEX(INDIRECT("Data!C"&$K$5,FALSE),MATCH(AO13,Data!$A:$A,0)),$BX$12)),"-") -> 116 | AY13: =IF(AND(AP13>=$AC$4,AP13<=$AU$4),IF(""=IFERROR(INDEX(INDIRECT("Data!C"&$K$5,FALSE),MATCH(AP13,Data!$A:$A,0)),$BX$12),$BX$11,IFERROR(INDEX(INDIRECT("Data!C"&$K$5,FALSE),MATCH(AP13,Data!$A:$A,0)),$BX$12)),"-") -> 181 | AZ13: =IF(AND(AQ13>=$AC$4,AQ13<=$AU$4),IF(""=IFERROR(INDEX(INDIRECT("Data!C"&$K$5,FALSE),MATCH(AQ13,Data!$A:$A,0)),$BX$12),$BX$11,IFERROR(INDEX(INDIRECT("Data!C"&$K$5,FALSE),MATCH(AQ13,Data!$A:$A,0)),$BX$12)),"-") -> 146 | BA13: =IF(AND(AR13>=$AC$4,AR13<=$AU$4),IF(""=IFERROR(INDEX(INDIRECT("Data!C"&$K$5,FALSE),MATCH(AR13,Data!$A:$A,0)),$BX$12),$BX$11,IFERROR(INDEX(INDIRECT("Data!C"&$K$5,FALSE),MATCH(AR13,Data!$A:$A,0)),$BX$12)),"-") -> 41 | BD13: =BD12+7 -> 42008 | BE13: =BD13+1 -> 42009 | BF13: =BE13+1 -> 42010 | BG13: =BF13+1 -> 42011 | BH13: =BG13+1 -> 42012 | BI13: =BH13+1 -> 42013 | BJ13: =BI13+1 -> 42014 | BL13: {=IFERROR(IF(MATCH(8,DAY(BD13:BJ13),0),BJ13,""),"")} -> 42014 | BM13: =IF(AND(BD13>=$AC$4,BD13<=$AU$4),IF(""=IFERROR(INDEX(INDIRECT("Data!C"&$K$5,FALSE),MATCH(BD13,Data!$A:$A,0)),$BX$12),$BX$11,IFERROR(INDEX(INDIRECT("Data!C"&$K$5,FALSE),MATCH(BD13,Data!$A:$A,0)),$BX$12)),"-") -> 15 | BN13: =IF(AND(BE13>=$AC$4,BE13<=$AU$4),IF(""=IFERROR(INDEX(INDIRECT("Data!C"&$K$5,FALSE),MATCH(BE13,Data!$A:$A,0)),$BX$12),$BX$11,IFERROR(INDEX(INDIRECT("Data!C"&$K$5,FALSE),MATCH(BE13,Data!$A:$A,0)),$BX$12)),"-") -> 124 | BO13: =IF(AND(BF13>=$AC$4,BF13<=$AU$4),IF(""=IFERROR(INDEX(INDIRECT("Data!C"&$K$5,FALSE),MATCH(BF13,Data!$A:$A,0)),$BX$12),$BX$11,IFERROR(INDEX(INDIRECT("Data!C"&$K$5,FALSE),MATCH(BF13,Data!$A:$A,0)),$BX$12)),"-") -> 147 | BP13: =IF(AND(BG13>=$AC$4,BG13<=$AU$4),IF(""=IFERROR(INDEX(INDIRECT("Data!C"&$K$5,FALSE),MATCH(BG13,Data!$A:$A,0)),$BX$12),$BX$11,IFERROR(INDEX(INDIRECT("Data!C"&$K$5,FALSE),MATCH(BG13,Data!$A:$A,0)),$BX$12)),"-") -> 251 | BQ13: =IF(AND(BH13>=$AC$4,BH13<=$AU$4),IF(""=IFERROR(INDEX(INDIRECT("Data!C"&$K$5,FALSE),MATCH(BH13,Data!$A:$A,0)),$BX$12),$BX$11,IFERROR(INDEX(INDIRECT("Data!C"&$K$5,FALSE),MATCH(BH13,Data!$A:$A,0)),$BX$12)),"-") -> 118 | BR13: =IF(AND(BI13>=$AC$4,BI13<=$AU$4),IF(""=IFERROR(INDEX(INDIRECT("Data!C"&$K$5,FALSE),MATCH(BI13,Data!$A:$A,0)),$BX$12),$BX$11,IFERROR(INDEX(INDIRECT("Data!C"&$K$5,FALSE),MATCH(BI13,Data!$A:$A,0)),$BX$12)),"-") -> 188 | BS13: =IF(AND(BJ13>=$AC$4,BJ13<=$AU$4),IF(""=IFERROR(INDEX(INDIRECT("Data!C"&$K$5,FALSE),MATCH(BJ13,Data!$A:$A,0)),$BX$12),$BX$11,IFERROR(INDEX(INDIRECT("Data!C"&$K$5,FALSE),MATCH(BJ13,Data!$A:$A,0)),$BX$12)),"-") -> 55 | BU13: =AVERAGE(K13:Q13,AC13:AI13,AU13:BA13,BM13:BS13) -> 124.03571
B14: =B13+7 -> 40923 | C14: =B14+1 -> 40924 | D14: =C14+1 -> 40925 | E14: =D14+1 -> 40926 | F14: =E14+1 -> 40927 | G14: =F14+1 -> 40928 | H14: =G14+1 -> 40929 | J14: {=IFERROR(IF(MATCH(8,DAY(B14:H14),0),H14,""),"")} | K14: =IF(AND(B14>=$AC$4,B14<=$AU$4),IF(""=IFERROR(INDEX(INDIRECT("Data!C"&$K$5,FALSE),MATCH(B14,Data!$A:$A,0)),$BX$12),$BX$11,IFERROR(INDEX(INDIRECT("Data!C"&$K$5,FALSE),MATCH(B14,Data!$A:$A,0)),$BX$12)),"-") -> 14 | L14: =IF(AND(C14>=$AC$4,C14<=$AU$4),IF(""=IFERROR(INDEX(INDIRECT("Data!C"&$K$5,FALSE),MATCH(C14,Data!$A:$A,0)),$BX$12),$BX$11,IFERROR(INDEX(INDIRECT("Data!C"&$K$5,FALSE),MATCH(C14,Data!$A:$A,0)),$BX$12)),"-") -> 128 | M14: =IF(AND(D14>=$AC$4,D14<=$AU$4),IF(""=IFERROR(INDEX(INDIRECT("Data!C"&$K$5,FALSE),MATCH(D14,Data!$A:$A,0)),$BX$12),$BX$11,IFERROR(INDEX(INDIRECT("Data!C"&$K$5,FALSE),MATCH(D14,Data!$A:$A,0)),$BX$12)),"-") -> 104 | N14: =IF(AND(E14>=$AC$4,E14<=$AU$4),IF(""=IFERROR(INDEX(INDIRECT("Data!C"&$K$5,FALSE),MATCH(E14,Data!$A:$A,0)),$BX$12),$BX$11,IFERROR(INDEX(INDIRECT("Data!C"&$K$5,FALSE),MATCH(E14,Data!$A:$A,0)),$BX$12)),"-") -> 111 | O14: =IF(AND(F14>=$AC$4,F14<=$AU$4),IF(""=IFERROR(INDEX(INDIRECT("Data!C"&$K$5,FALSE),MATCH(F14,Data!$A:$A,0)),$BX$12),$BX$11,IFERROR(INDEX(INDIRECT("Data!C"&$K$5,FALSE),MATCH(F14,Data!$A:$A,0)),$BX$12)),"-") -> 114 | P14: =IF(AND(G14>=$AC$4,G14<=$AU$4),IF(""=IFERROR(INDEX(INDIRECT("Data!C"&$K$5,FALSE),MATCH(G14,Data!$A:$A,0)),$BX$12),$BX$11,IFERROR(INDEX(INDIRECT("Data!C"&$K$5,FALSE),MATCH(G14,Data!$A:$A,0)),$BX$12)),"-") -> 174 | Q14: =IF(AND(H14>=$AC$4,H14<=$AU$4),IF(""=IFERROR(INDEX(INDIRECT("Data!C"&$K$5,FALSE),MATCH(H14,Data!$A:$A,0)),$BX$12),$BX$11,IFERROR(INDEX(INDIRECT("Data!C"&$K$5,FALSE),MATCH(H14,Data!$A:$A,0)),$BX$12)),"-") -> 54 | T14: =T13+7 -> 41287 | U14: =T14+1 -> 41288 | V14: =U14+1 -> 41289 | W14: =V14+1 -> 41290 | X14: =W14+1 -> 41291 | Y14: =X14+1 -> 41292 | Z14: =Y14+1 -> 41293 | AB14: {=IFERROR(IF(MATCH(8,DAY(T14:Z14),0),Z14,""),"")} | AC14: =IF(AND(T14>=$AC$4,T14<=$AU$4),IF(""=IFERROR(INDEX(INDIRECT("Data!C"&$K$5,FALSE),MATCH(T14,Data!$A:$A,0)),$BX$12),$BX$11,IFERROR(INDEX(INDIRECT("Data!C"&$K$5,FALSE),MATCH(T14,Data!$A:$A,0)),$BX$12)),"-") -> 12 | AD14: =IF(AND(U14>=$AC$4,U14<=$AU$4),IF(""=IFERROR(INDEX(INDIRECT("Data!C"&$K$5,FALSE),MATCH(U14,Data!$A:$A,0)),$BX$12),$BX$11,IFERROR(INDEX(INDIRECT("Data!C"&$K$5,FALSE),MATCH(U14,Data!$A:$A,0)),$BX$12)),"-") -> 158 | AE14: =IF(AND(V14>=$AC$4,V14<=$AU$4),IF(""=IFERROR(INDEX(INDIRECT("Data!C"&$K$5,FALSE),MATCH(V14,Data!$A:$A,0)),$BX$12),$BX$11,IFERROR(INDEX(INDIRECT("Data!C"&$K$5,FALSE),MATCH(V14,Data!$A:$A,0)),$BX$12)),"-") -> 124 | AF14: =IF(AND(W14>=$AC$4,W14<=$AU$4),IF(""=IFERROR(INDEX(INDIRECT("Data!C"&$K$5,FALSE),MATCH(W14,Data!$A:$A,0)),$BX$12),$BX$11,IFERROR(INDEX(INDIRECT("Data!C"&$K$5,FALSE),MATCH(W14,Data!$A:$A,0)),$BX$12)),"-") -> 181 | AG14: =IF(AND(X14>=$AC$4,X14<=$AU$4),IF(""=IFERROR(INDEX(INDIRECT("Data!C"&$K$5,FALSE),MATCH(X14,Data!$A:$A,0)),$BX$12),$BX$11,IFERROR(INDEX(INDIRECT("Data!C"&$K$5,FALSE),MATCH(X14,Data!$A:$A,0)),$BX$12)),"-") -> 99 | AH14: =IF(AND(Y14>=$AC$4,Y14<=$AU$4),IF(""=IFERROR(INDEX(INDIRECT("Data!C"&$K$5,FALSE),MATCH(Y14,Data!$A:$A,0)),$BX$12),$BX$11,IFERROR(INDEX(INDIRECT("Data!C"&$K$5,FALSE),MATCH(Y14,Data!$A:$A,0)),$BX$12)),"-") -> 191 | AI14: =IF(AND(Z14>=$AC$4,Z14<=$AU$4),IF(""=IFERROR(INDEX(INDIRECT("Data!C"&$K$5,FALSE),MATCH(Z14,Data!$A:$A,0)),$BX$12),$BX$11,IFERROR(INDEX(INDIRECT("Data!C"&$K$5,FALSE),MATCH(Z14,Data!$A:$A,0)),$BX$12)),"-") -> 54 | AL14: =AL13+7 -> 41651 | AM14: =AL14+1 -> 41652 | AN14: =AM14+1 -> 41653 | AO14: =AN14+1 -> 41654 | AP14: =AO14+1 -> 41655 | AQ14: =AP14+1 -> 41656 | AR14: =AQ14+1 -> 41657 | AT14: {=IFERROR(IF(MATCH(8,DAY(AL14:AR14),0),AR14,""),"")} | AU14: =IF(AND(AL14>=$AC$4,AL14<=$AU$4),IF(""=IFERROR(INDEX(INDIRECT("Data!C"&$K$5,FALSE),MATCH(AL14,Data!$A:$A,0)),$BX$12),$BX$11,IFERROR(INDEX(INDIRECT("Data!C"&$K$5,FALSE),MATCH(AL14,Data!$A:$A,0)),$BX$12)),"-") -> 22 | AV14: =IF(AND(AM14>=$AC$4,AM14<=$AU$4),IF(""=IFERROR(INDEX(INDIRECT("Data!C"&$K$5,FALSE),MATCH(AM14,Data!$A:$A,0)),$BX$12),$BX$11,IFERROR(INDEX(INDIRECT("Data!C"&$K$5,FALSE),MATCH(AM14,Data!$A:$A,0)),$BX$12)),"-") -> 128 | AW14: =IF(AND(AN14>=$AC$4,AN14<=$AU$4),IF(""=IFERROR(INDEX(INDIRECT("Data!C"&$K$5,FALSE),MATCH(AN14,Data!$A:$A,0)),$BX$12),$BX$11,IFERROR(INDEX(INDIRECT("Data!C"&$K$5,FALSE),MATCH(AN14,Data!$A:$A,0)),$BX$12)),"-") -> 211 | AX14: =IF(AND(AO14>=$AC$4,AO14<=$AU$4),IF(""=IFERROR(INDEX(INDIRECT("Data!C"&$K$5,FALSE),MATCH(AO14,Data!$A:$A,0)),$BX$12),$BX$11,IFERROR(INDEX(INDIRECT("Data!C"&$K$5,FALSE),MATCH(AO14,Data!$A:$A,0)),$BX$12)),"-") -> 262 | AY14: =IF(AND(AP14>=$AC$4,AP14<=$AU$4),IF(""=IFERROR(INDEX(INDIRECT("Data!C"&$K$5,FALSE),MATCH(AP14,Data!$A:$A,0)),$BX$12),$BX$11,IFERROR(INDEX(INDIRECT("Data!C"&$K$5,FALSE),MATCH(AP14,Data!$A:$A,0)),$BX$12)),"-") -> 205 | AZ14: =IF(AND(AQ14>=$AC$4,AQ14<=$AU$4),IF(""=IFERROR(INDEX(INDIRECT("Data!C"&$K$5,FALSE),MATCH(AQ14,Data!$A:$A,0)),$BX$12),$BX$11,IFERROR(INDEX(INDIRECT("Data!C"&$K$5,FALSE),MATCH(AQ14,Data!$A:$A,0)),$BX$12)),"-") -> 147 | BA14: =IF(AND(AR14>=$AC$4,AR14<=$AU$4),IF(""=IFERROR(INDEX(INDIRECT("Data!C"&$K$5,FALSE),MATCH(AR14,Data!$A:$A,0)),$BX$12),$BX$11,IFERROR(INDEX(INDIRECT("Data!C"&$K$5,FALSE),MATCH(AR14,Data!$A:$A,0)),$BX$12)),"-") -> 45 | BD14: =BD13+7 -> 42015 | BE14: =BD14+1 -> 42016 | BF14: =BE14+1 -> 42017 | BG14: =BF14+1 -> 42018 | BH14: =BG14+1 -> 42019 | BI14: =BH14+1 -> 42020 | BJ14: =BI14+1 -> 42021 | BL14: {=IFERROR(IF(MATCH(8,DAY(BD14:BJ14),0),BJ14,""),"")} | BM14: =IF(AND(BD14>=$AC$4,BD14<=$AU$4),IF(""=IFERROR(INDEX(INDIRECT("Data!C"&$K$5,FALSE),MATCH(BD14,Data!$A:$A,0)),$BX$12),$BX$11,IFERROR(INDEX(INDIRECT("Data!C"&$K$5,FALSE),MATCH(BD14,Data!$A:$A,0)),$BX$12)),"-") -> 22 | BN14: =IF(AND(BE14>=$AC$4,BE14<=$AU$4),IF(""=IFERROR(INDEX(INDIRECT("Data!C"&$K$5,FALSE),MATCH(BE14,Data!$A:$A,0)),$BX$12),$BX$11,IFERROR(INDEX(INDIRECT("Data!C"&$K$5,FALSE),MATCH(BE14,Data!$A:$A,0)),$BX$12)),"-") -> 195 | BO14: =IF(AND(BF14>=$AC$4,BF14<=$AU$4),IF(""=IFERROR(INDEX(INDIRECT("Data!C"&$K$5,FALSE),MATCH(BF14,Data!$A:$A,0)),$BX$12),$BX$11,IFERROR(INDEX(INDIRECT("Data!C"&$K$5,FALSE),MATCH(BF14,Data!$A:$A,0)),$BX$12)),"-") -> 280 | BP14: =IF(AND(BG14>=$AC$4,BG14<=$AU$4),IF(""=IFERROR(INDEX(INDIRECT("Data!C"&$K$5,FALSE),MATCH(BG14,Data!$A:$A,0)),$BX$12),$BX$11,IFERROR(INDEX(INDIRECT("Data!C"&$K$5,FALSE),MATCH(BG14,Data!$A:$A,0)),$BX$12)),"-") -> 275 | BQ14: =IF(AND(BH14>=$AC$4,BH14<=$AU$4),IF(""=IFERROR(INDEX(INDIRECT("Data!C"&$K$5,FALSE),MATCH(BH14,Data!$A:$A,0)),$BX$12),$BX$11,IFERROR(INDEX(INDIRECT("Data!C"&$K$5,FALSE),MATCH(BH14,Data!$A:$A,0)),$BX$12)),"-") -> 233 | BR14: =IF(AND(BI14>=$AC$4,BI14<=$AU$4),IF(""=IFERROR(INDEX(INDIRECT("Data!C"&$K$5,FALSE),MATCH(BI14,Data!$A:$A,0)),$BX$12),$BX$11,IFERROR(INDEX(INDIRECT("Data!C"&$K$5,FALSE),MATCH(BI14,Data!$A:$A,0)),$BX$12)),"-") -> 116 | BS14: =IF(AND(BJ14>=$AC$4,BJ14<=$AU$4),IF(""=IFERROR(INDEX(INDIRECT("Data!C"&$K$5,FALSE),MATCH(BJ14,Data!$A:$A,0)),$BX$12),$BX$11,IFERROR(INDEX(INDIRECT("Data!C"&$K$5,FALSE),MATCH(BJ14,Data!$A:$A,0)),$BX$12)),"-") -> 67 | BU14: =AVERAGE(K14:Q14,AC14:AI14,AU14:BA14,BM14:BS14) -> 133.07143 | BW14: Highlight Holidays? | BX14: yes
B15: =B14+7 -> 40930 | C15: =B15+1 -> 40931 | D15: =C15+1 -> 40932 | E15: =D15+1 -> 40933 | F15: =E15+1 -> 40934 | G15: =F15+1 -> 40935 | H15: =G15+1 -> 40936 | J15: {=IFERROR(IF(MATCH(8,DAY(B15:H15),0),H15,""),"")} | K15: =IF(AND(B15>=$AC$4,B15<=$AU$4),IF(""=IFERROR(INDEX(INDIRECT("Data!C"&$K$5,FALSE),MATCH(B15,Data!$A:$A,0)),$BX$12),$BX$11,IFERROR(INDEX(INDIRECT("Data!C"&$K$5,FALSE),MATCH(B15,Data!$A:$A,0)),$BX$12)),"-") -> 30 | L15: =IF(AND(C15>=$AC$4,C15<=$AU$4),IF(""=IFERROR(INDEX(INDIRECT("Data!C"&$K$5,FALSE),MATCH(C15,Data!$A:$A,0)),$BX$12),$BX$11,IFERROR(INDEX(INDIRECT("Data!C"&$K$5,FALSE),MATCH(C15,Data!$A:$A,0)),$BX$12)),"-") -> 264 | M15: =IF(AND(D15>=$AC$4,D15<=$AU$4),IF(""=IFERROR(INDEX(INDIRECT("Data!C"&$K$5,FALSE),MATCH(D15,Data!$A:$A,0)),$BX$12),$BX$11,IFERROR(INDEX(INDIRECT("Data!C"&$K$5,FALSE),MATCH(D15,Data!$A:$A,0)),$BX$12)),"-") -> 131 | N15: =IF(AND(E15>=$AC$4,E15<=$AU$4),IF(""=IFERROR(INDEX(INDIRECT("Data!C"&$K$5,FALSE),MATCH(E15,Data!$A:$A,0)),$BX$12),$BX$11,IFERROR(INDEX(INDIRECT("Data!C"&$K$5,FALSE),MATCH(E15,Data!$A:$A,0)),$BX$12)),"-") -> 163 | O15: =IF(AND(F15>=$AC$4,F15<=$AU$4),IF(""=IFERROR(INDEX(INDIRECT("Data!C"&$K$5,FALSE),MATCH(F15,Data!$A:$A,0)),$BX$12),$BX$11,IFERROR(INDEX(INDIRECT("Data!C"&$K$5,FALSE),MATCH(F15,Data!$A:$A,0)),$BX$12)),"-") -> 101 | P15: =IF(AND(G15>=$AC$4,G15<=$AU$4),IF(""=IFERROR(INDEX(INDIRECT("Data!C"&$K$5,FALSE),MATCH(G15,Data!$A:$A,0)),$BX$12),$BX$11,IFERROR(INDEX(INDIRECT("Data!C"&$K$5,FALSE),MATCH(G15,Data!$A:$A,0)),$BX$12)),"-") -> 130 | Q15: =IF(AND(H15>=$AC$4,H15<=$AU$4),IF(""=IFERROR(INDEX(INDIRECT("Data!C"&$K$5,FALSE),MATCH(H15,Data!$A:$A,0)),$BX$12),$BX$11,IFERROR(INDEX(INDIRECT("Data!C"&$K$5,FALSE),MATCH(H15,Data!$A:$A,0)),$BX$12)),"-") -> 43 | T15: =T14+7 -> 41294 | U15: =T15+1 -> 41295 | V15: =U15+1 -> 41296 | W15: =V15+1 -> 41297 | X15: =W15+1 -> 41298 | Y15: =X15+1 -> 41299 | Z15: =Y15+1 -> 41300 | AB15: {=IFERROR(IF(MATCH(8,DAY(T15:Z15),0),Z15,""),"")} | AC15: =IF(AND(T15>=$AC$4,T15<=$AU$4),IF(""=IFERROR(INDEX(INDIRECT("Data!C"&$K$5,FALSE),MATCH(T15,Data!$A:$A,0)),$BX$12),$BX$11,IFERROR(INDEX(INDIRECT("Data!C"&$K$5,FALSE),MATCH(T15,Data!$A:$A,0)),$BX$12)),"-") -> 22 | AD15: =IF(AND(U15>=$AC$4,U15<=$AU$4),IF(""=IFERROR(INDEX(INDIRECT("Data!C"&$K$5,FALSE),MATCH(U15,Data!$A:$A,0)),$BX$12),$BX$11,IFERROR(INDEX(INDIRECT("Data!C"&$K$5,FALSE),MATCH(U15,Data!$A:$A,0)),$BX$12)),"-") -> 208 | AE15: =IF(AND(V15>=$AC$4,V15<=$AU$4),IF(""=IFERROR(INDEX(INDIRECT("Data!C"&$K$5,FALSE),MATCH(V15,Data!$A:$A,0)),$BX$12),$BX$11,IFERROR(INDEX(INDIRECT("Data!C"&$K$5,FALSE),MATCH(V15,Data!$A:$A,0)),$BX$12)),"-") -> 132 | AF15: =IF(AND(W15>=$AC$4,W15<=$AU$4),IF(""=IFERROR(INDEX(INDIRECT("Data!C"&$K$5,FALSE),MATCH(W15,Data!$A:$A,0)),$BX$12),$BX$11,IFERROR(INDEX(INDIRECT("Data!C"&$K$5,FALSE),MATCH(W15,Data!$A:$A,0)),$BX$12)),"-") -> 279 | AG15: =IF(AND(X15>=$AC$4,X15<=$AU$4),IF(""=IFERROR(INDEX(INDIRECT("Data!C"&$K$5,FALSE),MATCH(X15,Data!$A:$A,0)),$BX$12),$BX$11,IFERROR(INDEX(INDIRECT("Data!C"&$K$5,FALSE),MATCH(X15,Data!$A:$A,0)),$BX$12)),"-") -> 143 | AH15: =IF(AND(Y15>=$AC$4,Y15<=$AU$4),IF(""=IFERROR(INDEX(INDIRECT("Data!C"&$K$5,FALSE),MATCH(Y15,Data!$A:$A,0)),$BX$12),$BX$11,IFERROR(INDEX(INDIRECT("Data!C"&$K$5,FALSE),MATCH(Y15,Data!$A:$A,0)),$BX$12)),"-") -> 115 | AI15: =IF(AND(Z15>=$AC$4,Z15<=$AU$4),IF(""=IFERROR(INDEX(INDIRECT("Data!C"&$K$5,FALSE),MATCH(Z15,Data!$A:$A,0)),$BX$12),$BX$11,IFERROR(INDEX(INDIRECT("Data!C"&$K$5,FALSE),MATCH(Z15,Data!$A:$A,0)),$BX$12)),"-") -> 72 | AL15: =AL14+7 -> 41658 | AM15: =AL15+1 -> 41659 | AN15: =AM15+1 -> 41660 | AO15: =AN15+1 -> 41661 | AP15: =AO15+1 -> 41662 | AQ15: =AP15+1 -> 41663 | AR15: =AQ15+1 -> 41664 | AT15: {=IFERROR(IF(MATCH(8,DAY(AL15:AR15),0),AR15,""),"")} | AU15: =IF(AND(AL15>=$AC$4,AL15<=$AU$4),IF(""=IFERROR(INDEX(INDIRECT("Data!C"&$K$5,FALSE),MATCH(AL15,Data!$A:$A,0)),$BX$12),$BX$11,IFERROR(INDEX(INDIRECT("Data!C"&$K$5,FALSE),MATCH(AL15,Data!$A:$A,0)),$BX$12)),"-") -> 17 | AV15: =IF(AND(AM15>=$AC$4,AM15<=$AU$4),IF(""=IFERROR(INDEX(INDIRECT("Data!C"&$K$5,FALSE),MATCH(AM15,Data!$A:$A,0)),$BX$12),$BX$11,IFERROR(INDEX(INDIRECT("Data!C"&$K$5,FALSE),MATCH(AM15,Data!$A:$A,0)),$BX$12)),"-") -> 329 | AW15: =IF(AND(AN15>=$AC$4,AN15<=$AU$4),IF(""=IFERROR(INDEX(INDIRECT("Data!C"&$K$5,FALSE),MATCH(AN15,Data!$A:$A,0)),$BX$12),$BX$11,IFERROR(INDEX(INDIRECT("Data!C"&$K$5,FALSE),MATCH(AN15,Data!$A:$A,0)),$BX$12)),"-") -> 220 | AX15: =IF(AND(AO15>=$AC$4,AO15<=$AU$4),IF(""=IFERROR(INDEX(INDIRECT("Data!C"&$K$5,FALSE),MATCH(AO15,Data!$A:$A,0)),$BX$12),$BX$11,IFERROR(INDEX(INDIRECT("Data!C"&$K$5,FALSE),MATCH(AO15,Data!$A:$A,0)),$BX$12)),"-") -> 220 | AY15: =IF(AND(AP15>=$AC$4,AP15<=$AU$4),IF(""=IFERROR(INDEX(INDIRECT("Data!C"&$K$5,FALSE),MATCH(AP15,Data!$A:$A,0)),$BX$12),$BX$11,IFERROR(INDEX(INDIRECT("Data!C"&$K$5,FALSE),MATCH(AP15,Data!$A:$A,0)),$BX$12)),"-") -> 238 | AZ15: =IF(AND(AQ15>=$AC$4,AQ15<=$AU$4),IF(""=IFERROR(INDEX(INDIRECT("Data!C"&$K$5,FALSE),MATCH(AQ15,Data!$A:$A,0)),$BX$12),$BX$11,IFERROR(INDEX(INDIRECT("Data!C"&$K$5,FALSE),MATCH(AQ15,Data!$A:$A,0)),$BX$12)),"-") -> 197 | BA15: =IF(AND(AR15>=$AC$4,AR15<=$AU$4),IF(""=IFERROR(INDEX(INDIRECT("Data!C"&$K$5,FALSE),MATCH(AR15,Data!$A:$A,0)),$BX$12),$BX$11,IFERROR(INDEX(INDIRECT("Data!C"&$K$5,FALSE),MATCH(AR15,Data!$A:$A,0)),$BX$12)),"-") -> 56 | BD15: =BD14+7 -> 42022 | BE15: =BD15+1 -> 42023 | BF15: =BE15+1 -> 42024 | BG15: =BF15+1 -> 42025 | BH15: =BG15+1 -> 42026 | BI15: =BH15+1 -> 42027 | BJ15: =BI15+1 -> 42028 | BL15: {=IFERROR(IF(MATCH(8,DAY(BD15:BJ15),0),BJ15,""),"")} | BM15: =IF(AND(BD15>=$AC$4,BD15<=$AU$4),IF(""=IFERROR(INDEX(INDIRECT("Data!C"&$K$5,FALSE),MATCH(BD15,Data!$A:$A,0)),$BX$12),$BX$11,IFERROR(INDEX(INDIRECT("Data!C"&$K$5,FALSE),MATCH(BD15,Data!$A:$A,0)),$BX$12)),"-") -> 37 | BN15: =IF(AND(BE15>=$AC$4,BE15<=$AU$4),IF(""=IFERROR(INDEX(INDIRECT("Data!C"&$K$5,FALSE),MATCH(BE15,Data!$A:$A,0)),$BX$12),$BX$11,IFERROR(INDEX(INDIRECT("Data!C"&$K$5,FALSE),MATCH(BE15,Data!$A:$A,0)),$BX$12)),"-") -> 362 | BO15: =IF(AND(BF15>=$AC$4,BF15<=$AU$4),IF(""=IFERROR(INDEX(INDIRECT("Data!C"&$K$5,FALSE),MATCH(BF15,Data!$A:$A,0)),$BX$12),$BX$11,IFERROR(INDEX(INDIRECT("Data!C"&$K$5,FALSE),MATCH(BF15,Data!$A:$A,0)),$BX$12)),"-") -> 336 | BP15: =IF(AND(BG15>=$AC$4,BG15<=$AU$4),IF(""=IFERROR(INDEX(INDIRECT("Data!C"&$K$5,FALSE),MATCH(BG15,Data!$A:$A,0)),$BX$12),$BX$11,IFERROR(INDEX(INDIRECT("Data!C"&$K$5,FALSE),MATCH(BG15,Data!$A:$A,0)),$BX$12)),"-") -> 201 | BQ15: =IF(AND(BH15>=$AC$4,BH15<=$AU$4),IF(""=IFERROR(INDEX(INDIRECT("Data!C"&$K$5,FALSE),MATCH(BH15,Data!$A:$A,0)),$BX$12),$BX$11,IFERROR(INDEX(INDIRECT("Data!C"&$K$5,FALSE),MATCH(BH15,Data!$A:$A,0)),$BX$12)),"-") -> 165 | BR15: =IF(AND(BI15>=$AC$4,BI15<=$AU$4),IF(""=IFERROR(INDEX(INDIRECT("Data!C"&$K$5,FALSE),MATCH(BI15,Data!$A:$A,0)),$BX$12),$BX$11,IFERROR(INDEX(INDIRECT("Data!C"&$K$5,FALSE),MATCH(BI15,Data!$A:$A,0)),$BX$12)),"-") -> 217 | BS15: =IF(AND(BJ15>=$AC$4,BJ15<=$AU$4),IF(""=IFERROR(INDEX(INDIRECT("Data!C"&$K$5,FALSE),MATCH(BJ15,Data!$A:$A,0)),$BX$12),$BX$11,IFERROR(INDEX(INDIRECT("Data!C"&$K$5,FALSE),MATCH(BJ15,Data!$A:$A,0)),$BX$12)),"-") -> 79 | BU15: =AVERAGE(K15:Q15,AC15:AI15,AU15:BA15,BM15:BS15) -> 160.96429
B16: =B15+7 -> 40937 | C16: =B16+1 -> 40938 | D16: =C16+1 -> 40939 | E16: =D16+1 -> 40940 | F16: =E16+1 -> 40941 | G16: =F16+1 -> 40942 | H16: =G16+1 -> 40943 | J16: {=IFERROR(IF(MATCH(8,DAY(B16:H16),0),H16,""),"")} | K16: =IF(AND(B16>=$AC$4,B16<=$AU$4),IF(""=IFERROR(INDEX(INDIRECT("Data!C"&$K$5,FALSE),MATCH(B16,Data!$A:$A,0)),$BX$12),$BX$11,IFERROR(INDEX(INDIRECT("Data!C"&$K$5,FALSE),MATCH(B16,Data!$A:$A,0)),$BX$12)),"-") -> 25 | L16: =IF(AND(C16>=$AC$4,C16<=$AU$4),IF(""=IFERROR(INDEX(INDIRECT("Data!C"&$K$5,FALSE),MATCH(C16,Data!$A:$A,0)),$BX$12),$BX$11,IFERROR(INDEX(INDIRECT("Data!C"&$K$5,FALSE),MATCH(C16,Data!$A:$A,0)),$BX$12)),"-") -> 324 | M16: =IF(AND(D16>=$AC$4,D16<=$AU$4),IF(""=IFERROR(INDEX(INDIRECT("Data!C"&$K$5,FALSE),MATCH(D16,Data!$A:$A,0)),$BX$12),$BX$11,IFERROR(INDEX(INDIRECT("Data!C"&$K$5,FALSE),MATCH(D16,Data!$A:$A,0)),$BX$12)),"-") -> 168 | N16: =IF(AND(E16>=$AC$4,E16<=$AU$4),IF(""=IFERROR(INDEX(INDIRECT("Data!C"&$K$5,FALSE),MATCH(E16,Data!$A:$A,0)),$BX$12),$BX$11,IFERROR(INDEX(INDIRECT("Data!C"&$K$5,FALSE),MATCH(E16,Data!$A:$A,0)),$BX$12)),"-") -> 232 | O16: =IF(AND(F16>=$AC$4,F16<=$AU$4),IF(""=IFERROR(INDEX(INDIRECT("Data!C"&$K$5,FALSE),MATCH(F16,Data!$A:$A,0)),$BX$12),$BX$11,IFERROR(INDEX(INDIRECT("Data!C"&$K$5,FALSE),MATCH(F16,Data!$A:$A,0)),$BX$12)),"-") -> 147 | P16: =IF(AND(G16>=$AC$4,G16<=$AU$4),IF(""=IFERROR(INDEX(INDIRECT("Data!C"&$K$5,FALSE),MATCH(G16,Data!$A:$A,0)),$BX$12),$BX$11,IFERROR(INDEX(INDIRECT("Data!C"&$K$5,FALSE),MATCH(G16,Data!$A:$A,0)),$BX$12)),"-") -> 128 | Q16: =IF(AND(H16>=$AC$4,H16<=$AU$4),IF(""=IFERROR(INDEX(INDIRECT("Data!C"&$K$5,FALSE),MATCH(H16,Data!$A:$A,0)),$BX$12),$BX$11,IFERROR(INDEX(INDIRECT("Data!C"&$K$5,FALSE),MATCH(H16,Data!$A:$A,0)),$BX$12)),"-") -> 43 | T16: =T15+7 -> 41301 | U16: =T16+1 -> 41302 | V16: =U16+1 -> 41303 | W16: =V16+1 -> 41304 | X16: =W16+1 -> 41305 | Y16: =X16+1 -> 41306 | Z16: =Y16+1 -> 41307 | AB16: {=IFERROR(IF(MATCH(8,DAY(T16:Z16),0),Z16,""),"")} | AC16: =IF(AND(T16>=$AC$4,T16<=$AU$4),IF(""=IFERROR(INDEX(INDIRECT("Data!C"&$K$5,FALSE),MATCH(T16,Data!$A:$A,0)),$BX$12),$BX$11,IFERROR(INDEX(INDIRECT("Data!C"&$K$5,FALSE),MATCH(T16,Data!$A:$A,0)),$BX$12)),"-") -> 19 | AD16: =IF(AND(U16>=$AC$4,U16<=$AU$4),IF(""=IFERROR(INDEX(INDIRECT("Data!C"&$K$5,FALSE),MATCH(U16,Data!$A:$A,0)),$BX$12),$BX$11,IFERROR(INDEX(INDIRECT("Data!C"&$K$5,FALSE),MATCH(U16,Data!$A:$A,0)),$BX$12)),"-") -> 271 | AE16: =IF(AND(V16>=$AC$4,V16<=$AU$4),IF(""=IFERROR(INDEX(INDIRECT("Data!C"&$K$5,FALSE),MATCH(V16,Data!$A:$A,0)),$BX$12),$BX$11,IFERROR(INDEX(INDIRECT("Data!C"&$K$5,FALSE),MATCH(V16,Data!$A:$A,0)),$BX$12)),"-") -> 259 | AF16: =IF(AND(W16>=$AC$4,W16<=$AU$4),IF(""=IFERROR(INDEX(INDIRECT("Data!C"&$K$5,FALSE),MATCH(W16,Data!$A:$A,0)),$BX$12),$BX$11,IFERROR(INDEX(INDIRECT("Data!C"&$K$5,FALSE),MATCH(W16,Data!$A:$A,0)),$BX$12)),"-") -> 200 | AG16: =IF(AND(X16>=$AC$4,X16<=$AU$4),IF(""=IFERROR(INDEX(INDIRECT("Data!C"&$K$5,FALSE),MATCH(X16,Data!$A:$A,0)),$BX$12),$BX$11,IFERROR(INDEX(INDIRECT("Data!C"&$K$5,FALSE),MATCH(X16,Data!$A:$A,0)),$BX$12)),"-") -> 169 | AH16: =IF(AND(Y16>=$AC$4,Y16<=$AU$4),IF(""=IFERROR(INDEX(INDIRECT("Data!C"&$K$5,FALSE),MATCH(Y16,Data!$A:$A,0)),$BX$12),$BX$11,IFERROR(INDEX(INDIRECT("Data!C"&$K$5,FALSE),MATCH(Y16,Data!$A:$A,0)),$BX$12)),"-") -> 134 | AI16: =IF(AND(Z16>=$AC$4,Z16<=$AU$4),IF(""=IFERROR(INDEX(INDIRECT("Data!C"&$K$5,FALSE),MATCH(Z16,Data!$A:$A,0)),$BX$12),$BX$11,IFERROR(INDEX(INDIRECT("Data!C"&$K$5,FALSE),MATCH(Z16,Data!$A:$A,0)),$BX$12)),"-") -> 54 | AL16: =AL15+7 -> 41665 | AM16: =AL16+1 -> 41666 | AN16: =AM16+1 -> 41667 | AO16: =AN16+1 -> 41668 | AP16: =AO16+1 -> 41669 | AQ16: =AP16+1 -> 41670 | AR16: =AQ16+1 -> 41671 | AT16: {=IFERROR(IF(MATCH(8,DAY(AL16:AR16),0),AR16,""),"")} | AU16: =IF(AND(AL16>=$AC$4,AL16<=$AU$4),IF(""=IFERROR(INDEX(INDIRECT("Data!C"&$K$5,FALSE),MATCH(AL16,Data!$A:$A,0)),$BX$12),$BX$11,IFERROR(INDEX(INDIRECT("Data!C"&$K$5,FALSE),MATCH(AL16,Data!$A:$A,0)),$BX$12)),"-") -> 31 | AV16: =IF(AND(AM16>=$AC$4,AM16<=$AU$4),IF(""=IFERROR(INDEX(INDIRECT("Data!C"&$K$5,FALSE),MATCH(AM16,Data!$A:$A,0)),$BX$12),$BX$11,IFERROR(INDEX(INDIRECT("Data!C"&$K$5,FALSE),MATCH(AM16,Data!$A:$A,0)),$BX$12)),"-") -> 311 | AW16: =IF(AND(AN16>=$AC$4,AN16<=$AU$4),IF(""=IFERROR(INDEX(INDIRECT("Data!C"&$K$5,FALSE),MATCH(AN16,Data!$A:$A,0)),$BX$12),$BX$11,IFERROR(INDEX(INDIRECT("Data!C"&$K$5,FALSE),MATCH(AN16,Data!$A:$A,0)),$BX$12)),"-") -> 283 | AX16: =IF(AND(AO16>=$AC$4,AO16<=$AU$4),IF(""=IFERROR(INDEX(INDIRECT("Data!C"&$K$5,FALSE),MATCH(AO16,Data!$A:$A,0)),$BX$12),$BX$11,IFERROR(INDEX(INDIRECT("Data!C"&$K$5,FALSE),MATCH(AO16,Data!$A:$A,0)),$BX$12)),"-") -> 227 | AY16: =IF(AND(AP16>=$AC$4,AP16<=$AU$4),IF(""=IFERROR(INDEX(INDIRECT("Data!C"&$K$5,FALSE),MATCH(AP16,Data!$A:$A,0)),$BX$12),$BX$11,IFERROR(INDEX(INDIRECT("Data!C"&$K$5,FALSE),MATCH(AP16,Data!$A:$A,0)),$BX$12)),"-") -> 204 | AZ16: =IF(AND(AQ16>=$AC$4,AQ16<=$AU$4),IF(""=IFERROR(INDEX(INDIRECT("Data!C"&$K$5,FALSE),MATCH(AQ16,Data!$A:$A,0)),$BX$12),$BX$11,IFERROR(INDEX(INDIRECT("Data!C"&$K$5,FALSE),MATCH(AQ16,Data!$A:$A,0)),$BX$12)),"-") -> 179 | BA16: =IF(AND(AR16>=$AC$4,AR16<=$AU$4),IF(""=IFERROR(INDEX(INDIRECT("Data!C"&$K$5,FALSE),MATCH(AR16,Data!$A:$A,0)),$BX$12),$BX$11,IFERROR(INDEX(INDIRECT("Data!C"&$K$5,FALSE),MATCH(AR16,Data!$A:$A,0)),$BX$12)),"-") -> 80 | BD16: =BD15+7 -> 42029 | BE16: =BD16+1 -> 42030 | BF16: =BE16+1 -> 42031 | BG16: =BF16+1 -> 42032 | BH16: =BG16+1 -> 42033 | BI16: =BH16+1 -> 42034 | BJ16: =BI16+1 -> 42035 | BL16: {=IFERROR(IF(MATCH(8,DAY(BD16:BJ16),0),BJ16,""),"")} | BM16: =IF(AND(BD16>=$AC$4,BD16<=$AU$4),IF(""=IFERROR(INDEX(INDIRECT("Data!C"&$K$5,FALSE),MATCH(BD16,Data!$A:$A,0)),$BX$12),$BX$11,IFERROR(INDEX(INDIRECT("Data!C"&$K$5,FALSE),MATCH(BD16,Data!$A:$A,0)),$BX$12)),"-") -> 31 | BN16: =IF(AND(BE16>=$AC$4,BE16<=$AU$4),IF(""=IFERROR(INDEX(INDIRECT("Data!C"&$K$5,FALSE),MATCH(BE16,Data!$A:$A,0)),$BX$12),$BX$11,IFERROR(INDEX(INDIRECT("Data!C"&$K$5,FALSE),MATCH(BE16,Data!$A:$A,0)),$BX$12)),"-") -> 432 | BO16: =IF(AND(BF16>=$AC$4,BF16<=$AU$4),IF(""=IFERROR(INDEX(INDIRECT("Data!C"&$K$5,FALSE),MATCH(BF16,Data!$A:$A,0)),$BX$12),$BX$11,IFERROR(INDEX(INDIRECT("Data!C"&$K$5,FALSE),MATCH(BF16,Data!$A:$A,0)),$BX$12)),"-") -> 283 | BP16: =IF(AND(BG16>=$AC$4,BG16<=$AU$4),IF(""=IFERROR(INDEX(INDIRECT("Data!C"&$K$5,FALSE),MATCH(BG16,Data!$A:$A,0)),$BX$12),$BX$11,IFERROR(INDEX(INDIRECT("Data!C"&$K$5,FALSE),MATCH(BG16,Data!$A:$A,0)),$BX$12)),"-") -> 304 | BQ16: =IF(AND(BH16>=$AC$4,BH16<=$AU$4),IF(""=IFERROR(INDEX(INDIRECT("Data!C"&$K$5,FALSE),MATCH(BH16,Data!$A:$A,0)),$BX$12),$BX$11,IFERROR(INDEX(INDIRECT("Data!C"&$K$5,FALSE),MATCH(BH16,Data!$A:$A,0)),$BX$12)),"-") -> 228 | BR16: =IF(AND(BI16>=$AC$4,BI16<=$AU$4),IF(""=IFERROR(INDEX(INDIRECT("Data!C"&$K$5,FALSE),MATCH(BI16,Data!$A:$A,0)),$BX$12),$BX$11,IFERROR(INDEX(INDIRECT("Data!C"&$K$5,FALSE),MATCH(BI16,Data!$A:$A,0)),$BX$12)),"-") -> 165 | BS16: =IF(AND(BJ16>=$AC$4,BJ16<=$AU$4),IF(""=IFERROR(INDEX(INDIRECT("Data!C"&$K$5,FALSE),MATCH(BJ16,Data!$A:$A,0)),$BX$12),$BX$11,IFERROR(INDEX(INDIRECT("Data!C"&$K$5,FALSE),MATCH(BJ16,Data!$A:$A,0)),$BX$12)),"-") -> 89 | BU16: =AVERAGE(K16:Q16,AC16:AI16,AU16:BA16,BM16:BS16) -> 179.28571 | BW16: The conditional formatting is applied
B17: =B16+7 -> 40944 | C17: =B17+1 -> 40945 | D17: =C17+1 -> 40946 | E17: =D17+1 -> 40947 | F17: =E17+1 -> 40948 | G17: =F17+1 -> 40949 | H17: =G17+1 -> 40950 | J17: {=IFERROR(IF(MATCH(8,DAY(B17:H17),0),H17,""),"")} -> 40950 | K17: =IF(AND(B17>=$AC$4,B17<=$AU$4),IF(""=IFERROR(INDEX(INDIRECT("Data!C"&$K$5,FALSE),MATCH(B17,Data!$A:$A,0)),$BX$12),$BX$11,IFERROR(INDEX(INDIRECT("Data!C"&$K$5,FALSE),MATCH(B17,Data!$A:$A,0)),$BX$12)),"-") -> 29 | L17: =IF(AND(C17>=$AC$4,C17<=$AU$4),IF(""=IFERROR(INDEX(INDIRECT("Data!C"&$K$5,FALSE),MATCH(C17,Data!$A:$A,0)),$BX$12),$BX$11,IFERROR(INDEX(INDIRECT("Data!C"&$K$5,FALSE),MATCH(C17,Data!$A:$A,0)),$BX$12)),"-") -> 311 | M17: =IF(AND(D17>=$AC$4,D17<=$AU$4),IF(""=IFERROR(INDEX(INDIRECT("Data!C"&$K$5,FALSE),MATCH(D17,Data!$A:$A,0)),$BX$12),$BX$11,IFERROR(INDEX(INDIRECT("Data!C"&$K$5,FALSE),MATCH(D17,Data!$A:$A,0)),$BX$12)),"-") -> 260 | N17: =IF(AND(E17>=$AC$4,E17<=$AU$4),IF(""=IFERROR(INDEX(INDIRECT("Data!C"&$K$5,FALSE),MATCH(E17,Data!$A:$A,0)),$BX$12),$BX$11,IFERROR(INDEX(INDIRECT("Data!C"&$K$5,FALSE),MATCH(E17,Data!$A:$A,0)),$BX$12)),"-") -> 226 | O17: =IF(AND(F17>=$AC$4,F17<=$AU$4),IF(""=IFERROR(INDEX(INDIRECT("Data!C"&$K$5,FALSE),MATCH(F17,Data!$A:$A,0)),$BX$12),$BX$11,IFERROR(INDEX(INDIRECT("Data!C"&$K$5,FALSE),MATCH(F17,Data!$A:$A,0)),$BX$12)),"-") -> 223 | P17: =IF(AND(G17>=$AC$4,G17<=$AU$4),IF(""=IFERROR(INDEX(INDIRECT("Data!C"&$K$5,FALSE),MATCH(G17,Data!$A:$A,0)),$BX$12),$BX$11,IFERROR(INDEX(INDIRECT("Data!C"&$K$5,FALSE),MATCH(G17,Data!$A:$A,0)),$BX$12)),"-") -> 219 | Q17: =IF(AND(H17>=$AC$4,H17<=$AU$4),IF(""=IFERROR(INDEX(INDIRECT("Data!C"&$K$5,FALSE),MATCH(H17,Data!$A:$A,0)),$BX$12),$BX$11,IFERROR(INDEX(INDIRECT("Data!C"&$K$5,FALSE),MATCH(H17,Data!$A:$A,0)),$BX$12)),"-") -> 51 | T17: =T16+7 -> 41308 | U17: =T17+1 -> 41309 | V17: =U17+1 -> 41310 | W17: =V17+1 -> 41311 | X17: =W17+1 -> 41312 | Y17: =X17+1 -> 41313 | Z17: =Y17+1 -> 41314 | AB17: {=IFERROR(IF(MATCH(8,DAY(T17:Z17),0),Z17,""),"")} -> 41314 | AC17: =IF(AND(T17>=$AC$4,T17<=$AU$4),IF(""=IFERROR(INDEX(INDIRECT("Data!C"&$K$5,FALSE),MATCH(T17,Data!$A:$A,0)),$BX$12),$BX$11,IFERROR(INDEX(INDIRECT("Data!C"&$K$5,FALSE),MATCH(T17,Data!$A:$A,0)),$BX$12)),"-") -> 40 | AD17: =IF(AND(U17>=$AC$4,U17<=$AU$4),IF(""=IFERROR(INDEX(INDIRECT("Data!C"&$K$5,FALSE),MATCH(U17,Data!$A:$A,0)),$BX$12),$BX$11,IFERROR(INDEX(INDIRECT("Data!C"&$K$5,FALSE),MATCH(U17,Data!$A:$A,0)),$BX$12)),"-") -> 428 | AE17: =IF(AND(V17>=$AC$4,V17<=$AU$4),IF(""=IFERROR(INDEX(INDIRECT("Data!C"&$K$5,FALSE),MATCH(V17,Data!$A:$A,0)),$BX$12),$BX$11,IFERROR(INDEX(INDIRECT("Data!C"&$K$5,FALSE),MATCH(V17,Data!$A:$A,0)),$BX$12)),"-") -> 393 | AF17: =IF(AND(W17>=$AC$4,W17<=$AU$4),IF(""=IFERROR(INDEX(INDIRECT("Data!C"&$K$5,FALSE),MATCH(W17,Data!$A:$A,0)),$BX$12),$BX$11,IFERROR(INDEX(INDIRECT("Data!C"&$K$5,FALSE),MATCH(W17,Data!$A:$A,0)),$BX$12)),"-") -> 237 | AG17: =IF(AND(X17>=$AC$4,X17<=$AU$4),IF(""=IFERROR(INDEX(INDIRECT("Data!C"&$K$5,FALSE),MATCH(X17,Data!$A:$A,0)),$BX$12),$BX$11,IFERROR(INDEX(INDIRECT("Data!C"&$K$5,FALSE),MATCH(X17,Data!$A:$A,0)),$BX$12)),"-") -> 288 | AH17: =IF(AND(Y17>=$AC$4,Y17<=$AU$4),IF(""=IFERROR(INDEX(INDIRECT("Data!C"&$K$5,FALSE),MATCH(Y17,Data!$A:$A,0)),$BX$12),$BX$11,IFERROR(INDEX(INDIRECT("Data!C"&$K$5,FALSE),MATCH(Y17,Data!$A:$A,0)),$BX$12)),"-") -> 209 | AI17: =IF(AND(Z17>=$AC$4,Z17<=$AU$4),IF(""=IFERROR(INDEX(INDIRECT("Data!C"&$K$5,FALSE),MATCH(Z17,Data!$A:$A,0)),$BX$12),$BX$11,IFERROR(INDEX(INDIRECT("Data!C"&$K$5,FALSE),MATCH(Z17,Data!$A:$A,0)),$BX$12)),"-") -> 61 | AL17: =AL16+7 -> 41672 | AM17: =AL17+1 -> 41673 | AN17: =AM17+1 -> 41674 | AO17: =AN17+1 -> 41675 | AP17: =AO17+1 -> 41676 | AQ17: =AP17+1 -> 41677 | AR17: =AQ17+1 -> 41678 | AT17: {=IFERROR(IF(MATCH(8,DAY(AL17:AR17),0),AR17,""),"")} -> 41678 | AU17: =IF(AND(AL17>=$AC$4,AL17<=$AU$4),IF(""=IFERROR(INDEX(INDIRECT("Data!C"&$K$5,FALSE),MATCH(AL17,Data!$A:$A,0)),$BX$12),$BX$11,IFERROR(INDEX(INDIRECT("Data!C"&$K$5,FALSE),MATCH(AL17,Data!$A:$A,0)),$BX$12)),"-") -> 40 | AV17: =IF(AND(AM17>=$AC$4,AM17<=$AU$4),IF(""=IFERROR(INDEX(INDIRECT("Data!C"&$K$5,FALSE),MATCH(AM17,Data!$A:$A,0)),$BX$12),$BX$11,IFERROR(INDEX(INDIRECT("Data!C"&$K$5,FALSE),MATCH(AM17,Data!$A:$A,0)),$BX$12)),"-") -> 449 | AW17: =IF(AND(AN17>=$AC$4,AN17<=$AU$4),IF(""=IFERROR(INDEX(INDIRECT("Data!C"&$K$5,FALSE),MATCH(AN17,Data!$A:$A,0)),$BX$12),$BX$11,IFERROR(INDEX(INDIRECT("Data!C"&$K$5,FALSE),MATCH(AN17,Data!$A:$A,0)),$BX$12)),"-") -> 406 | AX17: =IF(AND(AO17>=$AC$4,AO17<=$AU$4),IF(""=IFERROR(INDEX(INDIRECT("Data!C"&$K$5,FALSE),MATCH(AO17,Data!$A:$A,0)),$BX$12),$BX$11,IFERROR(INDEX(INDIRECT("Data!C"&$K$5,FALSE),MATCH(AO17,Data!$A:$A,0)),$BX$12)),"-") -> 369 | AY17: =IF(AND(AP17>=$AC$4,AP17<=$AU$4),IF(""=IFERROR(INDEX(INDIRECT("Data!C"&$K$5,FALSE),MATCH(AP17,Data!$A:$A,0)),$BX$12),$BX$11,IFERROR(INDEX(INDIRECT("Data!C"&$K$5,FALSE),MATCH(AP17,Data!$A:$A,0)),$BX$12)),"-") -> 272 | AZ17: =IF(AND(AQ17>=$AC$4,AQ17<=$AU$4),IF(""=IFERROR(INDEX(INDIRECT("Data!C"&$K$5,FALSE),MATCH(AQ17,Data!$A:$A,0)),$BX$12),$BX$11,IFERROR(INDEX(INDIRECT("Data!C"&$K$5,FALSE),MATCH(AQ17,Data!$A:$A,0)),$BX$12)),"-") -> 228 | BA17: =IF(AND(AR17>=$AC$4,AR17<=$AU$4),IF(""=IFERROR(INDEX(INDIRECT("Data!C"&$K$5,FALSE),MATCH(AR17,Data!$A:$A,0)),$BX$12),$BX$11,IFERROR(INDEX(INDIRECT("Data!C"&$K$5,FALSE),MATCH(AR17,Data!$A:$A,0)),$BX$12)),"-") -> 72 | BD17: =BD16+7 -> 42036 | BE17: =BD17+1 -> 42037 | BF17: =BE17+1 -> 42038 | BG17: =BF17+1 -> 42039 | BH17: =BG17+1 -> 42040 | BI17: =BH17+1 -> 42041 | BJ17: =BI17+1 -> 42042 | BL17: {=IFERROR(IF(MATCH(8,DAY(BD17:BJ17),0),BJ17,""),"")} | BM17: =IF(AND(BD17>=$AC$4,BD17<=$AU$4),IF(""=IFERROR(INDEX(INDIRECT("Data!C"&$K$5,FALSE),MATCH(BD17,Data!$A:$A,0)),$BX$12),$BX$11,IFERROR(INDEX(INDIRECT("Data!C"&$K$5,FALSE),MATCH(BD17,Data!$A:$A,0)),$BX$12)),"-") -> 27 | BN17: =IF(AND(BE17>=$AC$4,BE17<=$AU$4),IF(""=IFERROR(INDEX(INDIRECT("Data!C"&$K$5,FALSE),MATCH(BE17,Data!$A:$A,0)),$BX$12),$BX$11,IFERROR(INDEX(INDIRECT("Data!C"&$K$5,FALSE),MATCH(BE17,Data!$A:$A,0)),$BX$12)),"-") -> 309 | BO17: =IF(AND(BF17>=$AC$4,BF17<=$AU$4),IF(""=IFERROR(INDEX(INDIRECT("Data!C"&$K$5,FALSE),MATCH(BF17,Data!$A:$A,0)),$BX$12),$BX$11,IFERROR(INDEX(INDIRECT("Data!C"&$K$5,FALSE),MATCH(BF17,Data!$A:$A,0)),$BX$12)),"-") -> 258 | BP17: =IF(AND(BG17>=$AC$4,BG17<=$AU$4),IF(""=IFERROR(INDEX(INDIRECT("Data!C"&$K$5,FALSE),MATCH(BG17,Data!$A:$A,0)),$BX$12),$BX$11,IFERROR(INDEX(INDIRECT("Data!C"&$K$5,FALSE),MATCH(BG17,Data!$A:$A,0)),$BX$12)),"-") -> 290 | BQ17: =IF(AND(BH17>=$AC$4,BH17<=$AU$4),IF(""=IFERROR(INDEX(INDIRECT("Data!C"&$K$5,FALSE),MATCH(BH17,Data!$A:$A,0)),$BX$12),$BX$11,IFERROR(INDEX(INDIRECT("Data!C"&$K$5,FALSE),MATCH(BH17,Data!$A:$A,0)),$BX$12)),"-") -> 233 | BR17: =IF(AND(BI17>=$AC$4,BI17<=$AU$4),IF(""=IFERROR(INDEX(INDIRECT("Data!C"&$K$5,FALSE),MATCH(BI17,Data!$A:$A,0)),$BX$12),$BX$11,IFERROR(INDEX(INDIRECT("Data!C"&$K$5,FALSE),MATCH(BI17,Data!$A:$A,0)),$BX$12)),"-") -> 270 | BS17: =IF(AND(BJ17>=$AC$4,BJ17<=$AU$4),IF(""=IFERROR(INDEX(INDIRECT("Data!C"&$K$5,FALSE),MATCH(BJ17,Data!$A:$A,0)),$BX$12),$BX$11,IFERROR(INDEX(INDIRECT("Data!C"&$K$5,FALSE),MATCH(BJ17,Data!$A:$A,0)),$BX$12)),"-") -> 93 | BU17: =AVERAGE(K17:Q17,AC17:AI17,AU17:BA17,BM17:BS17) -> 224.67857 | BW17: to the Max/Min/Median/Avg values in
B18: =B17+7 -> 40951 | C18: =B18+1 -> 40952 | D18: =C18+1 -> 40953 | E18: =D18+1 -> 40954 | F18: =E18+1 -> 40955 | G18: =F18+1 -> 40956 | H18: =G18+1 -> 40957 | J18: {=IFERROR(IF(MATCH(8,DAY(B18:H18),0),H18,""),"")} | K18: =IF(AND(B18>=$AC$4,B18<=$AU$4),IF(""=IFERROR(INDEX(INDIRECT("Data!C"&$K$5,FALSE),MATCH(B18,Data!$A:$A,0)),$BX$12),$BX$11,IFERROR(INDEX(INDIRECT("Data!C"&$K$5,FALSE),MATCH(B18,Data!$A:$A,0)),$BX$12)),"-") -> 43 | L18: =IF(AND(C18>=$AC$4,C18<=$AU$4),IF(""=IFERROR(INDEX(INDIRECT("Data!C"&$K$5,FALSE),MATCH(C18,Data!$A:$A,0)),$BX$12),$BX$11,IFERROR(INDEX(INDIRECT("Data!C"&$K$5,FALSE),MATCH(C18,Data!$A:$A,0)),$BX$12)),"-") -> 263 | M18: =IF(AND(D18>=$AC$4,D18<=$AU$4),IF(""=IFERROR(INDEX(INDIRECT("Data!C"&$K$5,FALSE),MATCH(D18,Data!$A:$A,0)),$BX$12),$BX$11,IFERROR(INDEX(INDIRECT("Data!C"&$K$5,FALSE),MATCH(D18,Data!$A:$A,0)),$BX$12)),"-") -> 233 | N18: =IF(AND(E18>=$AC$4,E18<=$AU$4),IF(""=IFERROR(INDEX(INDIRECT("Data!C"&$K$5,FALSE),MATCH(E18,Data!$A:$A,0)),$BX$12),$BX$11,IFERROR(INDEX(INDIRECT("Data!C"&$K$5,FALSE),MATCH(E18,Data!$A:$A,0)),$BX$12)),"-") -> 331 | O18: =IF(AND(F18>=$AC$4,F18<=$AU$4),IF(""=IFERROR(INDEX(INDIRECT("Data!C"&$K$5,FALSE),MATCH(F18,Data!$A:$A,0)),$BX$12),$BX$11,IFERROR(INDEX(INDIRECT("Data!C"&$K$5,FALSE),MATCH(F18,Data!$A:$A,0)),$BX$12)),"-") -> 295 | P18: =IF(AND(G18>=$AC$4,G18<=$AU$4),IF(""=IFERROR(INDEX(INDIRECT("Data!C"&$K$5,FALSE),MATCH(G18,Data!$A:$A,0)),$BX$12),$BX$11,IFERROR(INDEX(INDIRECT("Data!C"&$K$5,FALSE),MATCH(G18,Data!$A:$A,0)),$BX$12)),"-") -> 172 | Q18: =IF(AND(H18>=$AC$4,H18<=$AU$4),IF(""=IFERROR(INDEX(INDIRECT("Data!C"&$K$5,FALSE),MATCH(H18,Data!$A:$A,0)),$BX$12),$BX$11,IFERROR(INDEX(INDIRECT("Data!C"&$K$5,FALSE),MATCH(H18,Data!$A:$A,0)),$BX$12)),"-") -> 68 | T18: =T17+7 -> 41315 | U18: =T18+1 -> 41316 | V18: =U18+1 -> 41317 | W18: =V18+1 -> 41318 | X18: =W18+1 -> 41319 | Y18: =X18+1 -> 41320 | Z18: =Y18+1 -> 41321 | AB18: {=IFERROR(IF(MATCH(8,DAY(T18:Z18),0),Z18,""),"")} | AC18: =IF(AND(T18>=$AC$4,T18<=$AU$4),IF(""=IFERROR(INDEX(INDIRECT("Data!C"&$K$5,FALSE),MATCH(T18,Data!$A:$A,0)),$BX$12),$BX$11,IFERROR(INDEX(INDIRECT("Data!C"&$K$5,FALSE),MATCH(T18,Data!$A:$A,0)),$BX$12)),"-") -> 30 | AD18: =IF(AND(U18>=$AC$4,U18<=$AU$4),IF(""=IFERROR(INDEX(INDIRECT("Data!C"&$K$5,FALSE),MATCH(U18,Data!$A:$A,0)),$BX$12),$BX$11,IFERROR(INDEX(INDIRECT("Data!C"&$K$5,FALSE),MATCH(U18,Data!$A:$A,0)),$BX$12)),"-") -> 392 | AE18: =IF(AND(V18>=$AC$4,V18<=$AU$4),IF(""=IFERROR(INDEX(INDIRECT("Data!C"&$K$5,FALSE),MATCH(V18,Data!$A:$A,0)),$BX$12),$BX$11,IFERROR(INDEX(INDIRECT("Data!C"&$K$5,FALSE),MATCH(V18,Data!$A:$A,0)),$BX$12)),"-") -> 316 | AF18: =IF(AND(W18>=$AC$4,W18<=$AU$4),IF(""=IFERROR(INDEX(INDIRECT("Data!C"&$K$5,FALSE),MATCH(W18,Data!$A:$A,0)),$BX$12),$BX$11,IFERROR(INDEX(INDIRECT("Data!C"&$K$5,FALSE),MATCH(W18,Data!$A:$A,0)),$BX$12)),"-") -> 325 | AG18: =IF(AND(X18>=$AC$4,X18<=$AU$4),IF(""=IFERROR(INDEX(INDIRECT("Data!C"&$K$5,FALSE),MATCH(X18,Data!$A:$A,0)),$BX$12),$BX$11,IFERROR(INDEX(INDIRECT("Data!C"&$K$5,FALSE),MATCH(X18,Data!$A:$A,0)),$BX$12)),"-") -> 265 | AH18: =IF(AND(Y18>=$AC$4,Y18<=$AU$4),IF(""=IFERROR(INDEX(INDIRECT("Data!C"&$K$5,FALSE),MATCH(Y18,Data!$A:$A,0)),$BX$12),$BX$11,IFERROR(INDEX(INDIRECT("Data!C"&$K$5,FALSE),MATCH(Y18,Data!$A:$A,0)),$BX$12)),"-") -> 191 | AI18: =IF(AND(Z18>=$AC$4,Z18<=$AU$4),IF(""=IFERROR(INDEX(INDIRECT("Data!C"&$K$5,FALSE),MATCH(Z18,Data!$A:$A,0)),$BX$12),$BX$11,IFERROR(INDEX(INDIRECT("Data!C"&$K$5,FALSE),MATCH(Z18,Data!$A:$A,0)),$BX$12)),"-") -> 74 | AL18: =AL17+7 -> 41679 | AM18: =AL18+1 -> 41680 | AN18: =AM18+1 -> 41681 | AO18: =AN18+1 -> 41682 | AP18: =AO18+1 -> 41683 | AQ18: =AP18+1 -> 41684 | AR18: =AQ18+1 -> 41685 | AT18: {=IFERROR(IF(MATCH(8,DAY(AL18:AR18),0),AR18,""),"")} | AU18: =IF(AND(AL18>=$AC$4,AL18<=$AU$4),IF(""=IFERROR(INDEX(INDIRECT("Data!C"&$K$5,FALSE),MATCH(AL18,Data!$A:$A,0)),$BX$12),$BX$11,IFERROR(INDEX(INDIRECT("Data!C"&$K$5,FALSE),MATCH(AL18,Data!$A:$A,0)),$BX$12)),"-") -> 30 | AV18: =IF(AND(AM18>=$AC$4,AM18<=$AU$4),IF(""=IFERROR(INDEX(INDIRECT("Data!C"&$K$5,FALSE),MATCH(AM18,Data!$A:$A,0)),$BX$12),$BX$11,IFERROR(INDEX(INDIRECT("Data!C"&$K$5,FALSE),MATCH(AM18,Data!$A:$A,0)),$BX$12)),"-") -> 413 | AW18: =IF(AND(AN18>=$AC$4,AN18<=$AU$4),IF(""=IFERROR(INDEX(INDIRECT("Data!C"&$K$5,FALSE),MATCH(AN18,Data!$A:$A,0)),$BX$12),$BX$11,IFERROR(INDEX(INDIRECT("Data!C"&$K$5,FALSE),MATCH(AN18,Data!$A:$A,0)),$BX$12)),"-") -> 410 | AX18: =IF(AND(AO18>=$AC$4,AO18<=$AU$4),IF(""=IFERROR(INDEX(INDIRECT("Data!C"&$K$5,FALSE),MATCH(AO18,Data!$A:$A,0)),$BX$12),$BX$11,IFERROR(INDEX(INDIRECT("Data!C"&$K$5,FALSE),MATCH(AO18,Data!$A:$A,0)),$BX$12)),"-") -> 271 | AY18: =IF(AND(AP18>=$AC$4,AP18<=$AU$4),IF(""=IFERROR(INDEX(INDIRECT("Data!C"&$K$5,FALSE),MATCH(AP18,Data!$A:$A,0)),$BX$12),$BX$11,IFERROR(INDEX(INDIRECT("Data!C"&$K$5,FALSE),MATCH(AP18,Data!$A:$A,0)),$BX$12)),"-") -> 207 | AZ18: =IF(AND(AQ18>=$AC$4,AQ18<=$AU$4),IF(""=IFERROR(INDEX(INDIRECT("Data!C"&$K$5,FALSE),MATCH(AQ18,Data!$A:$A,0)),$BX$12),$BX$11,IFERROR(INDEX(INDIRECT("Data!C"&$K$5,FALSE),MATCH(AQ18,Data!$A:$A,0)),$BX$12)),"-") -> 236 | BA18: =IF(AND(AR18>=$AC$4,AR18<=$AU$4),IF(""=IFERROR(INDEX(INDIRECT("Data!C"&$K$5,FALSE),MATCH(AR18,Data!$A:$A,0)),$BX$12),$BX$11,IFERROR(INDEX(INDIRECT("Data!C"&$K$5,FALSE),MATCH(AR18,Data!$A:$A,0)),$BX$12)),"-") -> 70 | BD18: =BD17+7 -> 42043 | BE18: =BD18+1 -> 42044 | BF18: =BE18+1 -> 42045 | BG18: =BF18+1 -> 42046 | BH18: =BG18+1 -> 42047 | BI18: =BH18+1 -> 42048 | BJ18: =BI18+1 -> 42049 | BL18: {=IFERROR(IF(MATCH(8,DAY(BD18:BJ18),0),BJ18,""),"")} -> 42049 | BM18: =IF(AND(BD18>=$AC$4,BD18<=$AU$4),IF(""=IFERROR(INDEX(INDIRECT("Data!C"&$K$5,FALSE),MATCH(BD18,Data!$A:$A,0)),$BX$12),$BX$11,IFERROR(INDEX(INDIRECT("Data!C"&$K$5,FALSE),MATCH(BD18,Data!$A:$A,0)),$BX$12)),"-") -> 36 | BN18: =IF(AND(BE18>=$AC$4,BE18<=$AU$4),IF(""=IFERROR(INDEX(INDIRECT("Data!C"&$K$5,FALSE),MATCH(BE18,Data!$A:$A,0)),$BX$12),$BX$11,IFERROR(INDEX(INDIRECT("Data!C"&$K$5,FALSE),MATCH(BE18,Data!$A:$A,0)),$BX$12)),"-") -> 430 | BO18: =IF(AND(BF18>=$AC$4,BF18<=$AU$4),IF(""=IFERROR(INDEX(INDIRECT("Data!C"&$K$5,FALSE),MATCH(BF18,Data!$A:$A,0)),$BX$12),$BX$11,IFERROR(INDEX(INDIRECT("Data!C"&$K$5,FALSE),MATCH(BF18,Data!$A:$A,0)),$BX$12)),"-") -> 425 | BP18: =IF(AND(BG18>=$AC$4,BG18<=$AU$4),IF(""=IFERROR(INDEX(INDIRECT("Data!C"&$K$5,FALSE),MATCH(BG18,Data!$A:$A,0)),$BX$12),$BX$11,IFERROR(INDEX(INDIRECT("Data!C"&$K$5,FALSE),MATCH(BG18,Data!$A:$A,0)),$BX$12)),"-") -> 390 | BQ18: =IF(AND(BH18>=$AC$4,BH18<=$AU$4),IF(""=IFERROR(INDEX(INDIRECT("Data!C"&$K$5,FALSE),MATCH(BH18,Data!$A:$A,0)),$BX$12),$BX$11,IFERROR(INDEX(INDIRECT("Data!C"&$K$5,FALSE),MATCH(BH18,Data!$A:$A,0)),$BX$12)),"-") -> 237 | BR18: =IF(AND(BI18>=$AC$4,BI18<=$AU$4),IF(""=IFERROR(INDEX(INDIRECT("Data!C"&$K$5,FALSE),MATCH(BI18,Data!$A:$A,0)),$BX$12),$BX$11,IFERROR(INDEX(INDIRECT("Data!C"&$K$5,FALSE),MATCH(BI18,Data!$A:$A,0)),$BX$12)),"-") -> 263 | BS18: =IF(AND(BJ18>=$AC$4,BJ18<=$AU$4),IF(""=IFERROR(INDEX(INDIRECT("Data!C"&$K$5,FALSE),MATCH(BJ18,Data!$A:$A,0)),$BX$12),$BX$11,IFERROR(INDEX(INDIRECT("Data!C"&$K$5,FALSE),MATCH(BJ18,Data!$A:$A,0)),$BX$12)),"-") -> 62 | BU18: =AVERAGE(K18:Q18,AC18:AI18,AU18:BA18,BM18:BS18) -> 231.35714 | BW18: the header, but this does not mean that
