Workbook
Name Month: [3]Data!$F:$F
Name Period: [3]Data!$C:$C
Name Product: [3]Data!$D:$D
Name Sales: [3]Data!$E:$E
Name Version: [3]Data!$B:$B
Name Year: [3]Data!$A:$A

Sheet Introduction
B5: Title | D5: Trend Analysis
A7: Navigation | B7: Content | D7: This file enables you to perform a detailed trend and variance analysis using statistical methods provided by Microsoft Excel
A8: Mapping | D8: With the integrated drop-down lists, you can easily navigate across months to analyze performance.
A9: Bridges for Trends | D9: Everything is set up already - all you need to do is bring in your data (sales and units)
D10: In addition, the template features a view on Month-to-Date (MTD) and Year-to-Date (YTD) results. The difference is explained below:
A11: Sales Data
A12: Units sold | D12: MTD: Refers to a single month (e.g. Oct MTD = the results of October only)
D13: YTD: Refers to the results of the entire year up to the selected month (e.g. Oct YTD = Jan + Feb + Mar + ... + Oct)
A14: Summary
B15: Customization difficulty (1-3) | D15: 2
A16: Chairs
A17: Tables | B17: Explanation of sheets | C17: Mapping: | D17: You can adjust all cells colored in green, which will then translate into the various drop-down lists across the file. You can also adjust the conversion factor (such as showing numbers in thousands, millions, etc.)
A18: Kitchen | C18: Sales Data & Units sold: | D18: This sheet contains the prepopulated data, Actuals are available until July YTD to provide a realistic picture of a business situation (middle of the year, still some months to go). Make sure to copy-paste your data into the right columns, and don't change the order of the cells.
A19: Accessories | C19: Bridges for Trends: | D19: Do not change this sheet. It is set up to automatically calculate the trend bridges needed for the statistical extrapolation in your various sheets.
C20: Summary: | D20: Select the month, and you are good to go! All kinds of different analyses, showing MTD, YTD and FY Performance, as well as variances.
C21: Individual Analysis sheets: | D21: Get the maximum level of detail for your product portfolio, showing trends, historical analyses, visualizations, and much more!
B23: How to customize | C23: 1) | D23: Ensure that the regional settings of your computer align with the "Months" in D:D on the sheet "Mapping" and update columns A:A and B:B for your particular data
C24: 2) | D24: On the data tabs "Sales Data" and "Units sold", bring in all relevant data in the green columns. Make sure the months in column B:B align with your mapping tab, and that they follow the same setup (e.g. "Jan 2020")
C25: 3) | D25: If your data set only allows for one version, copy-paste the data into both the "Budget" and "Actuals" column.
C26: 4) | D26: If needed, check out the video in which I walk you through each and every step!
C27: 5) | D27: Depending on the number of products you want to include in your file, simply copy-paste one of the invididual analysis sheets and change the product in cell E2.
C28: 6) | D28: For a detailed walkthrough, check out the attached video!

Sheet Mapping
A1: Products | B1: Version | C1: Conversion Factor | D1: Months
A2: Tables | B2: Actual | C2: 1000 | D2: Jan
A3: Kitchen | B3: Budget | D3: Feb
A4: Chairs | D4: Mar
A5: Accessories | D5: Apr
A6: Placeholder 1 | D6: May
A7: Placeholder 2 | D7: Jun
A8: Placeholder 3 | D8: Jul
A9: Placeholder 4 | D9: Aug
A10: Placeholder 5 | D10: Sep
A11: Placeholder 6 | D11: Oct
A12: Placeholder 7 | D12: Nov
A13: Placeholder 8 | D13: Dec
A14: Placeholder 9
A15: Placeholder 10
A16: Placeholder 11
A17: Placeholder 12
A18: Placeholder 13
A19: Placeholder 14

Sheet Bridges for Trends
A3: Current Month | B3: -1 | C3: -2 | D3: -3 | E3: -4 | F3: -5 | G3: -6 | H3: -7 | I3: -8 | J3: -9 | K3: -10 | L3: -11 | M3: -12 | N3: -13 | O3: -14 | P3: -15 | Q3: -16 | R3: -17 | S3: -18 | T3: -19 | U3: -20 | V3: -21 | W3: -22 | X3: -23 | Y3: -24
A4: ="Jan "&Summary!$C$2 -> Jan 2020 | B4: ="Dec "&Summary!$C$2-1 -> Dec 2019 | C4: ="Nov "&Summary!$C$2-1 -> Nov 2019 | D4: ="Oct "&Summary!$C$2-1 -> Oct 2019 | E4: ="Sep "&Summary!$C$2-1 -> Sep 2019 | F4: ="Aug "&Summary!$C$2-1 -> Aug 2019 | G4: ="Jul "&Summary!$C$2-1 -> Jul 2019 | H4: ="Jun "&Summary!$C$2-1 -> Jun 2019 | I4: ="May "&Summary!$C$2-1 -> May 2019 | J4: ="Apr "&Summary!$C$2-1 -> Apr 2019 | K4: ="Mar "&Summary!$C$2-1 -> Mar 2019 | L4: ="Feb "&Summary!$C$2-1 -> Feb 2019 | M4: ="Jan "&Summary!$C$2-1 -> Jan 2019 | N4: ="Dec "&Summary!$C$2-2 -> Dec 2018 | O4: ="Nov "&Summary!$C$2-2 -> Nov 2018 | P4: ="Oct "&Summary!$C$2-2 -> Oct 2018 | Q4: ="Sep "&Summary!$C$2-2 -> Sep 2018 | R4: ="Aug "&Summary!$C$2-2 -> Aug 2018 | S4: ="Jul "&Summary!$C$2-2 -> Jul 2018 | T4: ="Jun "&Summary!$C$2-2 -> Jun 2018 | U4: ="May "&Summary!$C$2-2 -> May 2018 | V4: ="Apr "&Summary!$C$2-2 -> Apr 2018 | W4: ="Mar "&Summary!$C$2-2 -> Mar 2018 | X4: ="Feb "&Summary!$C$2-2 -> Feb 2018 | Y4: ="Jan "&Summary!$C$2-2 -> Jan 2018
A5: ="Feb "&Summary!$C$2 -> Feb 2020 | B5: ="Jan "&Summary!$C$2 -> Jan 2020 | C5: ="Dec "&Summary!$C$2-1 -> Dec 2019 | D5: ="Nov "&Summary!$C$2-1 -> Nov 2019 | E5: Oct 2019 | F5: Sep 2019 | G5: Aug 2019 | H5: Jul 2019 | I5: ="Jun "&Summary!$C$2-1 -> Jun 2019 | J5: ="May "&Summary!$C$2-1 -> May 2019 | K5: ="Apr "&Summary!$C$2-1 -> Apr 2019 | L5: ="Mar "&Summary!$C$2-1 -> Mar 2019 | M5: ="Feb "&Summary!$C$2-1 -> Feb 2019 | N5: ="Jan "&Summary!$C$2-1 -> Jan 2019 | O5: Dec 2018 | P5: Nov 2018 | Q5: Oct 2018 | R5: Sep 2018 | S5: Aug 2018 | T5: Jul 2018 | U5: Jun 2018 | V5: May 2018 | W5: Apr 2018 | X5: Mar 2018 | Y5: Feb 2018
A6: ="Mar "&Summary!$C$2 -> Mar 2020 | B6: ="Feb "&Summary!$C$2 -> Feb 2020 | C6: ="Jan "&Summary!$C$2 -> Jan 2020 | D6: ="Dec "&Summary!$C$2-1 -> Dec 2019 | E6: Nov 2019 | F6: Oct 2019 | G6: Sep 2019 | H6: Aug 2019 | I6: Jul 2019 | J6: ="Jun "&Summary!$C$2-1 -> Jun 2019 | K6: ="May "&Summary!$C$2-1 -> May 2019 | L6: ="Apr "&Summary!$C$2-1 -> Apr 2019 | M6: ="Mar "&Summary!$C$2-1 -> Mar 2019 | N6: ="Feb "&Summary!$C$2-1 -> Feb 2019 | O6: Jan 2019 | P6: Dec 2018 | Q6: Nov 2018 | R6: Oct 2018 | S6: Sep 2018 | T6: Aug 2018 | U6: Jul 2018 | V6: Jun 2018 | W6: May 2018 | X6: Apr 2018 | Y6: Mar 2018
A7: ="Apr "&Summary!$C$2 -> Apr 2020 | B7: ="Mar "&Summary!$C$2 -> Mar 2020 | C7: ="Feb "&Summary!$C$2 -> Feb 2020 | D7: ="Jan "&Summary!$C$2 -> Jan 2020 | E7: Dec 2019 | F7: Nov 2019 | G7: Oct 2019 | H7: Sep 2019 | I7: Aug 2019 | J7: Jul 2019 | K7: ="Jun "&Summary!$C$2-1 -> Jun 2019 | L7: ="May "&Summary!$C$2-1 -> May 2019 | M7: ="Apr "&Summary!$C$2-1 -> Apr 2019 | N7: ="Mar "&Summary!$C$2-1 -> Mar 2019 | O7: Feb 2019 | P7: Jan 2019 | Q7: Dec 2018 | R7: Nov 2018 | S7: Oct 2018 | T7: Sep 2018 | U7: Aug 2018 | V7: Jul 2018 | W7: Jun 2018 | X7: May 2018 | Y7: Apr 2018
A8: ="May "&Summary!$C$2 -> May 2020 | B8: ="Apr "&Summary!$C$2 -> Apr 2020 | C8: ="Mar "&Summary!$C$2 -> Mar 2020 | D8: ="Feb "&Summary!$C$2 -> Feb 2020 | E8: Jan 2020 | F8: Dec 2019 | G8: Nov 2019 | H8: Oct 2019 | I8: Sep 2019 | J8: Aug 2019 | K8: Jul 2019 | L8: ="Jun "&Summary!$C$2-1 -> Jun 2019 | M8: ="May "&Summary!$C$2-1 -> May 2019 | N8: ="Apr "&Summary!$C$2-1 -> Apr 2019 | O8: Mar 2019 | P8: Feb 2019 | Q8: Jan 2019 | R8: Dec 2018 | S8: Nov 2018 | T8: Oct 2018 | U8: Sep 2018 | V8: Aug 2018 | W8: Jul 2018 | X8: Jun 2018 | Y8: May 2018
A9: ="Jun "&Summary!$C$2 -> Jun 2020 | B9: ="May "&Summary!$C$2 -> May 2020 | C9: ="Apr "&Summary!$C$2 -> Apr 2020 | D9: ="Mar "&Summary!$C$2 -> Mar 2020 | E9: Feb 2020 | F9: Jan 2020 | G9: Dec 2019 | H9: Nov 2019 | I9: Oct 2019 | J9: Sep 2019 | K9: Aug 2019 | L9: Jul 2019 | M9: ="Jun "&Summary!$C$2-1 -> Jun 2019 | N9: ="May "&Summary!$C$2-1 -> May 2019 | O9: Apr 2019 | P9: Mar 2019 | Q9: Feb 2019 | R9: Jan 2019 | S9: Dec 2018 | T9: Nov 2018 | U9: Oct 2018 | V9: Sep 2018 | W9: Aug 2018 | X9: Jul 2018 | Y9: Jun 2018
A10: ="Jul "&Summary!$C$2 -> Jul 2020 | B10: ="Jun "&Summary!$C$2 -> Jun 2020 | C10: ="May "&Summary!$C$2 -> May 2020 | D10: ="Apr "&Summary!$C$2 -> Apr 2020 | E10: Mar 2020 | F10: Feb 2020 | G10: Jan 2020 | H10: Dec 2019 | I10: Nov 2019 | J10: Oct 2019 | K10: Sep 2019 | L10: Aug 2019 | M10: Jul 2019 | N10: ="Jun "&Summary!$C$2-1 -> Jun 2019 | O10: May 2019 | P10: Apr 2019 | Q10: Mar 2019 | R10: Feb 2019 | S10: Jan 2019 | T10: Dec 2018 | U10: Nov 2018 | V10: Oct 2018 | W10: Sep 2018 | X10: Aug 2018 | Y10: Jul 2018
A11: ="Aug "&Summary!$C$2 -> Aug 2020 | B11: ="Jul "&Summary!$C$2 -> Jul 2020 | C11: ="Jun "&Summary!$C$2 -> Jun 2020 | D11: ="May "&Summary!$C$2 -> May 2020 | E11: Apr 2020 | F11: Mar 2020 | G11: Feb 2020 | H11: Jan 2020 | I11: Dec 2019 | J11: Nov 2019 | K11: Oct 2019 | L11: Sep 2019 | M11: Aug 2019 | N11: Jul 2019 | O11: Jun 2019 | P11: May 2019 | Q11: Apr 2019 | R11: Mar 2019 | S11: Feb 2019 | T11: Jan 2019 | U11: Dec 2018 | V11: Nov 2018 | W11: Oct 2018 | X11: Sep 2018 | Y11: Aug 2018
A12: ="Sep "&Summary!$C$2 -> Sep 2020 | B12: ="Aug "&Summary!$C$2 -> Aug 2020 | C12: ="Jul "&Summary!$C$2 -> Jul 2020 | D12: ="Jun "&Summary!$C$2 -> Jun 2020 | E12: May 2020 | F12: Apr 2020 | G12: Mar 2020 | H12: Feb 2020 | I12: Jan 2020 | J12: Dec 2019 | K12: Nov 2019 | L12: Oct 2019 | M12: Sep 2019 | N12: Aug 2019 | O12: Jul 2019 | P12: Jun 2019 | Q12: May 2019 | R12: Apr 2019 | S12: Mar 2019 | T12: Feb 2019 | U12: Jan 2019 | V12: Dec 2018 | W12: Nov 2018 | X12: Oct 2018 | Y12: Sep 2018
A13: ="Oct "&Summary!$C$2 -> Oct 2020 | B13: ="Sep "&Summary!$C$2 -> Sep 2020 | C13: ="Aug "&Summary!$C$2 -> Aug 2020 | D13: ="Jul "&Summary!$C$2 -> Jul 2020 | E13: Jun 2020 | F13: May 2020 | G13: Apr 2020 | H13: Mar 2020 | I13: Feb 2020 | J13: Jan 2020 | K13: Dec 2019 | L13: Nov 2019 | M13: Oct 2019 | N13: Sep 2019 | O13: Aug 2019 | P13: Jul 2019 | Q13: Jun 2019 | R13: May 2019 | S13: Apr 2019 | T13: Mar 2019 | U13: Feb 2019 | V13: Jan 2019 | W13: Dec 2018 | X13: Nov 2018 | Y13: Oct 2018
A14: ="Nov "&Summary!$C$2 -> Nov 2020 | B14: ="Oct "&Summary!$C$2 -> Oct 2020 | C14: ="Sep "&Summary!$C$2 -> Sep 2020 | D14: ="Aug "&Summary!$C$2 -> Aug 2020 | E14: Jul 2020 | F14: Jun 2020 | G14: May 2020 | H14: Apr 2020 | I14: Mar 2020 | J14: Feb 2020 | K14: Jan 2020 | L14: Dec 2019 | M14: Nov 2019 | N14: Oct 2019 | O14: Sep 2019 | P14: Aug 2019 | Q14: Jul 2019 | R14: Jun 2019 | S14: May 2019 | T14: Apr 2019 | U14: Mar 2019 | V14: Feb 2019 | W14: Jan 2019 | X14: Dec 2018 | Y14: Nov 2018
A15: ="Dec "&Summary!$C$2 -> Dec 2020 | B15: ="Nov "&Summary!$C$2 -> Nov 2020 | C15: ="Oct "&Summary!$C$2 -> Oct 2020 | D15: ="Sep "&Summary!$C$2 -> Sep 2020 | E15: Aug 2020 | F15: Jul 2020 | G15: Jun 2020 | H15: May 2020 | I15: Apr 2020 | J15: Mar 2020 | K15: Feb 2020 | L15: Jan 2020 | M15: Dec 2019 | N15: Nov 2019 | O15: Oct 2019 | P15: Sep 2019 | Q15: Aug 2019 | R15: Jul 2019 | S15: Jun 2019 | T15: May 2019 | U15: Apr 2019 | V15: Mar 2019 | W15: Feb 2019 | X15: Jan 2019 | Y15: Dec 2018

Sheet Sales Data
A1: Product | B1: Time | C1: Measure | D1: =Mapping!B3 -> Budget | E1: =Mapping!B2 -> Actual | F1: Year | G1: Period
A2: Chairs | B2: Apr 2018 | C2: Periodic | D2: 0 | E2: 207079.93 | F2: =YEAR(B2) -> 2018 | G2: =MONTH(DATEVALUE(LEFT(B2,3)&"1")) -> 4
A3: Accessories | B3: Apr 2018 | C3: Periodic | D3: 1397148.3 | E3: 1527716.3 | F3: =YEAR(B3) -> 2018 | G3: =MONTH(DATEVALUE(LEFT(B3,3)&"1")) -> 4
A4: Kitchen | B4: Apr 2018 | C4: Periodic | D4: 0 | E4: 50651.194 | F4: =YEAR(B4) -> 2018 | G4: =MONTH(DATEVALUE(LEFT(B4,3)&"1")) -> 4
A5: Tables | B5: Apr 2018 | C5: Periodic | D5: 248821.32 | E5: 334043.49 | F5: =YEAR(B5) -> 2018 | G5: =MONTH(DATEVALUE(LEFT(B5,3)&"1")) -> 4
A6: Chairs | B6: May 2019 | C6: Periodic | D6: 244543.69 | E6: 370877.74 | F6: =YEAR(B6) -> 2019 | G6: =MONTH(DATEVALUE(LEFT(B6,3)&"1")) -> 5
A7: Accessories | B7: May 2019 | C7: Periodic | D7: 1814704 | E7: 1970303.9 | F7: =YEAR(B7) -> 2019 | G7: =MONTH(DATEVALUE(LEFT(B7,3)&"1")) -> 5
A8: Kitchen | B8: May 2019 | C8: Periodic | D8: 103896.2 | E8: 99382.012 | F8: =YEAR(B8) -> 2019 | G8: =MONTH(DATEVALUE(LEFT(B8,3)&"1")) -> 5
A9: Tables | B9: May 2019 | C9: Periodic | D9: 444389.1 | E9: 473905.04 | F9: =YEAR(B9) -> 2019 | G9: =MONTH(DATEVALUE(LEFT(B9,3)&"1")) -> 5
A10: Chairs | B10: Apr 2020 | C10: Periodic | D10: 314809.77 | E10: 268370.6 | F10: =YEAR(B10) -> 2020 | G10: =MONTH(DATEVALUE(LEFT(B10,3)&"1")) -> 4
A11: Accessories | B11: Apr 2020 | C11: Periodic | D11: 2263168.4 | E11: 1927719.7 | F11: =YEAR(B11) -> 2020 | G11: =MONTH(DATEVALUE(LEFT(B11,3)&"1")) -> 4
A12: Kitchen | B12: Apr 2020 | C12: Periodic | D12: 311976.86 | E12: 206040.26 | F12: =YEAR(B12) -> 2020 | G12: =MONTH(DATEVALUE(LEFT(B12,3)&"1")) -> 4
A13: Tables | B13: Apr 2020 | C13: Periodic | D13: 523327.32 | E13: 309662.81 | F13: =YEAR(B13) -> 2020 | G13: =MONTH(DATEVALUE(LEFT(B13,3)&"1")) -> 4
... A145: Tables | B145: Sep 2020 | C145: Periodic | D145: 456199.94 | E145: 0 | F145: =YEAR(B145) -> 2020 | G145: =MONTH(DATEVALUE(LEFT(B145,3)&"1")) -> 9

Sheet Units sold
A1: Product | B1: Time | C1: Measure | D1: =Mapping!B3 -> Budget | E1: =Mapping!B2 -> Actual
A2: Chairs | B2: Apr 2018 | C2: Periodic | D2: 0 | E2: 0
A3: Chairs | B3: Apr 2018 | C3: Periodic | D3: 0 | E3: 0
A4: Chairs | B4: Apr 2018 | C4: Periodic | D4: 0 | E4: 46
A5: Chairs | B5: Apr 2018 | C5: Periodic | D5: 0 | E5: 12
A6: Accessories | B6: Apr 2018 | C6: Periodic | D6: 0 | E6: 0
A7: Accessories | B7: Apr 2018 | C7: Periodic | D7: 0 | E7: 0
A8: Accessories | B8: Apr 2018 | C8: Periodic | D8: 0 | E8: 0
A9: Accessories | B9: Apr 2018 | C9: Periodic | D9: 0 | E9: 0
A10: Accessories | B10: Apr 2018 | C10: Periodic | D10: 0 | E10: 0
A11: Accessories | B11: Apr 2018 | C11: Periodic | D11: 0 | E11: 0
A12: Accessories | B12: Apr 2018 | C12: Periodic | D12: 0 | E12: 198
A13: Accessories | B13: Apr 2018 | C13: Periodic | D13: 0 | E13: 300
... A1153: Tables | B1153: Sep 2020 | C1153: Periodic | D1153: 0 | E1153: 0

Sheet Summary
C1: Header | D1: YTD | E1: YTG | BG1: =MONTH(DATEVALUE(LEFT(BG6,3)&"1")) -> 8 | BH1: =MONTH(DATEVALUE(LEFT(BH6,3)&"1")) -> 9 | BI1: =MONTH(DATEVALUE(LEFT(BI6,3)&"1")) -> 10 | BJ1: =MONTH(DATEVALUE(LEFT(BJ6,3)&"1")) -> 11 | BK1: =MONTH(DATEVALUE(LEFT(BK6,3)&"1")) -> 12 | BL1: =MONTH(DATEVALUE(LEFT(BL6,3)&"1")) -> 1 | BM1: =MONTH(DATEVALUE(LEFT(BM6,3)&"1")) -> 2 | BN1: =MONTH(DATEVALUE(LEFT(BN6,3)&"1")) -> 3 | ... BR1: =MONTH(DATEVALUE(LEFT(BR6,3)&"1")) -> 7 | BT1: 13 | BU1: 14 | BV1: 15 | BW1: 16 | BX1: 17 | BY1: 18 | BZ1: 19 | CA1: 20 | CB1: 21 | CC1: 22 | CD1: 23 | CE1: 24 | CH1: 13 | CI1: 14 | CJ1: 15 | CK1: 16 | CL1: 17 | CM1: 18 | CN1: 19 | CO1: 20 | CP1: 21 | CQ1: 22 | CR1: 23 | CS1: 24
B2: Current Year | C2: 2020
B3: Current Month | C3: Jul | D3: =MONTH(DATEVALUE(C3&"1")) -> 7 | E3: =12-D3 -> 5
BT4: 12-month Trend | CH4: 6-month Trend | CV4: Monthly Average
C5: ="MTD "&$C$3 -> MTD Jul | G5: Variance | L5: ="YTD "&$C$3 -> YTD Jul | P5: Variance | U5: FY | Y5: Variance | AF5: Monthly Average | AJ5: FY Trend Outlook | AS5: ="Act "&Summary!$C$2 -> Act 2020 | CZ5: Performance
B6: =IF(Mapping!$C$2=1000,"Total Sales in kUSD",IF(Mapping!C2=1,"Total Sales in USD",IF(Mapping!C2=1000000,"Total Sales in mUSD","Error"))) -> Total Sales in kUSD | C6: ="Act "&Summary!$C$2-1 -> Act 2019 | D6: =Mapping!$B$3&" "&Summary!$C$2 -> Budget 2020 | E6: ="Act "&Summary!$C$2 -> Act 2020 | G6: Vs PY | I6: Vs BUD | L6: =C6 -> Act 2019 | M6: =D6 -> Budget 2020 | N6: =E6 -> Act 2020 | P6: Vs PY | R6: Vs BUD | U6: =L6 -> Act 2019 | V6: =M6 -> Budget 2020 | W6: ="Act "&Summary!$C$2 -> Act 2020 | Y6: Vs PY | AA6: Vs BUD | AC6: ="vs "&LEFT(#REF!,6) -> #REF! | AF6: YTD | AG6: YTG | AH6: Delta | AJ6: YTD +3m Rolling Rate | AK6: YTD +6m Rolling Rate | AL6: YTD +12m Rolling Rate | AM6: 6-month Trend | AN6: 12-month Trend | AP6: ="YTG "&RIGHT(Summary!$C$2,2)-1 -> YTG 19 | AQ6: ="YTG "&RIGHT(Summary!$C$2,2) -> YTG 20 | AS6: ='Bridges for Trends'!$A$4 -> Jan 2020 | AT6: ='Bridges for Trends'!$A$5 -> Feb 2020 | AU6: ='Bridges for Trends'!$A$6 -> Mar 2020 | AV6: ='Bridges for Trends'!$A$7 -> Apr 2020 | AW6: ='Bridges for Trends'!$A$8 -> May 2020 | AX6: ='Bridges for Trends'!$A$9 -> Jun 2020 | AY6: ='Bridges for Trends'!$A$10 -> Jul 2020 | AZ6: ='Bridges for Trends'!$A$11 -> Aug 2020 | BA6: ='Bridges for Trends'!$A$12 -> Sep 2020 | BB6: ='Bridges for Trends'!$A$13 -> Oct 2020 | BC6: ='Bridges for Trends'!$A$14 -> Nov 2020 | BD6: ='Bridges for Trends'!$A$15 -> Dec 2020 | BE6: FY | BG6: =VLOOKUP($BR6,'Bridges for Trends'!$A:$M,12,FALSE) -> Aug 2019 | BH6: =VLOOKUP($BR6,'Bridges for Trends'!$A:$M,11,FALSE) -> Sep 2019 | BI6: =VLOOKUP($BR6,'Bridges for Trends'!$A:$M,10,FALSE) -> Oct 2019 | BJ6: =VLOOKUP($BR6,'Bridges for Trends'!$A:$M,9,FALSE) -> Nov 2019 | BK6: =VLOOKUP($BR6,'Bridges for Trends'!$A:$M,8,FALSE) -> Dec 2019 | BL6: =VLOOKUP($BR6,'Bridges for Trends'!$A:$M,7,FALSE) -> Jan 2020 | BM6: =VLOOKUP($BR6,'Bridges for Trends'!$A:$M,6,FALSE) -> Feb 2020 | BN6: =VLOOKUP($BR6,'Bridges for Trends'!$A:$M,5,FALSE) -> Mar 2020 | BO6: =VLOOKUP($BR6,'Bridges for Trends'!$A:$M,4,FALSE) -> Apr 2020 | BP6: =VLOOKUP($BR6,'Bridges for Trends'!$A:$M,3,FALSE) -> May 2020 | BQ6: =VLOOKUP($BR6,'Bridges for Trends'!$A:$M,2,FALSE) -> Jun 2020 | BR6: =Summary!$C$3&" "&Summary!$C$2 -> Jul 2020 | BT6: =Mapping!$D$2 -> Jan | BU6: =Mapping!$D$3 -> Feb | BV6: =Mapping!$D$4 -> Mar | BW6: =Mapping!$D$5 -> Apr | BX6: =Mapping!$D$6 -> May | BY6: =Mapping!$D$7 -> Jun | BZ6: =Mapping!$D$8 -> Jul | CA6: =Mapping!$D$9 -> Aug | CB6: =Mapping!$D$10 -> Sep | CC6: =Mapping!$D$11 -> Oct | CD6: =Mapping!$D$12 -> Nov | CE6: =Mapping!$D$13 -> Dec | CF6: FY | CH6: =Mapping!$D$2 -> Jan | CI6: =Mapping!$D$3 -> Feb | CJ6: =Mapping!$D$4 -> Mar | CK6: =Mapping!$D$5 -> Apr | CL6: =Mapping!$D$6 -> May | CM6: =Mapping!$D$7 -> Jun | CN6: =Mapping!$D$8 -> Jul | CO6: =Mapping!$D$9 -> Aug | CP6: =Mapping!$D$10 -> Sep | CQ6: =Mapping!$D$11 -> Oct | CR6: =Mapping!$D$12 -> Nov | CS6: =Mapping!$D$13 -> Dec | CT6: FY | CV6: 3m | CW6: 6m | CX6: 12m | CZ6: YTD +3 month rolling rate | DA6: YTD +6 month rolling rate | DB6: YTD +12 month rolling rate
B7: =Mapping!A2 -> Tables | C7: =SUMIFS('Sales Data'!$E:$E,'Sales Data'!$A:$A,$B7,'Sales Data'!$B:$B,Summary!$C$3&" "&Summary!$C$2-1,'Sales Data'!$C:$C,"Periodic")/Mapping!$C$2 -> 445.98746 | D7: =SUMIFS('Sales Data'!$D:$D,'Sales Data'!$A:$A,$B7,'Sales Data'!$B:$B,Summary!$C$3&" "&Summary!$C$2,'Sales Data'!$C:$C,"Periodic")/Mapping!$C$2 -> 451.00764 | E7: =SUMIFS('Sales Data'!$E:$E,'Sales Data'!$A:$A,$B7,'Sales Data'!$B:$B,Summary!$C$3&" "&Summary!$C$2,'Sales Data'!$C:$C,"Periodic")/Mapping!$C$2 -> 321.86195 | G7: =E7-C7 -> -124.12551 | H7: =IF(ISERROR((E7/C7)-1),"N/A",(E7/C7)-1) -> -0.27831614 | I7: =E7-D7 -> -129.14569 | J7: =IF(ISERROR((E7/D7)-1),"N/A",(E7/D7)-1) -> -0.28634923 | L7: =SUMIFS('Sales Data'!$E:$E,'Sales Data'!$A:$A,$B7,'Sales Data'!$F:$F,$C$2-1,'Sales Data'!$G:$G,"<="&$D$3)/Mapping!$C$2 -> 3292.3216 | M7: =SUMIFS('Sales Data'!$D:$D,'Sales Data'!$A:$A,$B7,'Sales Data'!$F:$F,$C$2,'Sales Data'!$G:$G,"<="&$D$3)/Mapping!$C$2 -> 3514.9751 | N7: =SUMIFS('Sales Data'!$E:$E,'Sales Data'!$A:$A,$B7,'Sales Data'!$F:$F,$C$2,'Sales Data'!$G:$G,"<="&$D$3)/Mapping!$C$2 -> 2793.6432 | P7: =N7-L7 -> -498.67843 | Q7: =IF(ISERROR((N7/L7)-1),"N/A",(N7/L7)-1) -> -0.15146711 | R7: =N7-M7 -> -721.33197 | S7: =IF(ISERROR((N7/M7)-1),"N/A",(N7/M7)-1) -> -0.20521681 | U7: =SUMIFS('Sales Data'!$E:$E,'Sales Data'!$A:$A,$B7,'Sales Data'!$F:$F,$C$2-1,'Sales Data'!$G:$G,"<="&12)/Mapping!$C$2 -> 5941.2575 | V7: =SUMIFS('Sales Data'!$D:$D,'Sales Data'!$A:$A,$B7,'Sales Data'!$F:$F,$C$2,'Sales Data'!$G:$G,"<="&12)/Mapping!$C$2 -> 5937.3393 | W7: =SUMIFS('Sales Data'!$E:$E,'Sales Data'!$A:$A,$B7,'Sales Data'!$F:$F,$C$2,'Sales Data'!$G:$G,"<="&12)/Mapping!$C$2 -> 2793.6432 | Y7: =W7-U7 -> -3147.6143 | Z7: =IF(ISERROR((W7/U7)-1),"N/A",(W7/U7)-1) -> -0.52978924 | AA7: =W7-V7 -> -3143.6962 | AB7: =IF(ISERROR((W7/V7)-1),"N/A",(W7/V7)-1) -> -0.52947895 | AC7: =W7-#REF! -> #REF! | AD7: =IF(ISERROR((W7/#REF!)-1),"N/A",(W7/#REF!)-1) -> N/A | AF7: =N7/Summary!$D$3 -> 399.09188 | AG7: =(V7-N7)/Summary!$E$3 -> 628.73924 | AH7: =AG7-AF7 -> 229.64735 | AJ7: =CZ7-W7 -> 2115.0615 | AK7: =DA7-W7 -> 1954.3023 | AL7: =DB7-W7 -> 2267.7413 | AM7: =CT7-W7 -> 2227.3198 | AN7: =CF7-W7 -> 3456.9441 | AP7: =U7-L7 -> 2648.9359 | AQ7: =V7-N7 -> 3143.6962 | AS7: =SUMIFS('Sales Data'!$E:$E,'Sales Data'!$A:$A,$B7,'Sales Data'!$B:$B,AS$6,'Sales Data'!$C:$C,"Periodic")/Mapping!$C$2 -> 448.48043 | AT7: =SUMIFS('Sales Data'!$E:$E,'Sales Data'!$A:$A,$B7,'Sales Data'!$B:$B,AT$6,'Sales Data'!$C:$C,"Periodic")/Mapping!$C$2 -> 404.02749 | AU7: =SUMIFS('Sales Data'!$E:$E,'Sales Data'!$A:$A,$B7,'Sales Data'!$B:$B,AU$6,'Sales Data'!$C:$C,"Periodic")/Mapping!$C$2 -> 362.43555 | AV7: =SUMIFS('Sales Data'!$E:$E,'Sales Data'!$A:$A,$B7,'Sales Data'!$B:$B,AV$6,'Sales Data'!$C:$C,"Periodic")/Mapping!$C$2 -> 309.66281 | AW7: =SUMIFS('Sales Data'!$E:$E,'Sales Data'!$A:$A,$B7,'Sales Data'!$B:$B,AW$6,'Sales Data'!$C:$C,"Periodic")/Mapping!$C$2 -> 462.2603 | AX7: =SUMIFS('Sales Data'!$E:$E,'Sales Data'!$A:$A,$B7,'Sales Data'!$B:$B,AX$6,'Sales Data'!$C:$C,"Periodic")/Mapping!$C$2 -> 484.91463 | AY7: =SUMIFS('Sales Data'!$E:$E,'Sales Data'!$A:$A,$B7,'Sales Data'!$B:$B,AY$6,'Sales Data'!$C:$C,"Periodic")/Mapping!$C$2 -> 321.86195 | AZ7: =SUMIFS('Sales Data'!$E:$E,'Sales Data'!$A:$A,$B7,'Sales Data'!$B:$B,AZ$6,'Sales Data'!$C:$C,"Periodic")/Mapping!$C$2 -> 0 | ... BD7: =SUMIFS('Sales Data'!$E:$E,'Sales Data'!$A:$A,$B7,'Sales Data'!$B:$B,BD$6,'Sales Data'!$C:$C,"Periodic")/Mapping!$C$2 -> 0 | BE7: =SUM(AS7:BD7) -> 2793.6432 | BG7: =SUMIFS('Sales Data'!$E:$E,'Sales Data'!$A:$A,$B7,'Sales Data'!$B:$B,BG$6,'Sales Data'!$C:$C,"Periodic")/Mapping!$C$2 -> 508.46155 | BH7: =SUMIFS('Sales Data'!$E:$E,'Sales Data'!$A:$A,$B7,'Sales Data'!$B:$B,BH$6,'Sales Data'!$C:$C,"Periodic")/Mapping!$C$2 -> 424.09441 | BI7: =SUMIFS('Sales Data'!$E:$E,'Sales Data'!$A:$A,$B7,'Sales Data'!$B:$B,BI$6,'Sales Data'!$C:$C,"Periodic")/Mapping!$C$2 -> 633.17249 | BJ7: =SUMIFS('Sales Data'!$E:$E,'Sales Data'!$A:$A,$B7,'Sales Data'!$B:$B,BJ$6,'Sales Data'!$C:$C,"Periodic")/Mapping!$C$2 -> 700.03737 | BK7: =SUMIFS('Sales Data'!$E:$E,'Sales Data'!$A:$A,$B7,'Sales Data'!$B:$B,BK$6,'Sales Data'!$C:$C,"Periodic")/Mapping!$C$2 -> 383.17004 | BL7: =SUMIFS('Sales Data'!$E:$E,'Sales Data'!$A:$A,$B7,'Sales Data'!$B:$B,BL$6,'Sales Data'!$C:$C,"Periodic")/Mapping!$C$2 -> 448.48043 | BM7: =SUMIFS('Sales Data'!$E:$E,'Sales Data'!$A:$A,$B7,'Sales Data'!$B:$B,BM$6,'Sales Data'!$C:$C,"Periodic")/Mapping!$C$2 -> 404.02749 | BN7: =SUMIFS('Sales Data'!$E:$E,'Sales Data'!$A:$A,$B7,'Sales Data'!$B:$B,BN$6,'Sales Data'!$C:$C,"Periodic")/Mapping!$C$2 -> 362.43555 | ... BR7: =SUMIFS('Sales Data'!$E:$E,'Sales Data'!$A:$A,$B7,'Sales Data'!$B:$B,BR$6,'Sales Data'!$C:$C,"Periodic")/Mapping!$C$2 -> 321.86195 | BT7: =IFERROR(IF(AS7<>0,AS7,FORECAST(BT$1,$BG7:$BR7,$BG$1:$BR$1)),"") -> 448.48043 | BU7: =IFERROR(IF(AT7<>0,AT7,FORECAST(BU$1,$BG7:$BR7,$BG$1:$BR$1)),"") -> 404.02749 | BV7: =IFERROR(IF(AU7<>0,AU7,FORECAST(BV$1,$BG7:$BR7,$BG$1:$BR$1)),"") -> 362.43555 | BW7: =IFERROR(IF(AV7<>0,AV7,FORECAST(BW$1,$BG7:$BR7,$BG$1:$BR$1)),"") -> 309.66281 | BX7: =IFERROR(IF(AW7<>0,AW7,FORECAST(BX$1,$BG7:$BR7,$BG$1:$BR$1)),"") -> 462.2603 | BY7: =IFERROR(IF(AX7<>0,AX7,FORECAST(BY$1,$BG7:$BR7,$BG$1:$BR$1)),"") -> 484.91463 | BZ7: =IFERROR(IF(AY7<>0,AY7,FORECAST(BZ$1,$BG7:$BR7,$BG$1:$BR$1)),"") -> 321.86195 | CA7: =IFERROR(IF(AZ7<>0,AZ7,FORECAST(CA$1,$BG7:$BR7,$BG$1:$BR$1)),"") -> 660.69972 | ... CE7: =IFERROR(IF(BD7<>0,BD7,FORECAST(CE$1,$BG7:$BR7,$BG$1:$BR$1)),"") -> 722.07793 | CF7: =SUM(BT7:CE7) -> 6250.5873 | CH7: =IFERROR(IF(AS7<>0,AS7,FORECAST(CH$1,$BM7:$BR7,$BM$1:$BR$1)),"") -> 448.48043 | CI7: =IFERROR(IF(AT7<>0,AT7,FORECAST(CI$1,$BM7:$BR7,$BM$1:$BR$1)),"") -> 404.02749 | CJ7: =IFERROR(IF(AU7<>0,AU7,FORECAST(CJ$1,$BM7:$BR7,$BM$1:$BR$1)),"") -> 362.43555 | CK7: =IFERROR(IF(AV7<>0,AV7,FORECAST(CK$1,$BM7:$BR7,$BM$1:$BR$1)),"") -> 309.66281 | CL7: =IFERROR(IF(AW7<>0,AW7,FORECAST(CL$1,$BM7:$BR7,$BM$1:$BR$1)),"") -> 462.2603 | CM7: =IFERROR(IF(AX7<>0,AX7,FORECAST(CM$1,$BM7:$BR7,$BM$1:$BR$1)),"") -> 484.91463 | CN7: =IFERROR(IF(AY7<>0,AY7,FORECAST(CN$1,$BM7:$BR7,$BM$1:$BR$1)),"") -> 321.86195 | CO7: =IFERROR(IF(AZ7<>0,AZ7,FORECAST(CO$1,$BM7:$BR7,$BM$1:$BR$1)),"") -> 439.22356 | ... CS7: =IFERROR(IF(BD7<>0,BD7,FORECAST(CS$1,$BM7:$BR7,$BM$1:$BR$1)),"") -> 451.70436 | CT7: =SUM(CH7:CS7) -> 5020.963 | CV7: =SUM(BP7:BR7)/3 -> 423.01229 | CW7: =SUM(BM7:BR7)/6 -> 390.86046 | CX7: =SUM(BG7:BR7)/12 -> 453.54825 | CZ7: =N7+Summary!$E$3*CV7 -> 4908.7046 | DA7: =N7+CW7*Summary!$E$3 -> 4747.9455 | DB7: =N7+CX7*Summary!$E$3 -> 5061.3844
B8: =Mapping!A3 -> Kitchen | C8: =SUMIFS('Sales Data'!$E:$E,'Sales Data'!$A:$A,$B8,'Sales Data'!$B:$B,Summary!$C$3&" "&Summary!$C$2-1,'Sales Data'!$C:$C,"Periodic")/Mapping!$C$2 -> 141.73288 | D8: =SUMIFS('Sales Data'!$D:$D,'Sales Data'!$A:$A,$B8,'Sales Data'!$B:$B,Summary!$C$3&" "&Summary!$C$2,'Sales Data'!$C:$C,"Periodic")/Mapping!$C$2 -> 417.69261 | E8: =SUMIFS('Sales Data'!$E:$E,'Sales Data'!$A:$A,$B8,'Sales Data'!$B:$B,Summary!$C$3&" "&Summary!$C$2,'Sales Data'!$C:$C,"Periodic")/Mapping!$C$2 -> 294.97234 | G8: =E8-C8 -> 153.23947 | H8: =IF(ISERROR((E8/C8)-1),"N/A",(E8/C8)-1) -> 1.081185 | I8: =E8-D8 -> -122.72026 | J8: =IF(ISERROR((E8/D8)-1),"N/A",(E8/D8)-1) -> -0.2938052 | L8: =SUMIFS('Sales Data'!$E:$E,'Sales Data'!$A:$A,$B8,'Sales Data'!$F:$F,$C$2-1,'Sales Data'!$G:$G,"<="&$D$3)/Mapping!$C$2 -> 754.79524 | M8: =SUMIFS('Sales Data'!$D:$D,'Sales Data'!$A:$A,$B8,'Sales Data'!$F:$F,$C$2,'Sales Data'!$G:$G,"<="&$D$3)/Mapping!$C$2 -> 2282.5057 | N8: =SUMIFS('Sales Data'!$E:$E,'Sales Data'!$A:$A,$B8,'Sales Data'!$F:$F,$C$2,'Sales Data'!$G:$G,"<="&$D$3)/Mapping!$C$2 -> 1731.7656 | P8: =N8-L8 -> 976.9704 | Q8: =IF(ISERROR((N8/L8)-1),"N/A",(N8/L8)-1) -> 1.2943516 | R8: =N8-M8 -> -550.74001 | S8: =IF(ISERROR((N8/M8)-1),"N/A",(N8/M8)-1) -> -0.24128747 | U8: =SUMIFS('Sales Data'!$E:$E,'Sales Data'!$A:$A,$B8,'Sales Data'!$F:$F,$C$2-1,'Sales Data'!$G:$G,"<="&12)/Mapping!$C$2 -> 1792.1636 | V8: =SUMIFS('Sales Data'!$D:$D,'Sales Data'!$A:$A,$B8,'Sales Data'!$F:$F,$C$2,'Sales Data'!$G:$G,"<="&12)/Mapping!$C$2 -> 4921.3566 | W8: =SUMIFS('Sales Data'!$E:$E,'Sales Data'!$A:$A,$B8,'Sales Data'!$F:$F,$C$2,'Sales Data'!$G:$G,"<="&12)/Mapping!$C$2 -> 1731.7656 | Y8: =W8-U8 -> -60.397989 | Z8: =IF(ISERROR((W8/U8)-1),"N/A",(W8/U8)-1) -> -0.033701158 | AA8: =W8-V8 -> -3189.5909 | AB8: =IF(ISERROR((W8/V8)-1),"N/A",(W8/V8)-1) -> -0.64811214 | AC8: =W8-#REF! -> #REF! | AD8: =IF(ISERROR((W8/#REF!)-1),"N/A",(W8/#REF!)-1) -> N/A | AF8: =N8/Summary!$D$3 -> 247.39509 | AG8: =(V8-N8)/Summary!$E$3 -> 637.91818 | AH8: =AG8-AF8 -> 390.52309 | AJ8: =CZ8-V8 -> -1874.2471 | AK8: =DA8-V8 -> -1926.1317 | AL8: =DB8-V8 -> -2035.7851 | AM8: =CT8-V8 -> -1246.7198 | AN8: =CF8-V8 -> -2178.5762 | AP8: =U8-L8 -> 1037.3684 | AQ8: =V8-N8 -> 3189.5909 | AS8: =SUMIFS('Sales Data'!$E:$E,'Sales Data'!$A:$A,$B8,'Sales Data'!$B:$B,AS$6,'Sales Data'!$C:$C,"Periodic")/Mapping!$C$2 -> 215.61462 | AT8: =SUMIFS('Sales Data'!$E:$E,'Sales Data'!$A:$A,$B8,'Sales Data'!$B:$B,AT$6,'Sales Data'!$C:$C,"Periodic")/Mapping!$C$2 -> 214.22627 | AU8: =SUMIFS('Sales Data'!$E:$E,'Sales Data'!$A:$A,$B8,'Sales Data'!$B:$B,AU$6,'Sales Data'!$C:$C,"Periodic")/Mapping!$C$2 -> 306.67823 | AV8: =SUMIFS('Sales Data'!$E:$E,'Sales Data'!$A:$A,$B8,'Sales Data'!$B:$B,AV$6,'Sales Data'!$C:$C,"Periodic")/Mapping!$C$2 -> 206.04026 | AW8: =SUMIFS('Sales Data'!$E:$E,'Sales Data'!$A:$A,$B8,'Sales Data'!$B:$B,AW$6,'Sales Data'!$C:$C,"Periodic")/Mapping!$C$2 -> 244.29622 | AX8: =SUMIFS('Sales Data'!$E:$E,'Sales Data'!$A:$A,$B8,'Sales Data'!$B:$B,AX$6,'Sales Data'!$C:$C,"Periodic")/Mapping!$C$2 -> 249.9377 | AY8: =SUMIFS('Sales Data'!$E:$E,'Sales Data'!$A:$A,$B8,'Sales Data'!$B:$B,AY$6,'Sales Data'!$C:$C,"Periodic")/Mapping!$C$2 -> 294.97234 | AZ8: =SUMIFS('Sales Data'!$E:$E,'Sales Data'!$A:$A,$B8,'Sales Data'!$B:$B,AZ$6,'Sales Data'!$C:$C,"Periodic")/Mapping!$C$2 -> 0 | ... BD8: =SUMIFS('Sales Data'!$E:$E,'Sales Data'!$A:$A,$B8,'Sales Data'!$B:$B,BD$6,'Sales Data'!$C:$C,"Periodic")/Mapping!$C$2 -> 0 | BE8: =SUM(AS8:BD8) -> 1731.7656 | BG8: =SUMIFS('Sales Data'!$E:$E,'Sales Data'!$A:$A,$B8,'Sales Data'!$B:$B,BG$6,'Sales Data'!$C:$C,"Periodic")/Mapping!$C$2 -> 171.96272 | BH8: =SUMIFS('Sales Data'!$E:$E,'Sales Data'!$A:$A,$B8,'Sales Data'!$B:$B,BH$6,'Sales Data'!$C:$C,"Periodic")/Mapping!$C$2 -> 171.63258 | BI8: =SUMIFS('Sales Data'!$E:$E,'Sales Data'!$A:$A,$B8,'Sales Data'!$B:$B,BI$6,'Sales Data'!$C:$C,"Periodic")/Mapping!$C$2 -> 212.70068 | BJ8: =SUMIFS('Sales Data'!$E:$E,'Sales Data'!$A:$A,$B8,'Sales Data'!$B:$B,BJ$6,'Sales Data'!$C:$C,"Periodic")/Mapping!$C$2 -> 258.54867 | BK8: =SUMIFS('Sales Data'!$E:$E,'Sales Data'!$A:$A,$B8,'Sales Data'!$B:$B,BK$6,'Sales Data'!$C:$C,"Periodic")/Mapping!$C$2 -> 222.52373 | BL8: =SUMIFS('Sales Data'!$E:$E,'Sales Data'!$A:$A,$B8,'Sales Data'!$B:$B,BL$6,'Sales Data'!$C:$C,"Periodic")/Mapping!$C$2 -> 215.61462 | BM8: =SUMIFS('Sales Data'!$E:$E,'Sales Data'!$A:$A,$B8,'Sales Data'!$B:$B,BM$6,'Sales Data'!$C:$C,"Periodic")/Mapping!$C$2 -> 214.22627 | BN8: =SUMIFS('Sales Data'!$E:$E,'Sales Data'!$A:$A,$B8,'Sales Data'!$B:$B,BN$6,'Sales Data'!$C:$C,"Periodic")/Mapping!$C$2 -> 306.67823 | ... BR8: =SUMIFS('Sales Data'!$E:$E,'Sales Data'!$A:$A,$B8,'Sales Data'!$B:$B,BR$6,'Sales Data'!$C:$C,"Periodic")/Mapping!$C$2 -> 294.97234 | BT8: =IFERROR(IF(AS8<>0,AS8,FORECAST(BT$1,$BG8:$BR8,$BG$1:$BR$1)),"") -> 215.61462 | BU8: =IFERROR(IF(AT8<>0,AT8,FORECAST(BU$1,$BG8:$BR8,$BG$1:$BR$1)),"") -> 214.22627 | BV8: =IFERROR(IF(AU8<>0,AU8,FORECAST(BV$1,$BG8:$BR8,$BG$1:$BR$1)),"") -> 306.67823 | BW8: =IFERROR(IF(AV8<>0,AV8,FORECAST(BW$1,$BG8:$BR8,$BG$1:$BR$1)),"") -> 206.04026 | BX8: =IFERROR(IF(AW8<>0,AW8,FORECAST(BX$1,$BG8:$BR8,$BG$1:$BR$1)),"") -> 244.29622 | BY8: =IFERROR(IF(AX8<>0,AX8,FORECAST(BY$1,$BG8:$BR8,$BG$1:$BR$1)),"") -> 249.9377 | BZ8: =IFERROR(IF(AY8<>0,AY8,FORECAST(BZ$1,$BG8:$BR8,$BG$1:$BR$1)),"") -> 294.97234 | CA8: =IFERROR(IF(AZ8<>0,AZ8,FORECAST(CA$1,$BG8:$BR8,$BG$1:$BR$1)),"") -> 205.88788 | ... CE8: =IFERROR(IF(BD8<>0,BD8,FORECAST(CE$1,$BG8:$BR8,$BG$1:$BR$1)),"") -> 198.51802 | CF8: =SUM(BT8:CE8) -> 2742.7804 | CH8: =IFERROR(IF(AS8<>0,AS8,FORECAST(CH$1,$BM8:$BR8,$BM$1:$BR$1)),"") -> 215.61462 | CI8: =IFERROR(IF(AT8<>0,AT8,FORECAST(CI$1,$BM8:$BR8,$BM$1:$BR$1)),"") -> 214.22627 | CJ8: =IFERROR(IF(AU8<>0,AU8,FORECAST(CJ$1,$BM8:$BR8,$BM$1:$BR$1)),"") -> 306.67823 | CK8: =IFERROR(IF(AV8<>0,AV8,FORECAST(CK$1,$BM8:$BR8,$BM$1:$BR$1)),"") -> 206.04026 | CL8: =IFERROR(IF(AW8<>0,AW8,FORECAST(CL$1,$BM8:$BR8,$BM$1:$BR$1)),"") -> 244.29622 | CM8: =IFERROR(IF(AX8<>0,AX8,FORECAST(CM$1,$BM8:$BR8,$BM$1:$BR$1)),"") -> 249.9377 | CN8: =IFERROR(IF(AY8<>0,AY8,FORECAST(CN$1,$BM8:$BR8,$BM$1:$BR$1)),"") -> 294.97234 | CO8: =IFERROR(IF(AZ8<>0,AZ8,FORECAST(CO$1,$BM8:$BR8,$BM$1:$BR$1)),"") -> 373.0448 | ... CS8: =IFERROR(IF(BD8<>0,BD8,FORECAST(CS$1,$BM8:$BR8,$BM$1:$BR$1)),"") -> 404.10363 | CT8: =SUM(CH8:CS8) -> 3674.6367 | CV8: =SUM(BP8:BR8)/3 -> 263.06875 | CW8: =SUM(BM8:BR8)/6 -> 252.69184 | CX8: =SUM(BG8:BR8)/12 -> 230.76117 | CZ8: =N8+Summary!$E$3*CV8 -> 3047.1094 | DA8: =N8+CW8*Summary!$E$3 -> 2995.2248 | DB8: =N8+CX8*Summary!$E$3 -> 2885.5715
B9: =Mapping!A4 -> Chairs | C9: =SUMIFS('Sales Data'!$E:$E,'Sales Data'!$A:$A,$B9,'Sales Data'!$B:$B,Summary!$C$3&" "&Summary!$C$2-1,'Sales Data'!$C:$C,"Periodic")/Mapping!$C$2 -> 330.49778 | D9: =SUMIFS('Sales Data'!$D:$D,'Sales Data'!$A:$A,$B9,'Sales Data'!$B:$B,Summary!$C$3&" "&Summary!$C$2,'Sales Data'!$C:$C,"Periodic")/Mapping!$C$2 -> 329.69726 | E9: =SUMIFS('Sales Data'!$E:$E,'Sales Data'!$A:$A,$B9,'Sales Data'!$B:$B,Summary!$C$3&" "&Summary!$C$2,'Sales Data'!$C:$C,"Periodic")/Mapping!$C$2 -> 348.54445 | G9: =E9-C9 -> 18.046668 | H9: =IF(ISERROR((E9/C9)-1),"N/A",(E9/C9)-1) -> 0.054604505 | I9: =E9-D9 -> 18.847186 | J9: =IF(ISERROR((E9/D9)-1),"N/A",(E9/D9)-1) -> 0.057165127 | L9: =SUMIFS('Sales Data'!$E:$E,'Sales Data'!$A:$A,$B9,'Sales Data'!$F:$F,$C$2-1,'Sales Data'!$G:$G,"<="&$D$3)/Mapping!$C$2 -> 2028.7036 | M9: =SUMIFS('Sales Data'!$D:$D,'Sales Data'!$A:$A,$B9,'Sales Data'!$F:$F,$C$2,'Sales Data'!$G:$G,"<="&$D$3)/Mapping!$C$2 -> 2129.5317 | N9: =SUMIFS('Sales Data'!$E:$E,'Sales Data'!$A:$A,$B9,'Sales Data'!$F:$F,$C$2,'Sales Data'!$G:$G,"<="&$D$3)/Mapping!$C$2 -> 2203.3072 | P9: =N9-L9 -> 174.60358 | Q9: =IF(ISERROR((N9/L9)-1),"N/A",(N9/L9)-1) -> 0.086066578 | R9: =N9-M9 -> 73.775501 | S9: =IF(ISERROR((N9/M9)-1),"N/A",(N9/M9)-1) -> 0.034644002 | U9: =SUMIFS('Sales Data'!$E:$E,'Sales Data'!$A:$A,$B9,'Sales Data'!$F:$F,$C$2-1,'Sales Data'!$G:$G,"<="&12)/Mapping!$C$2 -> 3274.872 | V9: =SUMIFS('Sales Data'!$D:$D,'Sales Data'!$A:$A,$B9,'Sales Data'!$F:$F,$C$2,'Sales Data'!$G:$G,"<="&12)/Mapping!$C$2 -> 3681.2958 | W9: =SUMIFS('Sales Data'!$E:$E,'Sales Data'!$A:$A,$B9,'Sales Data'!$F:$F,$C$2,'Sales Data'!$G:$G,"<="&12)/Mapping!$C$2 -> 2203.3072 | Y9: =W9-U9 -> -1071.5648 | Z9: =IF(ISERROR((W9/U9)-1),"N/A",(W9/U9)-1) -> -0.32720814 | AA9: =W9-V9 -> -1477.9885 | AB9: =IF(ISERROR((W9/V9)-1),"N/A",(W9/V9)-1) -> -0.40148595 | AC9: =W9-#REF! -> #REF! | AD9: =IF(ISERROR((W9/#REF!)-1),"N/A",(W9/#REF!)-1) -> N/A | AF9: =N9/Summary!$D$3 -> 314.75817 | AG9: =(V9-N9)/Summary!$E$3 -> 295.59771 | AH9: =AG9-AF9 -> -19.160468 | AJ9: =CZ9-V9 -> 186.68176 | AK9: =DA9-V9 -> 69.078111 | AL9: =DB9-V9 -> -40.707032 | AM9: =CT9-V9 -> 2024.2416 | AN9: =CF9-V9 -> -529.10159 | AP9: =U9-L9 -> 1246.1684 | AQ9: =V9-N9 -> 1477.9885 | AS9: =SUMIFS('Sales Data'!$E:$E,'Sales Data'!$A:$A,$B9,'Sales Data'!$B:$B,AS$6,'Sales Data'!$C:$C,"Periodic")/Mapping!$C$2 -> 346.82725 | AT9: =SUMIFS('Sales Data'!$E:$E,'Sales Data'!$A:$A,$B9,'Sales Data'!$B:$B,AT$6,'Sales Data'!$C:$C,"Periodic")/Mapping!$C$2 -> 238.7955 | AU9: =SUMIFS('Sales Data'!$E:$E,'Sales Data'!$A:$A,$B9,'Sales Data'!$B:$B,AU$6,'Sales Data'!$C:$C,"Periodic")/Mapping!$C$2 -> 350.5117 | AV9: =SUMIFS('Sales Data'!$E:$E,'Sales Data'!$A:$A,$B9,'Sales Data'!$B:$B,AV$6,'Sales Data'!$C:$C,"Periodic")/Mapping!$C$2 -> 268.3706 | AW9: =SUMIFS('Sales Data'!$E:$E,'Sales Data'!$A:$A,$B9,'Sales Data'!$B:$B,AW$6,'Sales Data'!$C:$C,"Periodic")/Mapping!$C$2 -> 198.77341 | AX9: =SUMIFS('Sales Data'!$E:$E,'Sales Data'!$A:$A,$B9,'Sales Data'!$B:$B,AX$6,'Sales Data'!$C:$C,"Periodic")/Mapping!$C$2 -> 451.48431 | AY9: =SUMIFS('Sales Data'!$E:$E,'Sales Data'!$A:$A,$B9,'Sales Data'!$B:$B,AY$6,'Sales Data'!$C:$C,"Periodic")/Mapping!$C$2 -> 348.54445 | AZ9: =SUMIFS('Sales Data'!$E:$E,'Sales Data'!$A:$A,$B9,'Sales Data'!$B:$B,AZ$6,'Sales Data'!$C:$C,"Periodic")/Mapping!$C$2 -> 0 | ... BD9: =SUMIFS('Sales Data'!$E:$E,'Sales Data'!$A:$A,$B9,'Sales Data'!$B:$B,BD$6,'Sales Data'!$C:$C,"Periodic")/Mapping!$C$2 -> 0 | BE9: =SUM(AS9:BD9) -> 2203.3072 | BG9: =SUMIFS('Sales Data'!$E:$E,'Sales Data'!$A:$A,$B9,'Sales Data'!$B:$B,BG$6,'Sales Data'!$C:$C,"Periodic")/Mapping!$C$2 -> 207.34384 | BH9: =SUMIFS('Sales Data'!$E:$E,'Sales Data'!$A:$A,$B9,'Sales Data'!$B:$B,BH$6,'Sales Data'!$C:$C,"Periodic")/Mapping!$C$2 -> 331.06043 | BI9: =SUMIFS('Sales Data'!$E:$E,'Sales Data'!$A:$A,$B9,'Sales Data'!$B:$B,BI$6,'Sales Data'!$C:$C,"Periodic")/Mapping!$C$2 -> 191.55253 | BJ9: =SUMIFS('Sales Data'!$E:$E,'Sales Data'!$A:$A,$B9,'Sales Data'!$B:$B,BJ$6,'Sales Data'!$C:$C,"Periodic")/Mapping!$C$2 -> 319.95401 | BK9: =SUMIFS('Sales Data'!$E:$E,'Sales Data'!$A:$A,$B9,'Sales Data'!$B:$B,BK$6,'Sales Data'!$C:$C,"Periodic")/Mapping!$C$2 -> 196.25758 | BL9: =SUMIFS('Sales Data'!$E:$E,'Sales Data'!$A:$A,$B9,'Sales Data'!$B:$B,BL$6,'Sales Data'!$C:$C,"Periodic")/Mapping!$C$2 -> 346.82725 | BM9: =SUMIFS('Sales Data'!$E:$E,'Sales Data'!$A:$A,$B9,'Sales Data'!$B:$B,BM$6,'Sales Data'!$C:$C,"Periodic")/Mapping!$C$2 -> 238.7955 | BN9: =SUMIFS('Sales Data'!$E:$E,'Sales Data'!$A:$A,$B9,'Sales Data'!$B:$B,BN$6,'Sales Data'!$C:$C,"Periodic")/Mapping!$C$2 -> 350.5117 | ... BR9: =SUMIFS('Sales Data'!$E:$E,'Sales Data'!$A:$A,$B9,'Sales Data'!$B:$B,BR$6,'Sales Data'!$C:$C,"Periodic")/Mapping!$C$2 -> 348.54445 | BT9: =IFERROR(IF(AS9<>0,AS9,FORECAST(BT$1,$BG9:$BR9,$BG$1:$BR$1)),"") -> 346.82725 | BU9: =IFERROR(IF(AT9<>0,AT9,FORECAST(BU$1,$BG9:$BR9,$BG$1:$BR$1)),"") -> 238.7955 | BV9: =IFERROR(IF(AU9<>0,AU9,FORECAST(BV$1,$BG9:$BR9,$BG$1:$BR$1)),"") -> 350.5117 | BW9: =IFERROR(IF(AV9<>0,AV9,FORECAST(BW$1,$BG9:$BR9,$BG$1:$BR$1)),"") -> 268.3706 | BX9: =IFERROR(IF(AW9<>0,AW9,FORECAST(BX$1,$BG9:$BR9,$BG$1:$BR$1)),"") -> 198.77341 | BY9: =IFERROR(IF(AX9<>0,AX9,FORECAST(BY$1,$BG9:$BR9,$BG$1:$BR$1)),"") -> 451.48431 | BZ9: =IFERROR(IF(AY9<>0,AY9,FORECAST(BZ$1,$BG9:$BR9,$BG$1:$BR$1)),"") -> 348.54445 | CA9: =IFERROR(IF(AZ9<>0,AZ9,FORECAST(CA$1,$BG9:$BR9,$BG$1:$BR$1)),"") -> 202.38112 | ... CE9: =IFERROR(IF(BD9<>0,BD9,FORECAST(CE$1,$BG9:$BR9,$BG$1:$BR$1)),"") -> 177.17366 | CF9: =SUM(BT9:CE9) -> 3152.1942 | CH9: =IFERROR(IF(AS9<>0,AS9,FORECAST(CH$1,$BM9:$BR9,$BM$1:$BR$1)),"") -> 346.82725 | CI9: =IFERROR(IF(AT9<>0,AT9,FORECAST(CI$1,$BM9:$BR9,$BM$1:$BR$1)),"") -> 238.7955 | CJ9: =IFERROR(IF(AU9<>0,AU9,FORECAST(CJ$1,$BM9:$BR9,$BM$1:$BR$1)),"") -> 350.5117 | CK9: =IFERROR(IF(AV9<>0,AV9,FORECAST(CK$1,$BM9:$BR9,$BM$1:$BR$1)),"") -> 268.3706 | CL9: =IFERROR(IF(AW9<>0,AW9,FORECAST(CL$1,$BM9:$BR9,$BM$1:$BR$1)),"") -> 198.77341 | CM9: =IFERROR(IF(AX9<>0,AX9,FORECAST(CM$1,$BM9:$BR9,$BM$1:$BR$1)),"") -> 451.48431 | CN9: =IFERROR(IF(AY9<>0,AY9,FORECAST(CN$1,$BM9:$BR9,$BM$1:$BR$1)),"") -> 348.54445 | CO9: =IFERROR(IF(AZ9<>0,AZ9,FORECAST(CO$1,$BM9:$BR9,$BM$1:$BR$1)),"") -> 655.75658 | ... CS9: =IFERROR(IF(BD9<>0,BD9,FORECAST(CS$1,$BM9:$BR9,$BM$1:$BR$1)),"") -> 745.13548 | CT9: =SUM(CH9:CS9) -> 5705.5374 | CV9: =SUM(BP9:BR9)/3 -> 332.93406 | CW9: =SUM(BM9:BR9)/6 -> 309.41333 | CX9: =SUM(BG9:BR9)/12 -> 287.4563 | CZ9: =N9+Summary!$E$3*CV9 -> 3867.9775 | DA9: =N9+CW9*Summary!$E$3 -> 3750.3739 | DB9: =N9+CX9*Summary!$E$3 -> 3640.5887
B10: =Mapping!A5 -> Accessories | C10: =SUMIFS('Sales Data'!$E:$E,'Sales Data'!$A:$A,$B10,'Sales Data'!$B:$B,Summary!$C$3&" "&Summary!$C$2-1,'Sales Data'!$C:$C,"Periodic")/Mapping!$C$2 -> 2447.2911 | D10: =SUMIFS('Sales Data'!$D:$D,'Sales Data'!$A:$A,$B10,'Sales Data'!$B:$B,Summary!$C$3&" "&Summary!$C$2,'Sales Data'!$C:$C,"Periodic")/Mapping!$C$2 -> 2295.1582 | E10: =SUMIFS('Sales Data'!$E:$E,'Sales Data'!$A:$A,$B10,'Sales Data'!$B:$B,Summary!$C$3&" "&Summary!$C$2,'Sales Data'!$C:$C,"Periodic")/Mapping!$C$2 -> 2230.7594 | G10: =E10-C10 -> -216.53171 | H10: =IF(ISERROR((E10/C10)-1),"N/A",(E10/C10)-1) -> -0.088478117 | I10: =E10-D10 -> -64.398846 | J10: =IF(ISERROR((E10/D10)-1),"N/A",(E10/D10)-1) -> -0.028058565 | L10: =SUMIFS('Sales Data'!$E:$E,'Sales Data'!$A:$A,$B10,'Sales Data'!$F:$F,$C$2-1,'Sales Data'!$G:$G,"<="&$D$3)/Mapping!$C$2 -> 13676.597 | M10: =SUMIFS('Sales Data'!$D:$D,'Sales Data'!$A:$A,$B10,'Sales Data'!$F:$F,$C$2,'Sales Data'!$G:$G,"<="&$D$3)/Mapping!$C$2 -> 14669.69 | N10: =SUMIFS('Sales Data'!$E:$E,'Sales Data'!$A:$A,$B10,'Sales Data'!$F:$F,$C$2,'Sales Data'!$G:$G,"<="&$D$3)/Mapping!$C$2 -> 15745.228 | P10: =N10-L10 -> 2068.6308 | Q10: =IF(ISERROR((N10/L10)-1),"N/A",(N10/L10)-1) -> 0.15125333 | R10: =N10-M10 -> 1075.5383 | S10: =IF(ISERROR((N10/M10)-1),"N/A",(N10/M10)-1) -> 0.073317044 | U10: =SUMIFS('Sales Data'!$E:$E,'Sales Data'!$A:$A,$B10,'Sales Data'!$F:$F,$C$2-1,'Sales Data'!$G:$G,"<="&12)/Mapping!$C$2 -> 23640.903 | V10: =SUMIFS('Sales Data'!$D:$D,'Sales Data'!$A:$A,$B10,'Sales Data'!$F:$F,$C$2,'Sales Data'!$G:$G,"<="&12)/Mapping!$C$2 -> 25060.11 | W10: =SUMIFS('Sales Data'!$E:$E,'Sales Data'!$A:$A,$B10,'Sales Data'!$F:$F,$C$2,'Sales Data'!$G:$G,"<="&12)/Mapping!$C$2 -> 15745.228 | Y10: =W10-U10 -> -7895.6756 | Z10: =IF(ISERROR((W10/U10)-1),"N/A",(W10/U10)-1) -> -0.33398366 | AA10: =W10-V10 -> -9314.882 | AB10: =IF(ISERROR((W10/V10)-1),"N/A",(W10/V10)-1) -> -0.37170156 | AC10: =W10-#REF! -> #REF! | AD10: =IF(ISERROR((W10/#REF!)-1),"N/A",(W10/#REF!)-1) -> N/A | AF10: =N10/Summary!$D$3 -> 2249.3183 | AG10: =(V10-N10)/Summary!$E$3 -> 1862.9764 | AH10: =AG10-AF10 -> -386.34187 | AJ10: =CZ10-V10 -> 1795.9352 | AK10: =DA10-V10 -> 1827.1332 | AL10: =DB10-V10 -> 1397.424 | AM10: =CT10-V10 -> 2601.2068 | AN10: =CF10-V10 -> -784.96534 | AP10: =U10-L10 -> 9964.3064 | AQ10: =V10-N10 -> 9314.882 | AS10: =SUMIFS('Sales Data'!$E:$E,'Sales Data'!$A:$A,$B10,'Sales Data'!$B:$B,AS$6,'Sales Data'!$C:$C,"Periodic")/Mapping!$C$2 -> 2374.8097 | AT10: =SUMIFS('Sales Data'!$E:$E,'Sales Data'!$A:$A,$B10,'Sales Data'!$B:$B,AT$6,'Sales Data'!$C:$C,"Periodic")/Mapping!$C$2 -> 1899.9103 | AU10: =SUMIFS('Sales Data'!$E:$E,'Sales Data'!$A:$A,$B10,'Sales Data'!$B:$B,AU$6,'Sales Data'!$C:$C,"Periodic")/Mapping!$C$2 -> 2876.2979 | AV10: =SUMIFS('Sales Data'!$E:$E,'Sales Data'!$A:$A,$B10,'Sales Data'!$B:$B,AV$6,'Sales Data'!$C:$C,"Periodic")/Mapping!$C$2 -> 1927.7197 | AW10: =SUMIFS('Sales Data'!$E:$E,'Sales Data'!$A:$A,$B10,'Sales Data'!$B:$B,AW$6,'Sales Data'!$C:$C,"Periodic")/Mapping!$C$2 -> 2047.5976 | AX10: =SUMIFS('Sales Data'!$E:$E,'Sales Data'!$A:$A,$B10,'Sales Data'!$B:$B,AX$6,'Sales Data'!$C:$C,"Periodic")/Mapping!$C$2 -> 2388.1333 | AY10: =SUMIFS('Sales Data'!$E:$E,'Sales Data'!$A:$A,$B10,'Sales Data'!$B:$B,AY$6,'Sales Data'!$C:$C,"Periodic")/Mapping!$C$2 -> 2230.7594 | AZ10: =SUMIFS('Sales Data'!$E:$E,'Sales Data'!$A:$A,$B10,'Sales Data'!$B:$B,AZ$6,'Sales Data'!$C:$C,"Periodic")/Mapping!$C$2 -> 0 | ... BD10: =SUMIFS('Sales Data'!$E:$E,'Sales Data'!$A:$A,$B10,'Sales Data'!$B:$B,BD$6,'Sales Data'!$C:$C,"Periodic")/Mapping!$C$2 -> 0 | BE10: =SUM(AS10:BD10) -> 15745.228 | BG10: =SUMIFS('Sales Data'!$E:$E,'Sales Data'!$A:$A,$B10,'Sales Data'!$B:$B,BG$6,'Sales Data'!$C:$C,"Periodic")/Mapping!$C$2 -> 1799.0383 | BH10: =SUMIFS('Sales Data'!$E:$E,'Sales Data'!$A:$A,$B10,'Sales Data'!$B:$B,BH$6,'Sales Data'!$C:$C,"Periodic")/Mapping!$C$2 -> 1950.4351 | BI10: =SUMIFS('Sales Data'!$E:$E,'Sales Data'!$A:$A,$B10,'Sales Data'!$B:$B,BI$6,'Sales Data'!$C:$C,"Periodic")/Mapping!$C$2 -> 2097.4439 | BJ10: =SUMIFS('Sales Data'!$E:$E,'Sales Data'!$A:$A,$B10,'Sales Data'!$B:$B,BJ$6,'Sales Data'!$C:$C,"Periodic")/Mapping!$C$2 -> 1940.724 | BK10: =SUMIFS('Sales Data'!$E:$E,'Sales Data'!$A:$A,$B10,'Sales Data'!$B:$B,BK$6,'Sales Data'!$C:$C,"Periodic")/Mapping!$C$2 -> 2176.665 | BL10: =SUMIFS('Sales Data'!$E:$E,'Sales Data'!$A:$A,$B10,'Sales Data'!$B:$B,BL$6,'Sales Data'!$C:$C,"Periodic")/Mapping!$C$2 -> 2374.8097 | BM10: =SUMIFS('Sales Data'!$E:$E,'Sales Data'!$A:$A,$B10,'Sales Data'!$B:$B,BM$6,'Sales Data'!$C:$C,"Periodic")/Mapping!$C$2 -> 1899.9103 | BN10: =SUMIFS('Sales Data'!$E:$E,'Sales Data'!$A:$A,$B10,'Sales Data'!$B:$B,BN$6,'Sales Data'!$C:$C,"Periodic")/Mapping!$C$2 -> 2876.2979 | ... BR10: =SUMIFS('Sales Data'!$E:$E,'Sales Data'!$A:$A,$B10,'Sales Data'!$B:$B,BR$6,'Sales Data'!$C:$C,"Periodic")/Mapping!$C$2 -> 2230.7594 | BT10: =IFERROR(IF(AS10<>0,AS10,FORECAST(BT$1,$BG10:$BR10,$BG$1:$BR$1)),"") -> 2374.8097 | BU10: =IFERROR(IF(AT10<>0,AT10,FORECAST(BU$1,$BG10:$BR10,$BG$1:$BR$1)),"") -> 1899.9103 | BV10: =IFERROR(IF(AU10<>0,AU10,FORECAST(BV$1,$BG10:$BR10,$BG$1:$BR$1)),"") -> 2876.2979 | BW10: =IFERROR(IF(AV10<>0,AV10,FORECAST(BW$1,$BG10:$BR10,$BG$1:$BR$1)),"") -> 1927.7197 | BX10: =IFERROR(IF(AW10<>0,AW10,FORECAST(BX$1,$BG10:$BR10,$BG$1:$BR$1)),"") -> 2047.5976 | BY10: =IFERROR(IF(AX10<>0,AX10,FORECAST(BY$1,$BG10:$BR10,$BG$1:$BR$1)),"") -> 2388.1333 | BZ10: =IFERROR(IF(AY10<>0,AY10,FORECAST(BZ$1,$BG10:$BR10,$BG$1:$BR$1)),"") -> 2230.7594 | CA10: =IFERROR(IF(AZ10<>0,AZ10,FORECAST(CA$1,$BG10:$BR10,$BG$1:$BR$1)),"") -> 1762.3031 | ... CE10: =IFERROR(IF(BD10<>0,BD10,FORECAST(CE$1,$BG10:$BR10,$BG$1:$BR$1)),"") -> 1649.6636 | CF10: =SUM(BT10:CE10) -> 24275.145 | CH10: =IFERROR(IF(AS10<>0,AS10,FORECAST(CH$1,$BM10:$BR10,$BM$1:$BR$1)),"") -> 2374.8097 | CI10: =IFERROR(IF(AT10<>0,AT10,FORECAST(CI$1,$BM10:$BR10,$BM$1:$BR$1)),"") -> 1899.9103 | CJ10: =IFERROR(IF(AU10<>0,AU10,FORECAST(CJ$1,$BM10:$BR10,$BM$1:$BR$1)),"") -> 2876.2979 | CK10: =IFERROR(IF(AV10<>0,AV10,FORECAST(CK$1,$BM10:$BR10,$BM$1:$BR$1)),"") -> 1927.7197 | CL10: =IFERROR(IF(AW10<>0,AW10,FORECAST(CL$1,$BM10:$BR10,$BM$1:$BR$1)),"") -> 2047.5976 | CM10: =IFERROR(IF(AX10<>0,AX10,FORECAST(CM$1,$BM10:$BR10,$BM$1:$BR$1)),"") -> 2388.1333 | CN10: =IFERROR(IF(AY10<>0,AY10,FORECAST(CN$1,$BM10:$BR10,$BM$1:$BR$1)),"") -> 2230.7594 | CO10: =IFERROR(IF(AZ10<>0,AZ10,FORECAST(CO$1,$BM10:$BR10,$BM$1:$BR$1)),"") -> 2365.5246 | ... CS10: =IFERROR(IF(BD10<>0,BD10,FORECAST(CS$1,$BM10:$BR10,$BM$1:$BR$1)),"") -> 2400.9109 | CT10: =SUM(CH10:CS10) -> 27661.317 | CV10: =SUM(BP10:BR10)/3 -> 2222.1634 | CW10: =SUM(BM10:BR10)/6 -> 2228.403 | CX10: =SUM(BG10:BR10)/12 -> 2142.4612 | CZ10: =N10+Summary!$E$3*CV10 -> 26856.045 | DA10: =N10+CW10*Summary!$E$3 -> 26887.243 | DB10: =N10+CX10*Summary!$E$3 -> 26457.534
B11: =Mapping!A6 -> Placeholder 1 | C11: =SUMIFS('Sales Data'!$E:$E,'Sales Data'!$A:$A,$B11,'Sales Data'!$B:$B,Summary!$C$3&" "&Summary!$C$2-1,'Sales Data'!$C:$C,"Periodic")/Mapping!$C$2 -> 0 | D11: =SUMIFS('Sales Data'!$D:$D,'Sales Data'!$A:$A,$B11,'Sales Data'!$B:$B,Summary!$C$3&" "&Summary!$C$2,'Sales Data'!$C:$C,"Periodic")/Mapping!$C$2 -> 0 | E11: =SUMIFS('Sales Data'!$E:$E,'Sales Data'!$A:$A,$B11,'Sales Data'!$B:$B,Summary!$C$3&" "&Summary!$C$2,'Sales Data'!$C:$C,"Periodic")/Mapping!$C$2 -> 0 | G11: =E11-C11 -> 0 | H11: =IF(ISERROR((E11/C11)-1),"N/A",(E11/C11)-1) -> N/A | I11: =E11-D11 -> 0 | J11: =IF(ISERROR((E11/D11)-1),"N/A",(E11/D11)-1) -> N/A | L11: =SUMIFS('Sales Data'!$E:$E,'Sales Data'!$A:$A,$B11,'Sales Data'!$F:$F,$C$2-1,'Sales Data'!$G:$G,"<="&$D$3)/Mapping!$C$2 -> 0 | M11: =SUMIFS('Sales Data'!$D:$D,'Sales Data'!$A:$A,$B11,'Sales Data'!$F:$F,$C$2,'Sales Data'!$G:$G,"<="&$D$3)/Mapping!$C$2 -> 0 | N11: =SUMIFS('Sales Data'!$E:$E,'Sales Data'!$A:$A,$B11,'Sales Data'!$F:$F,$C$2,'Sales Data'!$G:$G,"<="&$D$3)/Mapping!$C$2 -> 0 | P11: =N11-L11 -> 0 | Q11: =IF(ISERROR((N11/L11)-1),"N/A",(N11/L11)-1) -> N/A | R11: =N11-M11 -> 0 | S11: =IF(ISERROR((N11/M11)-1),"N/A",(N11/M11)-1) -> N/A | U11: =SUMIFS('Sales Data'!$E:$E,'Sales Data'!$A:$A,$B11,'Sales Data'!$F:$F,$C$2-1,'Sales Data'!$G:$G,"<="&12)/Mapping!$C$2 -> 0 | V11: =SUMIFS('Sales Data'!$D:$D,'Sales Data'!$A:$A,$B11,'Sales Data'!$F:$F,$C$2,'Sales Data'!$G:$G,"<="&12)/Mapping!$C$2 -> 0 | W11: =SUMIFS('Sales Data'!$E:$E,'Sales Data'!$A:$A,$B11,'Sales Data'!$F:$F,$C$2,'Sales Data'!$G:$G,"<="&12)/Mapping!$C$2 -> 0 | Y11: =W11-U11 -> 0 | Z11: =IF(ISERROR((W11/U11)-1),"N/A",(W11/U11)-1) -> N/A | AA11: =W11-V11 -> 0 | AB11: =IF(ISERROR((W11/V11)-1),"N/A",(W11/V11)-1) -> N/A | AC11: =W11-#REF! -> #REF! | AD11: =IF(ISERROR((W11/#REF!)-1),"N/A",(W11/#REF!)-1) -> N/A | AF11: =N11/Summary!$D$3 -> 0 | AG11: =(V11-N11)/Summary!$E$3 -> 0 | AH11: =AG11-AF11 -> 0 | AJ11: =CZ11-V11 -> 0 | AK11: =DA11-V11 -> 0 | AL11: =DB11-V11 -> 0 | AM11: =CT11-V11 -> 0 | AN11: =CF11-V11 -> 0 | AP11: =U11-L11 -> 0 | AQ11: =V11-N11 -> 0 | AS11: =SUMIFS('Sales Data'!$E:$E,'Sales Data'!$A:$A,$B11,'Sales Data'!$B:$B,AS$6,'Sales Data'!$C:$C,"Periodic")/Mapping!$C$2 -> 0 | AT11: =SUMIFS('Sales Data'!$E:$E,'Sales Data'!$A:$A,$B11,'Sales Data'!$B:$B,AT$6,'Sales Data'!$C:$C,"Periodic")/Mapping!$C$2 -> 0 | AU11: =SUMIFS('Sales Data'!$E:$E,'Sales Data'!$A:$A,$B11,'Sales Data'!$B:$B,AU$6,'Sales Data'!$C:$C,"Periodic")/Mapping!$C$2 -> 0 | AV11: =SUMIFS('Sales Data'!$E:$E,'Sales Data'!$A:$A,$B11,'Sales Data'!$B:$B,AV$6,'Sales Data'!$C:$C,"Periodic")/Mapping!$C$2 -> 0 | AW11: =SUMIFS('Sales Data'!$E:$E,'Sales Data'!$A:$A,$B11,'Sales Data'!$B:$B,AW$6,'Sales Data'!$C:$C,"Periodic")/Mapping!$C$2 -> 0 | AX11: =SUMIFS('Sales Data'!$E:$E,'Sales Data'!$A:$A,$B11,'Sales Data'!$B:$B,AX$6,'Sales Data'!$C:$C,"Periodic")/Mapping!$C$2 -> 0 | AY11: =SUMIFS('Sales Data'!$E:$E,'Sales Data'!$A:$A,$B11,'Sales Data'!$B:$B,AY$6,'Sales Data'!$C:$C,"Periodic")/Mapping!$C$2 -> 0 | AZ11: =SUMIFS('Sales Data'!$E:$E,'Sales Data'!$A:$A,$B11,'Sales Data'!$B:$B,AZ$6,'Sales Data'!$C:$C,"Periodic")/Mapping!$C$2 -> 0 | ... BD11: =SUMIFS('Sales Data'!$E:$E,'Sales Data'!$A:$A,$B11,'Sales Data'!$B:$B,BD$6,'Sales Data'!$C:$C,"Periodic")/Mapping!$C$2 -> 0 | BE11: =SUM(AS11:BD11) -> 0 | BG11: =SUMIFS('Sales Data'!$E:$E,'Sales Data'!$A:$A,$B11,'Sales Data'!$B:$B,BG$6,'Sales Data'!$C:$C,"Periodic")/Mapping!$C$2 -> 0 | BH11: =SUMIFS('Sales Data'!$E:$E,'Sales Data'!$A:$A,$B11,'Sales Data'!$B:$B,BH$6,'Sales Data'!$C:$C,"Periodic")/Mapping!$C$2 -> 0 | BI11: =SUMIFS('Sales Data'!$E:$E,'Sales Data'!$A:$A,$B11,'Sales Data'!$B:$B,BI$6,'Sales Data'!$C:$C,"Periodic")/Mapping!$C$2 -> 0 | BJ11: =SUMIFS('Sales Data'!$E:$E,'Sales Data'!$A:$A,$B11,'Sales Data'!$B:$B,BJ$6,'Sales Data'!$C:$C,"Periodic")/Mapping!$C$2 -> 0 | BK11: =SUMIFS('Sales Data'!$E:$E,'Sales Data'!$A:$A,$B11,'Sales Data'!$B:$B,BK$6,'Sales Data'!$C:$C,"Periodic")/Mapping!$C$2 -> 0 | BL11: =SUMIFS('Sales Data'!$E:$E,'Sales Data'!$A:$A,$B11,'Sales Data'!$B:$B,BL$6,'Sales Data'!$C:$C,"Periodic")/Mapping!$C$2 -> 0 | BM11: =SUMIFS('Sales Data'!$E:$E,'Sales Data'!$A:$A,$B11,'Sales Data'!$B:$B,BM$6,'Sales Data'!$C:$C,"Periodic")/Mapping!$C$2 -> 0 | BN11: =SUMIFS('Sales Data'!$E:$E,'Sales Data'!$A:$A,$B11,'Sales Data'!$B:$B,BN$6,'Sales Data'!$C:$C,"Periodic")/Mapping!$C$2 -> 0 | ... BR11: =SUMIFS('Sales Data'!$E:$E,'Sales Data'!$A:$A,$B11,'Sales Data'!$B:$B,BR$6,'Sales Data'!$C:$C,"Periodic")/Mapping!$C$2 -> 0 | BT11: =IFERROR(IF(AS11<>0,AS11,FORECAST(BT$1,$BG11:$BR11,$BG$1:$BR$1)),"") -> 0 | BU11: =IFERROR(IF(AT11<>0,AT11,FORECAST(BU$1,$BG11:$BR11,$BG$1:$BR$1)),"") -> 0 | BV11: =IFERROR(IF(AU11<>0,AU11,FORECAST(BV$1,$BG11:$BR11,$BG$1:$BR$1)),"") -> 0 | BW11: =IFERROR(IF(AV11<>0,AV11,FORECAST(BW$1,$BG11:$BR11,$BG$1:$BR$1)),"") -> 0 | BX11: =IFERROR(IF(AW11<>0,AW11,FORECAST(BX$1,$BG11:$BR11,$BG$1:$BR$1)),"") -> 0 | BY11: =IFERROR(IF(AX11<>0,AX11,FORECAST(BY$1,$BG11:$BR11,$BG$1:$BR$1)),"") -> 0 | BZ11: =IFERROR(IF(AY11<>0,AY11,FORECAST(BZ$1,$BG11:$BR11,$BG$1:$BR$1)),"") -> 0 | CA11: =IFERROR(IF(AZ11<>0,AZ11,FORECAST(CA$1,$BG11:$BR11,$BG$1:$BR$1)),"") -> 0 | ... CE11: =IFERROR(IF(BD11<>0,BD11,FORECAST(CE$1,$BG11:$BR11,$BG$1:$BR$1)),"") -> 0 | CF11: =SUM(BT11:CE11) -> 0 | CH11: =IFERROR(IF(AS11<>0,AS11,FORECAST(CH$1,$BM11:$BR11,$BM$1:$BR$1)),"") -> 0 | CI11: =IFERROR(IF(AT11<>0,AT11,FORECAST(CI$1,$BM11:$BR11,$BM$1:$BR$1)),"") -> 0 | CJ11: =IFERROR(IF(AU11<>0,AU11,FORECAST(CJ$1,$BM11:$BR11,$BM$1:$BR$1)),"") -> 0 | CK11: =IFERROR(IF(AV11<>0,AV11,FORECAST(CK$1,$BM11:$BR11,$BM$1:$BR$1)),"") -> 0 | CL11: =IFERROR(IF(AW11<>0,AW11,FORECAST(CL$1,$BM11:$BR11,$BM$1:$BR$1)),"") -> 0 | CM11: =IFERROR(IF(AX11<>0,AX11,FORECAST(CM$1,$BM11:$BR11,$BM$1:$BR$1)),"") -> 0 | CN11: =IFERROR(IF(AY11<>0,AY11,FORECAST(CN$1,$BM11:$BR11,$BM$1:$BR$1)),"") -> 0 | CO11: =IFERROR(IF(AZ11<>0,AZ11,FORECAST(CO$1,$BM11:$BR11,$BM$1:$BR$1)),"") -> 0 | ... CS11: =IFERROR(IF(BD11<>0,BD11,FORECAST(CS$1,$BM11:$BR11,$BM$1:$BR$1)),"") -> 0 | CT11: =SUM(CH11:CS11) -> 0 | CV11: =SUM(BP11:BR11)/3 -> 0 | CW11: =SUM(BM11:BR11)/6 -> 0 | CX11: =SUM(BG11:BR11)/12 -> 0 | CZ11: =N11+Summary!$E$3*CV11 -> 0 | DA11: =N11+CW11*Summary!$E$3 -> 0 | DB11: =N11+CX11*Summary!$E$3 -> 0
B12: =Mapping!A7 -> Placeholder 2 | C12: =SUMIFS('Sales Data'!$E:$E,'Sales Data'!$A:$A,$B12,'Sales Data'!$B:$B,Summary!$C$3&" "&Summary!$C$2-1,'Sales Data'!$C:$C,"Periodic")/Mapping!$C$2 -> 0 | D12: =SUMIFS('Sales Data'!$D:$D,'Sales Data'!$A:$A,$B12,'Sales Data'!$B:$B,Summary!$C$3&" "&Summary!$C$2,'Sales Data'!$C:$C,"Periodic")/Mapping!$C$2 -> 0 | E12: =SUMIFS('Sales Data'!$E:$E,'Sales Data'!$A:$A,$B12,'Sales Data'!$B:$B,Summary!$C$3&" "&Summary!$C$2,'Sales Data'!$C:$C,"Periodic")/Mapping!$C$2 -> 0 | G12: =E12-C12 -> 0 | H12: =IF(ISERROR((E12/C12)-1),"N/A",(E12/C12)-1) -> N/A | I12: =E12-D12 -> 0 | J12: =IF(ISERROR((E12/D12)-1),"N/A",(E12/D12)-1) -> N/A | L12: =SUMIFS('Sales Data'!$E:$E,'Sales Data'!$A:$A,$B12,'Sales Data'!$F:$F,$C$2-1,'Sales Data'!$G:$G,"<="&$D$3)/Mapping!$C$2 -> 0 | M12: =SUMIFS('Sales Data'!$D:$D,'Sales Data'!$A:$A,$B12,'Sales Data'!$F:$F,$C$2,'Sales Data'!$G:$G,"<="&$D$3)/Mapping!$C$2 -> 0 | N12: =SUMIFS('Sales Data'!$E:$E,'Sales Data'!$A:$A,$B12,'Sales Data'!$F:$F,$C$2,'Sales Data'!$G:$G,"<="&$D$3)/Mapping!$C$2 -> 0 | P12: =N12-L12 -> 0 | Q12: =IF(ISERROR((N12/L12)-1),"N/A",(N12/L12)-1) -> N/A | R12: =N12-M12 -> 0 | S12: =IF(ISERROR((N12/M12)-1),"N/A",(N12/M12)-1) -> N/A | U12: =SUMIFS('Sales Data'!$E:$E,'Sales Data'!$A:$A,$B12,'Sales Data'!$F:$F,$C$2-1,'Sales Data'!$G:$G,"<="&12)/Mapping!$C$2 -> 0 | V12: =SUMIFS('Sales Data'!$D:$D,'Sales Data'!$A:$A,$B12,'Sales Data'!$F:$F,$C$2,'Sales Data'!$G:$G,"<="&12)/Mapping!$C$2 -> 0 | W12: =SUMIFS('Sales Data'!$E:$E,'Sales Data'!$A:$A,$B12,'Sales Data'!$F:$F,$C$2,'Sales Data'!$G:$G,"<="&12)/Mapping!$C$2 -> 0 | Y12: =W12-U12 -> 0 | Z12: =IF(ISERROR((W12/U12)-1),"N/A",(W12/U12)-1) -> N/A | AA12: =W12-V12 -> 0 | AB12: =IF(ISERROR((W12/V12)-1),"N/A",(W12/V12)-1) -> N/A | AC12: =W12-#REF! -> #REF! | AD12: =IF(ISERROR((W12/#REF!)-1),"N/A",(W12/#REF!)-1) -> N/A | AF12: =N12/Summary!$D$3 -> 0 | AG12: =(V12-N12)/Summary!$E$3 -> 0 | AH12: =AG12-AF12 -> 0 | AJ12: =CZ12-V12 -> 0 | AK12: =DA12-V12 -> 0 | AL12: =DB12-V12 -> 0 | AM12: =CT12-V12 -> 0 | AN12: =CF12-V12 -> 0 | AP12: =U12-L12 -> 0 | AQ12: =V12-N12 -> 0 | AS12: =SUMIFS('Sales Data'!$E:$E,'Sales Data'!$A:$A,$B12,'Sales Data'!$B:$B,AS$6,'Sales Data'!$C:$C,"Periodic")/Mapping!$C$2 -> 0 | AT12: =SUMIFS('Sales Data'!$E:$E,'Sales Data'!$A:$A,$B12,'Sales Data'!$B:$B,AT$6,'Sales Data'!$C:$C,"Periodic")/Mapping!$C$2 -> 0 | AU12: =SUMIFS('Sales Data'!$E:$E,'Sales Data'!$A:$A,$B12,'Sales Data'!$B:$B,AU$6,'Sales Data'!$C:$C,"Periodic")/Mapping!$C$2 -> 0 | AV12: =SUMIFS('Sales Data'!$E:$E,'Sales Data'!$A:$A,$B12,'Sales Data'!$B:$B,AV$6,'Sales Data'!$C:$C,"Periodic")/Mapping!$C$2 -> 0 | AW12: =SUMIFS('Sales Data'!$E:$E,'Sales Data'!$A:$A,$B12,'Sales Data'!$B:$B,AW$6,'Sales Data'!$C:$C,"Periodic")/Mapping!$C$2 -> 0 | AX12: =SUMIFS('Sales Data'!$E:$E,'Sales Data'!$A:$A,$B12,'Sales Data'!$B:$B,AX$6,'Sales Data'!$C:$C,"Periodic")/Mapping!$C$2 -> 0 | AY12: =SUMIFS('Sales Data'!$E:$E,'Sales Data'!$A:$A,$B12,'Sales Data'!$B:$B,AY$6,'Sales Data'!$C:$C,"Periodic")/Mapping!$C$2 -> 0 | AZ12: =SUMIFS('Sales Data'!$E:$E,'Sales Data'!$A:$A,$B12,'Sales Data'!$B:$B,AZ$6,'Sales Data'!$C:$C,"Periodic")/Mapping!$C$2 -> 0 | ... BD12: =SUMIFS('Sales Data'!$E:$E,'Sales Data'!$A:$A,$B12,'Sales Data'!$B:$B,BD$6,'Sales Data'!$C:$C,"Periodic")/Mapping!$C$2 -> 0 | BE12: =SUM(AS12:BD12) -> 0 | BG12: =SUMIFS('Sales Data'!$E:$E,'Sales Data'!$A:$A,$B12,'Sales Data'!$B:$B,BG$6,'Sales Data'!$C:$C,"Periodic")/Mapping!$C$2 -> 0 | BH12: =SUMIFS('Sales Data'!$E:$E,'Sales Data'!$A:$A,$B12,'Sales Data'!$B:$B,BH$6,'Sales Data'!$C:$C,"Periodic")/Mapping!$C$2 -> 0 | BI12: =SUMIFS('Sales Data'!$E:$E,'Sales Data'!$A:$A,$B12,'Sales Data'!$B:$B,BI$6,'Sales Data'!$C:$C,"Periodic")/Mapping!$C$2 -> 0 | BJ12: =SUMIFS('Sales Data'!$E:$E,'Sales Data'!$A:$A,$B12,'Sales Data'!$B:$B,BJ$6,'Sales Data'!$C:$C,"Periodic")/Mapping!$C$2 -> 0 | BK12: =SUMIFS('Sales Data'!$E:$E,'Sales Data'!$A:$A,$B12,'Sales Data'!$B:$B,BK$6,'Sales Data'!$C:$C,"Periodic")/Mapping!$C$2 -> 0 | BL12: =SUMIFS('Sales Data'!$E:$E,'Sales Data'!$A:$A,$B12,'Sales Data'!$B:$B,BL$6,'Sales Data'!$C:$C,"Periodic")/Mapping!$C$2 -> 0 | BM12: =SUMIFS('Sales Data'!$E:$E,'Sales Data'!$A:$A,$B12,'Sales Data'!$B:$B,BM$6,'Sales Data'!$C:$C,"Periodic")/Mapping!$C$2 -> 0 | BN12: =SUMIFS('Sales Data'!$E:$E,'Sales Data'!$A:$A,$B12,'Sales Data'!$B:$B,BN$6,'Sales Data'!$C:$C,"Periodic")/Mapping!$C$2 -> 0 | ... BR12: =SUMIFS('Sales Data'!$E:$E,'Sales Data'!$A:$A,$B12,'Sales Data'!$B:$B,BR$6,'Sales Data'!$C:$C,"Periodic")/Mapping!$C$2 -> 0 | BT12: =IFERROR(IF(AS12<>0,AS12,FORECAST(BT$1,$BG12:$BR12,$BG$1:$BR$1)),"") -> 0 | BU12: =IFERROR(IF(AT12<>0,AT12,FORECAST(BU$1,$BG12:$BR12,$BG$1:$BR$1)),"") -> 0 | BV12: =IFERROR(IF(AU12<>0,AU12,FORECAST(BV$1,$BG12:$BR12,$BG$1:$BR$1)),"") -> 0 | BW12: =IFERROR(IF(AV12<>0,AV12,FORECAST(BW$1,$BG12:$BR12,$BG$1:$BR$1)),"") -> 0 | BX12: =IFERROR(IF(AW12<>0,AW12,FORECAST(BX$1,$BG12:$BR12,$BG$1:$BR$1)),"") -> 0 | BY12: =IFERROR(IF(AX12<>0,AX12,FORECAST(BY$1,$BG12:$BR12,$BG$1:$BR$1)),"") -> 0 | BZ12: =IFERROR(IF(AY12<>0,AY12,FORECAST(BZ$1,$BG12:$BR12,$BG$1:$BR$1)),"") -> 0 | CA12: =IFERROR(IF(AZ12<>0,AZ12,FORECAST(CA$1,$BG12:$BR12,$BG$1:$BR$1)),"") -> 0 | ... CE12: =IFERROR(IF(BD12<>0,BD12,FORECAST(CE$1,$BG12:$BR12,$BG$1:$BR$1)),"") -> 0 | CF12: =SUM(BT12:CE12) -> 0 | CH12: =IFERROR(IF(AS12<>0,AS12,FORECAST(CH$1,$BM12:$BR12,$BM$1:$BR$1)),"") -> 0 | CI12: =IFERROR(IF(AT12<>0,AT12,FORECAST(CI$1,$BM12:$BR12,$BM$1:$BR$1)),"") -> 0 | CJ12: =IFERROR(IF(AU12<>0,AU12,FORECAST(CJ$1,$BM12:$BR12,$BM$1:$BR$1)),"") -> 0 | CK12: =IFERROR(IF(AV12<>0,AV12,FORECAST(CK$1,$BM12:$BR12,$BM$1:$BR$1)),"") -> 0 | CL12: =IFERROR(IF(AW12<>0,AW12,FORECAST(CL$1,$BM12:$BR12,$BM$1:$BR$1)),"") -> 0 | CM12: =IFERROR(IF(AX12<>0,AX12,FORECAST(CM$1,$BM12:$BR12,$BM$1:$BR$1)),"") -> 0 | CN12: =IFERROR(IF(AY12<>0,AY12,FORECAST(CN$1,$BM12:$BR12,$BM$1:$BR$1)),"") -> 0 | CO12: =IFERROR(IF(AZ12<>0,AZ12,FORECAST(CO$1,$BM12:$BR12,$BM$1:$BR$1)),"") -> 0 | ... CS12: =IFERROR(IF(BD12<>0,BD12,FORECAST(CS$1,$BM12:$BR12,$BM$1:$BR$1)),"") -> 0 | CT12: =SUM(CH12:CS12) -> 0 | CV12: =SUM(BP12:BR12)/3 -> 0 | CW12: =SUM(BM12:BR12)/6 -> 0 | CX12: =SUM(BG12:BR12)/12 -> 0 | CZ12: =N12+Summary!$E$3*CV12 -> 0 | DA12: =N12+CW12*Summary!$E$3 -> 0 | DB12: =N12+CX12*Summary!$E$3 -> 0
